view's UpdateUserDetails raised exception during schema generation; use `getattr(self, 'swagger_fake_view', False)` to detect and short-circuit this
Traceback (most recent call last):
  File "D:\Jafar\AAD\.env\lib\site-packages\drf_yasg\inspectors\base.py", line 42, in call_view_method
    return view_method()
  File "D:\Jafar\AAD\.env\lib\site-packages\rest_framework\generics.py", line 63, in get_queryset
    assert self.queryset is not None, (
AssertionError: 'UpdateUserDetails' should either include a `queryset` attribute, or override the `get_queryset()` method.
view's UpdateUserDetails raised exception during schema generation; use `getattr(self, 'swagger_fake_view', False)` to detect and short-circuit this
Traceback (most recent call last):
  File "D:\Jafar\AAD\.env\lib\site-packages\drf_yasg\inspectors\base.py", line 42, in call_view_method
    return view_method()
  File "D:\Jafar\AAD\.env\lib\site-packages\rest_framework\generics.py", line 63, in get_queryset
    assert self.queryset is not None, (
AssertionError: 'UpdateUserDetails' should either include a `queryset` attribute, or override the `get_queryset()` method.
view's UpdateUserDetails raised exception during schema generation; use `getattr(self, 'swagger_fake_view', False)` to detect and short-circuit this
Traceback (most recent call last):
  File "D:\Jafar\AAD\.env\lib\site-packages\drf_yasg\inspectors\base.py", line 42, in call_view_method
    return view_method()
  File "D:\Jafar\AAD\.env\lib\site-packages\rest_framework\generics.py", line 63, in get_queryset
    assert self.queryset is not None, (
AssertionError: 'UpdateUserDetails' should either include a `queryset` attribute, or override the `get_queryset()` method.
view's UpdateUserDetails raised exception during schema generation; use `getattr(self, 'swagger_fake_view', False)` to detect and short-circuit this
Traceback (most recent call last):
  File "D:\Jafar\AAD\.env\lib\site-packages\drf_yasg\inspectors\base.py", line 42, in call_view_method
    return view_method()
  File "D:\Jafar\AAD\.env\lib\site-packages\rest_framework\generics.py", line 63, in get_queryset
    assert self.queryset is not None, (
AssertionError: 'UpdateUserDetails' should either include a `queryset` attribute, or override the `get_queryset()` method.
Not Found: /media/consent_audios/audio.mp3
[33mHTTP GET /media/consent_audios/audio.mp3 404 [0.04, 127.0.0.1:50761][0m
Unauthorized: /abdm/api/v1/account/getCard
[31;1mHTTP GET /abdm/api/v1/account/getCard 401 [0.25, 127.0.0.1:53567][0m
Not Found: /
[33mHTTP GET / 404 [0.10, 127.0.0.1:53494][0m
Not Found: /favicon.ico
[33mHTTP GET /favicon.ico 404 [0.02, 127.0.0.1:53494][0m
view's UpdateUserDetails raised exception during schema generation; use `getattr(self, 'swagger_fake_view', False)` to detect and short-circuit this
Traceback (most recent call last):
  File "D:\Jafar\AAD\.env\lib\site-packages\drf_yasg\inspectors\base.py", line 42, in call_view_method
    return view_method()
  File "D:\Jafar\AAD\.env\lib\site-packages\rest_framework\generics.py", line 63, in get_queryset
    assert self.queryset is not None, (
AssertionError: 'UpdateUserDetails' should either include a `queryset` attribute, or override the `get_queryset()` method.
view's UpdateUserDetails raised exception during schema generation; use `getattr(self, 'swagger_fake_view', False)` to detect and short-circuit this
Traceback (most recent call last):
  File "D:\Jafar\AAD\.env\lib\site-packages\drf_yasg\inspectors\base.py", line 42, in call_view_method
    return view_method()
  File "D:\Jafar\AAD\.env\lib\site-packages\rest_framework\generics.py", line 63, in get_queryset
    assert self.queryset is not None, (
AssertionError: 'UpdateUserDetails' should either include a `queryset` attribute, or override the `get_queryset()` method.
view's UpdateUserDetails raised exception during schema generation; use `getattr(self, 'swagger_fake_view', False)` to detect and short-circuit this
Traceback (most recent call last):
  File "D:\Jafar\AAD\.env\lib\site-packages\drf_yasg\inspectors\base.py", line 42, in call_view_method
    return view_method()
  File "D:\Jafar\AAD\.env\lib\site-packages\rest_framework\generics.py", line 63, in get_queryset
    assert self.queryset is not None, (
AssertionError: 'UpdateUserDetails' should either include a `queryset` attribute, or override the `get_queryset()` method.
Internal Server Error: /adminportal/api/GetuserListAPI/mo
Traceback (most recent call last):
  File "D:\Jafar\AAD\adminportal\serializers.py", line 72, in get_ward
    Ward_Name = data.section.healthPost.ward.wardName
AttributeError: 'NoneType' object has no attribute 'healthPost'

During handling of the above exception, another exception occurred:

Traceback (most recent call last):
  File "D:\Jafar\AAD\.env\lib\site-packages\asgiref\sync.py", line 534, in thread_handler
    raise exc_info[1]
  File "D:\Jafar\AAD\.env\lib\site-packages\django\core\handlers\exception.py", line 42, in inner
    response = await get_response(request)
  File "D:\Jafar\AAD\.env\lib\site-packages\django\core\handlers\base.py", line 253, in _get_response_async
    response = await wrapped_callback(
  File "D:\Jafar\AAD\.env\lib\site-packages\asgiref\sync.py", line 479, in __call__
    ret: _R = await loop.run_in_executor(
  File "C:\Program Files\WindowsApps\PythonSoftwareFoundation.Python.3.10_3.10.3056.0_x64__qbz5n2kfra8p0\lib\concurrent\futures\thread.py", line 58, in run
    result = self.fn(*self.args, **self.kwargs)
  File "D:\Jafar\AAD\.env\lib\site-packages\asgiref\sync.py", line 538, in thread_handler
    return func(*args, **kwargs)
  File "D:\Jafar\AAD\.env\lib\site-packages\django\views\decorators\csrf.py", line 56, in wrapper_view
    return view_func(*args, **kwargs)
  File "D:\Jafar\AAD\.env\lib\site-packages\django\views\generic\base.py", line 104, in view
    return self.dispatch(request, *args, **kwargs)
  File "D:\Jafar\AAD\.env\lib\site-packages\rest_framework\views.py", line 509, in dispatch
    response = self.handle_exception(exc)
  File "D:\Jafar\AAD\.env\lib\site-packages\rest_framework\views.py", line 469, in handle_exception
    self.raise_uncaught_exception(exc)
  File "D:\Jafar\AAD\.env\lib\site-packages\rest_framework\views.py", line 480, in raise_uncaught_exception
    raise exc
  File "D:\Jafar\AAD\.env\lib\site-packages\rest_framework\views.py", line 506, in dispatch
    response = handler(request, *args, **kwargs)
  File "D:\Jafar\AAD\adminportal\views.py", line 188, in get
    'data': serializer.data})
  File "D:\Jafar\AAD\.env\lib\site-packages\rest_framework\serializers.py", line 768, in data
    ret = super().data
  File "D:\Jafar\AAD\.env\lib\site-packages\rest_framework\serializers.py", line 253, in data
    self._data = self.to_representation(self.instance)
  File "D:\Jafar\AAD\.env\lib\site-packages\rest_framework\serializers.py", line 686, in to_representation
    return [
  File "D:\Jafar\AAD\.env\lib\site-packages\rest_framework\serializers.py", line 687, in <listcomp>
    self.child.to_representation(item) for item in iterable
  File "D:\Jafar\AAD\.env\lib\site-packages\rest_framework\serializers.py", line 522, in to_representation
    ret[field.field_name] = field.to_representation(attribute)
  File "D:\Jafar\AAD\.env\lib\site-packages\rest_framework\fields.py", line 1838, in to_representation
    return method(value)
  File "D:\Jafar\AAD\adminportal\serializers.py", line 74, in get_ward
    Ward_Name = data.dispensary.ward.wardName
AttributeError: 'NoneType' object has no attribute 'ward'
[35;1mHTTP GET /adminportal/api/GetuserListAPI/mo 500 [0.88, 127.0.0.1:52319][0m
Unauthorized: /allauth/api/GetDispensaryListAPI
[31;1mHTTP GET /allauth/api/GetDispensaryListAPI 401 [0.01, 127.0.0.1:52832][0m
view's UpdateUserDetails raised exception during schema generation; use `getattr(self, 'swagger_fake_view', False)` to detect and short-circuit this
Traceback (most recent call last):
  File "D:\Jafar\AAD\.env\lib\site-packages\drf_yasg\inspectors\base.py", line 42, in call_view_method
    return view_method()
  File "D:\Jafar\AAD\.env\lib\site-packages\rest_framework\generics.py", line 63, in get_queryset
    assert self.queryset is not None, (
AssertionError: 'UpdateUserDetails' should either include a `queryset` attribute, or override the `get_queryset()` method.
view's UpdateUserDetails raised exception during schema generation; use `getattr(self, 'swagger_fake_view', False)` to detect and short-circuit this
Traceback (most recent call last):
  File "D:\Jafar\AAD\.env\lib\site-packages\drf_yasg\inspectors\base.py", line 42, in call_view_method
    return view_method()
  File "D:\Jafar\AAD\.env\lib\site-packages\rest_framework\generics.py", line 63, in get_queryset
    assert self.queryset is not None, (
AssertionError: 'UpdateUserDetails' should either include a `queryset` attribute, or override the `get_queryset()` method.
Internal Server Error: /doctor/api/ViewFamilyDetails/181/
Traceback (most recent call last):
  File "D:\Jafar\AAD\.env\lib\site-packages\asgiref\sync.py", line 534, in thread_handler
    raise exc_info[1]
  File "D:\Jafar\AAD\.env\lib\site-packages\django\core\handlers\exception.py", line 42, in inner
    response = await get_response(request)
  File "D:\Jafar\AAD\.env\lib\site-packages\django\core\handlers\base.py", line 253, in _get_response_async
    response = await wrapped_callback(
  File "D:\Jafar\AAD\.env\lib\site-packages\asgiref\sync.py", line 479, in __call__
    ret: _R = await loop.run_in_executor(
  File "C:\Program Files\WindowsApps\PythonSoftwareFoundation.Python.3.10_3.10.3056.0_x64__qbz5n2kfra8p0\lib\concurrent\futures\thread.py", line 58, in run
    result = self.fn(*self.args, **self.kwargs)
  File "D:\Jafar\AAD\.env\lib\site-packages\asgiref\sync.py", line 538, in thread_handler
    return func(*args, **kwargs)
  File "D:\Jafar\AAD\.env\lib\site-packages\django\views\decorators\csrf.py", line 56, in wrapper_view
    return view_func(*args, **kwargs)
  File "D:\Jafar\AAD\.env\lib\site-packages\django\views\generic\base.py", line 104, in view
    return self.dispatch(request, *args, **kwargs)
  File "D:\Jafar\AAD\.env\lib\site-packages\rest_framework\views.py", line 509, in dispatch
    response = self.handle_exception(exc)
  File "D:\Jafar\AAD\.env\lib\site-packages\rest_framework\views.py", line 469, in handle_exception
    self.raise_uncaught_exception(exc)
  File "D:\Jafar\AAD\.env\lib\site-packages\rest_framework\views.py", line 480, in raise_uncaught_exception
    raise exc
  File "D:\Jafar\AAD\.env\lib\site-packages\rest_framework\views.py", line 506, in dispatch
    response = handler(request, *args, **kwargs)
  File "D:\Jafar\AAD\.env\lib\site-packages\rest_framework\decorators.py", line 50, in handler
    return func(*args, **kwargs)
  File "D:\Jafar\AAD\doctorsApp\views.py", line 213, in ViewFamilyDetails
    testData  = serializer.data
  File "D:\Jafar\AAD\.env\lib\site-packages\rest_framework\serializers.py", line 555, in data
    ret = super().data
  File "D:\Jafar\AAD\.env\lib\site-packages\rest_framework\serializers.py", line 253, in data
    self._data = self.to_representation(self.instance)
  File "D:\Jafar\AAD\.env\lib\site-packages\rest_framework\serializers.py", line 522, in to_representation
    ret[field.field_name] = field.to_representation(attribute)
  File "D:\Jafar\AAD\.env\lib\site-packages\rest_framework\serializers.py", line 686, in to_representation
    return [
  File "D:\Jafar\AAD\.env\lib\site-packages\rest_framework\serializers.py", line 687, in <listcomp>
    self.child.to_representation(item) for item in iterable
  File "D:\Jafar\AAD\.env\lib\site-packages\rest_framework\serializers.py", line 522, in to_representation
    ret[field.field_name] = field.to_representation(attribute)
  File "D:\Jafar\AAD\.env\lib\site-packages\rest_framework\fields.py", line 1838, in to_representation
    return method(value)
  File "D:\Jafar\AAD\doctorsApp\serializers.py", line 156, in get_report
    print(data.patientFamilyMember_id)
AttributeError: 'familyMembers' object has no attribute 'patientFamilyMember_id'
[35;1mHTTP GET /doctor/api/ViewFamilyDetails/181/ 500 [0.52, 127.0.0.1:54099][0m
Internal Server Error: /doctor/api/ViewFamilyDetails/181/
Traceback (most recent call last):
  File "D:\Jafar\AAD\.env\lib\site-packages\asgiref\sync.py", line 534, in thread_handler
    raise exc_info[1]
  File "D:\Jafar\AAD\.env\lib\site-packages\django\core\handlers\exception.py", line 42, in inner
    response = await get_response(request)
  File "D:\Jafar\AAD\.env\lib\site-packages\django\core\handlers\base.py", line 253, in _get_response_async
    response = await wrapped_callback(
  File "D:\Jafar\AAD\.env\lib\site-packages\asgiref\sync.py", line 479, in __call__
    ret: _R = await loop.run_in_executor(
  File "C:\Program Files\WindowsApps\PythonSoftwareFoundation.Python.3.10_3.10.3056.0_x64__qbz5n2kfra8p0\lib\concurrent\futures\thread.py", line 58, in run
    result = self.fn(*self.args, **self.kwargs)
  File "D:\Jafar\AAD\.env\lib\site-packages\asgiref\sync.py", line 538, in thread_handler
    return func(*args, **kwargs)
  File "D:\Jafar\AAD\.env\lib\site-packages\django\views\decorators\csrf.py", line 56, in wrapper_view
    return view_func(*args, **kwargs)
  File "D:\Jafar\AAD\.env\lib\site-packages\django\views\generic\base.py", line 104, in view
    return self.dispatch(request, *args, **kwargs)
  File "D:\Jafar\AAD\.env\lib\site-packages\rest_framework\views.py", line 509, in dispatch
    response = self.handle_exception(exc)
  File "D:\Jafar\AAD\.env\lib\site-packages\rest_framework\views.py", line 469, in handle_exception
    self.raise_uncaught_exception(exc)
  File "D:\Jafar\AAD\.env\lib\site-packages\rest_framework\views.py", line 480, in raise_uncaught_exception
    raise exc
  File "D:\Jafar\AAD\.env\lib\site-packages\rest_framework\views.py", line 506, in dispatch
    response = handler(request, *args, **kwargs)
  File "D:\Jafar\AAD\.env\lib\site-packages\rest_framework\decorators.py", line 50, in handler
    return func(*args, **kwargs)
  File "D:\Jafar\AAD\doctorsApp\views.py", line 213, in ViewFamilyDetails
    testData  = serializer.data
  File "D:\Jafar\AAD\.env\lib\site-packages\rest_framework\serializers.py", line 555, in data
    ret = super().data
  File "D:\Jafar\AAD\.env\lib\site-packages\rest_framework\serializers.py", line 253, in data
    self._data = self.to_representation(self.instance)
  File "D:\Jafar\AAD\.env\lib\site-packages\rest_framework\serializers.py", line 522, in to_representation
    ret[field.field_name] = field.to_representation(attribute)
  File "D:\Jafar\AAD\.env\lib\site-packages\rest_framework\serializers.py", line 686, in to_representation
    return [
  File "D:\Jafar\AAD\.env\lib\site-packages\rest_framework\serializers.py", line 687, in <listcomp>
    self.child.to_representation(item) for item in iterable
  File "D:\Jafar\AAD\.env\lib\site-packages\rest_framework\serializers.py", line 522, in to_representation
    ret[field.field_name] = field.to_representation(attribute)
  File "D:\Jafar\AAD\.env\lib\site-packages\rest_framework\fields.py", line 1838, in to_representation
    return method(value)
  File "D:\Jafar\AAD\doctorsApp\serializers.py", line 156, in get_report
    print(data.patientFamilyMember())
TypeError: create_reverse_many_to_one_manager.<locals>.RelatedManager.__call__() missing 1 required keyword-only argument: 'manager'
[35;1mHTTP GET /doctor/api/ViewFamilyDetails/181/ 500 [0.20, 127.0.0.1:54128][0m
Internal Server Error: /doctor/api/ViewFamilyDetails/181/
Traceback (most recent call last):
  File "D:\Jafar\AAD\.env\lib\site-packages\asgiref\sync.py", line 534, in thread_handler
    raise exc_info[1]
  File "D:\Jafar\AAD\.env\lib\site-packages\django\core\handlers\exception.py", line 42, in inner
    response = await get_response(request)
  File "D:\Jafar\AAD\.env\lib\site-packages\django\core\handlers\base.py", line 253, in _get_response_async
    response = await wrapped_callback(
  File "D:\Jafar\AAD\.env\lib\site-packages\asgiref\sync.py", line 479, in __call__
    ret: _R = await loop.run_in_executor(
  File "C:\Program Files\WindowsApps\PythonSoftwareFoundation.Python.3.10_3.10.3056.0_x64__qbz5n2kfra8p0\lib\concurrent\futures\thread.py", line 58, in run
    result = self.fn(*self.args, **self.kwargs)
  File "D:\Jafar\AAD\.env\lib\site-packages\asgiref\sync.py", line 538, in thread_handler
    return func(*args, **kwargs)
  File "D:\Jafar\AAD\.env\lib\site-packages\django\views\decorators\csrf.py", line 56, in wrapper_view
    return view_func(*args, **kwargs)
  File "D:\Jafar\AAD\.env\lib\site-packages\django\views\generic\base.py", line 104, in view
    return self.dispatch(request, *args, **kwargs)
  File "D:\Jafar\AAD\.env\lib\site-packages\rest_framework\views.py", line 509, in dispatch
    response = self.handle_exception(exc)
  File "D:\Jafar\AAD\.env\lib\site-packages\rest_framework\views.py", line 469, in handle_exception
    self.raise_uncaught_exception(exc)
  File "D:\Jafar\AAD\.env\lib\site-packages\rest_framework\views.py", line 480, in raise_uncaught_exception
    raise exc
  File "D:\Jafar\AAD\.env\lib\site-packages\rest_framework\views.py", line 506, in dispatch
    response = handler(request, *args, **kwargs)
  File "D:\Jafar\AAD\.env\lib\site-packages\rest_framework\decorators.py", line 50, in handler
    return func(*args, **kwargs)
  File "D:\Jafar\AAD\doctorsApp\views.py", line 213, in ViewFamilyDetails
    testData  = serializer.data
  File "D:\Jafar\AAD\.env\lib\site-packages\rest_framework\serializers.py", line 555, in data
    ret = super().data
  File "D:\Jafar\AAD\.env\lib\site-packages\rest_framework\serializers.py", line 253, in data
    self._data = self.to_representation(self.instance)
  File "D:\Jafar\AAD\.env\lib\site-packages\rest_framework\serializers.py", line 522, in to_representation
    ret[field.field_name] = field.to_representation(attribute)
  File "D:\Jafar\AAD\.env\lib\site-packages\rest_framework\serializers.py", line 686, in to_representation
    return [
  File "D:\Jafar\AAD\.env\lib\site-packages\rest_framework\serializers.py", line 687, in <listcomp>
    self.child.to_representation(item) for item in iterable
  File "D:\Jafar\AAD\.env\lib\site-packages\rest_framework\serializers.py", line 522, in to_representation
    ret[field.field_name] = field.to_representation(attribute)
  File "D:\Jafar\AAD\.env\lib\site-packages\rest_framework\fields.py", line 1838, in to_representation
    return method(value)
  File "D:\Jafar\AAD\doctorsApp\serializers.py", line 156, in get_report
    print(data.patientFamilyMember.patientPathLabReports)
AttributeError: 'RelatedManager' object has no attribute 'patientPathLabReports'
[35;1mHTTP GET /doctor/api/ViewFamilyDetails/181/ 500 [0.13, 127.0.0.1:54231][0m
The joined path (D:\home\bgisadmin\AAD_backend\AAD_Backend\media\patientPathLabResults\Sanjay Guptae1af10a2-773d-4588-93ed-c36a5bc71059.pdf) is located outside of the base path component (D:\Jafar\AAD\media)
Traceback (most recent call last):
  File "D:\Jafar\AAD\.env\lib\site-packages\asgiref\sync.py", line 534, in thread_handler
    raise exc_info[1]
  File "D:\Jafar\AAD\.env\lib\site-packages\django\core\handlers\exception.py", line 42, in inner
    response = await get_response(request)
  File "D:\Jafar\AAD\.env\lib\site-packages\django\core\handlers\base.py", line 284, in _get_response_async
    response = await sync_to_async(
  File "D:\Jafar\AAD\.env\lib\site-packages\asgiref\sync.py", line 479, in __call__
    ret: _R = await loop.run_in_executor(
  File "C:\Program Files\WindowsApps\PythonSoftwareFoundation.Python.3.10_3.10.3056.0_x64__qbz5n2kfra8p0\lib\concurrent\futures\thread.py", line 58, in run
    result = self.fn(*self.args, **self.kwargs)
  File "D:\Jafar\AAD\.env\lib\site-packages\asgiref\sync.py", line 538, in thread_handler
    return func(*args, **kwargs)
  File "D:\Jafar\AAD\.env\lib\site-packages\django\template\response.py", line 114, in render
    self.content = self.rendered_content
  File "D:\Jafar\AAD\.env\lib\site-packages\rest_framework\response.py", line 70, in rendered_content
    ret = renderer.render(self.data, accepted_media_type, context)
  File "D:\Jafar\AAD\.env\lib\site-packages\rest_framework\renderers.py", line 99, in render
    ret = json.dumps(
  File "D:\Jafar\AAD\.env\lib\site-packages\rest_framework\utils\json.py", line 25, in dumps
    return json.dumps(*args, **kwargs)
  File "C:\Program Files\WindowsApps\PythonSoftwareFoundation.Python.3.10_3.10.3056.0_x64__qbz5n2kfra8p0\lib\json\__init__.py", line 238, in dumps
    **kw).encode(obj)
  File "C:\Program Files\WindowsApps\PythonSoftwareFoundation.Python.3.10_3.10.3056.0_x64__qbz5n2kfra8p0\lib\json\encoder.py", line 199, in encode
    chunks = self.iterencode(o, _one_shot=True)
  File "C:\Program Files\WindowsApps\PythonSoftwareFoundation.Python.3.10_3.10.3056.0_x64__qbz5n2kfra8p0\lib\json\encoder.py", line 257, in iterencode
    return _iterencode(o, 0)
  File "D:\Jafar\AAD\.env\lib\site-packages\rest_framework\utils\encoders.py", line 66, in default
    return tuple(item for item in obj)
  File "D:\Jafar\AAD\.env\lib\site-packages\rest_framework\utils\encoders.py", line 66, in <genexpr>
    return tuple(item for item in obj)
  File "D:\Jafar\AAD\.env\lib\site-packages\django\core\files\base.py", line 78, in __iter__
    for chunk in self.chunks():
  File "D:\Jafar\AAD\.env\lib\site-packages\django\core\files\base.py", line 55, in chunks
    self.seek(0)
  File "D:\Jafar\AAD\.env\lib\site-packages\django\core\files\utils.py", line 46, in <lambda>
    seek = property(lambda self: self.file.seek)
  File "D:\Jafar\AAD\.env\lib\site-packages\django\db\models\fields\files.py", line 48, in _get_file
    self._file = self.storage.open(self.name, "rb")
  File "D:\Jafar\AAD\.env\lib\site-packages\django\core\files\storage\base.py", line 22, in open
    return self._open(name, mode)
  File "D:\Jafar\AAD\.env\lib\site-packages\django\core\files\storage\filesystem.py", line 68, in _open
    return File(open(self.path(name), mode))
  File "D:\Jafar\AAD\.env\lib\site-packages\django\core\files\storage\filesystem.py", line 179, in path
    return safe_join(self.location, name)
  File "D:\Jafar\AAD\.env\lib\site-packages\django\utils\_os.py", line 31, in safe_join
    raise SuspiciousFileOperation(
django.core.exceptions.SuspiciousFileOperation: The joined path (D:\home\bgisadmin\AAD_backend\AAD_Backend\media\patientPathLabResults\Sanjay Guptae1af10a2-773d-4588-93ed-c36a5bc71059.pdf) is located outside of the base path component (D:\Jafar\AAD\media)
Bad Request: /doctor/api/ViewFamilyDetails/181/
[31;1mHTTP GET /doctor/api/ViewFamilyDetails/181/ 400 [0.24, 127.0.0.1:54570][0m
The joined path (D:\home\bgisadmin\AAD_backend\AAD_Backend\media\patientPathLabResults\Sanjay Guptae1af10a2-773d-4588-93ed-c36a5bc71059.pdf) is located outside of the base path component (D:\Jafar\AAD\media)
Traceback (most recent call last):
  File "D:\Jafar\AAD\.env\lib\site-packages\asgiref\sync.py", line 534, in thread_handler
    raise exc_info[1]
  File "D:\Jafar\AAD\.env\lib\site-packages\django\core\handlers\exception.py", line 42, in inner
    response = await get_response(request)
  File "D:\Jafar\AAD\.env\lib\site-packages\django\core\handlers\base.py", line 284, in _get_response_async
    response = await sync_to_async(
  File "D:\Jafar\AAD\.env\lib\site-packages\asgiref\sync.py", line 479, in __call__
    ret: _R = await loop.run_in_executor(
  File "C:\Program Files\WindowsApps\PythonSoftwareFoundation.Python.3.10_3.10.3056.0_x64__qbz5n2kfra8p0\lib\concurrent\futures\thread.py", line 58, in run
    result = self.fn(*self.args, **self.kwargs)
  File "D:\Jafar\AAD\.env\lib\site-packages\asgiref\sync.py", line 538, in thread_handler
    return func(*args, **kwargs)
  File "D:\Jafar\AAD\.env\lib\site-packages\django\template\response.py", line 114, in render
    self.content = self.rendered_content
  File "D:\Jafar\AAD\.env\lib\site-packages\rest_framework\response.py", line 70, in rendered_content
    ret = renderer.render(self.data, accepted_media_type, context)
  File "D:\Jafar\AAD\.env\lib\site-packages\rest_framework\renderers.py", line 99, in render
    ret = json.dumps(
  File "D:\Jafar\AAD\.env\lib\site-packages\rest_framework\utils\json.py", line 25, in dumps
    return json.dumps(*args, **kwargs)
  File "C:\Program Files\WindowsApps\PythonSoftwareFoundation.Python.3.10_3.10.3056.0_x64__qbz5n2kfra8p0\lib\json\__init__.py", line 238, in dumps
    **kw).encode(obj)
  File "C:\Program Files\WindowsApps\PythonSoftwareFoundation.Python.3.10_3.10.3056.0_x64__qbz5n2kfra8p0\lib\json\encoder.py", line 199, in encode
    chunks = self.iterencode(o, _one_shot=True)
  File "C:\Program Files\WindowsApps\PythonSoftwareFoundation.Python.3.10_3.10.3056.0_x64__qbz5n2kfra8p0\lib\json\encoder.py", line 257, in iterencode
    return _iterencode(o, 0)
  File "D:\Jafar\AAD\.env\lib\site-packages\rest_framework\utils\encoders.py", line 66, in default
    return tuple(item for item in obj)
  File "D:\Jafar\AAD\.env\lib\site-packages\rest_framework\utils\encoders.py", line 66, in <genexpr>
    return tuple(item for item in obj)
  File "D:\Jafar\AAD\.env\lib\site-packages\django\core\files\base.py", line 78, in __iter__
    for chunk in self.chunks():
  File "D:\Jafar\AAD\.env\lib\site-packages\django\core\files\base.py", line 55, in chunks
    self.seek(0)
  File "D:\Jafar\AAD\.env\lib\site-packages\django\core\files\utils.py", line 46, in <lambda>
    seek = property(lambda self: self.file.seek)
  File "D:\Jafar\AAD\.env\lib\site-packages\django\db\models\fields\files.py", line 48, in _get_file
    self._file = self.storage.open(self.name, "rb")
  File "D:\Jafar\AAD\.env\lib\site-packages\django\core\files\storage\base.py", line 22, in open
    return self._open(name, mode)
  File "D:\Jafar\AAD\.env\lib\site-packages\django\core\files\storage\filesystem.py", line 68, in _open
    return File(open(self.path(name), mode))
  File "D:\Jafar\AAD\.env\lib\site-packages\django\core\files\storage\filesystem.py", line 179, in path
    return safe_join(self.location, name)
  File "D:\Jafar\AAD\.env\lib\site-packages\django\utils\_os.py", line 31, in safe_join
    raise SuspiciousFileOperation(
django.core.exceptions.SuspiciousFileOperation: The joined path (D:\home\bgisadmin\AAD_backend\AAD_Backend\media\patientPathLabResults\Sanjay Guptae1af10a2-773d-4588-93ed-c36a5bc71059.pdf) is located outside of the base path component (D:\Jafar\AAD\media)
Bad Request: /doctor/api/ViewFamilyDetails/181/
[31;1mHTTP GET /doctor/api/ViewFamilyDetails/181/ 400 [0.19, 127.0.0.1:54774][0m
The joined path (D:\home\bgisadmin\AAD_backend\AAD_Backend\media\patientPathLabResults\SanjayGuptae1af10a2-773d-4588-93ed-c36a5bc71059.pdf) is located outside of the base path component (D:\Jafar\AAD\media)
Traceback (most recent call last):
  File "D:\Jafar\AAD\.env\lib\site-packages\asgiref\sync.py", line 534, in thread_handler
    raise exc_info[1]
  File "D:\Jafar\AAD\.env\lib\site-packages\django\core\handlers\exception.py", line 42, in inner
    response = await get_response(request)
  File "D:\Jafar\AAD\.env\lib\site-packages\django\core\handlers\base.py", line 284, in _get_response_async
    response = await sync_to_async(
  File "D:\Jafar\AAD\.env\lib\site-packages\asgiref\sync.py", line 479, in __call__
    ret: _R = await loop.run_in_executor(
  File "C:\Program Files\WindowsApps\PythonSoftwareFoundation.Python.3.10_3.10.3056.0_x64__qbz5n2kfra8p0\lib\concurrent\futures\thread.py", line 58, in run
    result = self.fn(*self.args, **self.kwargs)
  File "D:\Jafar\AAD\.env\lib\site-packages\asgiref\sync.py", line 538, in thread_handler
    return func(*args, **kwargs)
  File "D:\Jafar\AAD\.env\lib\site-packages\django\template\response.py", line 114, in render
    self.content = self.rendered_content
  File "D:\Jafar\AAD\.env\lib\site-packages\rest_framework\response.py", line 70, in rendered_content
    ret = renderer.render(self.data, accepted_media_type, context)
  File "D:\Jafar\AAD\.env\lib\site-packages\rest_framework\renderers.py", line 99, in render
    ret = json.dumps(
  File "D:\Jafar\AAD\.env\lib\site-packages\rest_framework\utils\json.py", line 25, in dumps
    return json.dumps(*args, **kwargs)
  File "C:\Program Files\WindowsApps\PythonSoftwareFoundation.Python.3.10_3.10.3056.0_x64__qbz5n2kfra8p0\lib\json\__init__.py", line 238, in dumps
    **kw).encode(obj)
  File "C:\Program Files\WindowsApps\PythonSoftwareFoundation.Python.3.10_3.10.3056.0_x64__qbz5n2kfra8p0\lib\json\encoder.py", line 199, in encode
    chunks = self.iterencode(o, _one_shot=True)
  File "C:\Program Files\WindowsApps\PythonSoftwareFoundation.Python.3.10_3.10.3056.0_x64__qbz5n2kfra8p0\lib\json\encoder.py", line 257, in iterencode
    return _iterencode(o, 0)
  File "D:\Jafar\AAD\.env\lib\site-packages\rest_framework\utils\encoders.py", line 66, in default
    return tuple(item for item in obj)
  File "D:\Jafar\AAD\.env\lib\site-packages\rest_framework\utils\encoders.py", line 66, in <genexpr>
    return tuple(item for item in obj)
  File "D:\Jafar\AAD\.env\lib\site-packages\django\core\files\base.py", line 78, in __iter__
    for chunk in self.chunks():
  File "D:\Jafar\AAD\.env\lib\site-packages\django\core\files\base.py", line 55, in chunks
    self.seek(0)
  File "D:\Jafar\AAD\.env\lib\site-packages\django\core\files\utils.py", line 46, in <lambda>
    seek = property(lambda self: self.file.seek)
  File "D:\Jafar\AAD\.env\lib\site-packages\django\db\models\fields\files.py", line 48, in _get_file
    self._file = self.storage.open(self.name, "rb")
  File "D:\Jafar\AAD\.env\lib\site-packages\django\core\files\storage\base.py", line 22, in open
    return self._open(name, mode)
  File "D:\Jafar\AAD\.env\lib\site-packages\django\core\files\storage\filesystem.py", line 68, in _open
    return File(open(self.path(name), mode))
  File "D:\Jafar\AAD\.env\lib\site-packages\django\core\files\storage\filesystem.py", line 179, in path
    return safe_join(self.location, name)
  File "D:\Jafar\AAD\.env\lib\site-packages\django\utils\_os.py", line 31, in safe_join
    raise SuspiciousFileOperation(
django.core.exceptions.SuspiciousFileOperation: The joined path (D:\home\bgisadmin\AAD_backend\AAD_Backend\media\patientPathLabResults\SanjayGuptae1af10a2-773d-4588-93ed-c36a5bc71059.pdf) is located outside of the base path component (D:\Jafar\AAD\media)
Bad Request: /doctor/api/ViewFamilyDetails/181/
[31;1mHTTP GET /doctor/api/ViewFamilyDetails/181/ 400 [0.17, 127.0.0.1:55004][0m
Internal Server Error: /doctor/api/ViewFamilyDetails/181/
Traceback (most recent call last):
  File "D:\Jafar\AAD\.env\lib\site-packages\asgiref\sync.py", line 534, in thread_handler
    raise exc_info[1]
  File "D:\Jafar\AAD\.env\lib\site-packages\django\core\handlers\exception.py", line 42, in inner
    response = await get_response(request)
  File "D:\Jafar\AAD\.env\lib\site-packages\django\core\handlers\base.py", line 284, in _get_response_async
    response = await sync_to_async(
  File "D:\Jafar\AAD\.env\lib\site-packages\asgiref\sync.py", line 479, in __call__
    ret: _R = await loop.run_in_executor(
  File "C:\Program Files\WindowsApps\PythonSoftwareFoundation.Python.3.10_3.10.3056.0_x64__qbz5n2kfra8p0\lib\concurrent\futures\thread.py", line 58, in run
    result = self.fn(*self.args, **self.kwargs)
  File "D:\Jafar\AAD\.env\lib\site-packages\asgiref\sync.py", line 538, in thread_handler
    return func(*args, **kwargs)
  File "D:\Jafar\AAD\.env\lib\site-packages\django\template\response.py", line 114, in render
    self.content = self.rendered_content
  File "D:\Jafar\AAD\.env\lib\site-packages\rest_framework\response.py", line 70, in rendered_content
    ret = renderer.render(self.data, accepted_media_type, context)
  File "D:\Jafar\AAD\.env\lib\site-packages\rest_framework\renderers.py", line 99, in render
    ret = json.dumps(
  File "D:\Jafar\AAD\.env\lib\site-packages\rest_framework\utils\json.py", line 25, in dumps
    return json.dumps(*args, **kwargs)
  File "C:\Program Files\WindowsApps\PythonSoftwareFoundation.Python.3.10_3.10.3056.0_x64__qbz5n2kfra8p0\lib\json\__init__.py", line 238, in dumps
    **kw).encode(obj)
  File "C:\Program Files\WindowsApps\PythonSoftwareFoundation.Python.3.10_3.10.3056.0_x64__qbz5n2kfra8p0\lib\json\encoder.py", line 199, in encode
    chunks = self.iterencode(o, _one_shot=True)
  File "C:\Program Files\WindowsApps\PythonSoftwareFoundation.Python.3.10_3.10.3056.0_x64__qbz5n2kfra8p0\lib\json\encoder.py", line 257, in iterencode
    return _iterencode(o, 0)
  File "D:\Jafar\AAD\.env\lib\site-packages\rest_framework\utils\encoders.py", line 50, in default
    return obj.decode()
UnicodeDecodeError: 'utf-8' codec can't decode byte 0xe2 in position 1: invalid continuation byte
[35;1mHTTP GET /doctor/api/ViewFamilyDetails/181/ 500 [0.30, 127.0.0.1:55889][0m
Internal Server Error: /doctor/api/ViewFamilyDetails/181/
Traceback (most recent call last):
  File "D:\Jafar\AAD\.env\lib\site-packages\asgiref\sync.py", line 534, in thread_handler
    raise exc_info[1]
  File "D:\Jafar\AAD\.env\lib\site-packages\django\core\handlers\exception.py", line 42, in inner
    response = await get_response(request)
  File "D:\Jafar\AAD\.env\lib\site-packages\django\core\handlers\base.py", line 253, in _get_response_async
    response = await wrapped_callback(
  File "D:\Jafar\AAD\.env\lib\site-packages\asgiref\sync.py", line 479, in __call__
    ret: _R = await loop.run_in_executor(
  File "C:\Program Files\WindowsApps\PythonSoftwareFoundation.Python.3.10_3.10.3056.0_x64__qbz5n2kfra8p0\lib\concurrent\futures\thread.py", line 58, in run
    result = self.fn(*self.args, **self.kwargs)
  File "D:\Jafar\AAD\.env\lib\site-packages\asgiref\sync.py", line 538, in thread_handler
    return func(*args, **kwargs)
  File "D:\Jafar\AAD\.env\lib\site-packages\django\views\decorators\csrf.py", line 56, in wrapper_view
    return view_func(*args, **kwargs)
  File "D:\Jafar\AAD\.env\lib\site-packages\django\views\generic\base.py", line 104, in view
    return self.dispatch(request, *args, **kwargs)
  File "D:\Jafar\AAD\.env\lib\site-packages\rest_framework\views.py", line 509, in dispatch
    response = self.handle_exception(exc)
  File "D:\Jafar\AAD\.env\lib\site-packages\rest_framework\views.py", line 469, in handle_exception
    self.raise_uncaught_exception(exc)
  File "D:\Jafar\AAD\.env\lib\site-packages\rest_framework\views.py", line 480, in raise_uncaught_exception
    raise exc
  File "D:\Jafar\AAD\.env\lib\site-packages\rest_framework\views.py", line 506, in dispatch
    response = handler(request, *args, **kwargs)
  File "D:\Jafar\AAD\.env\lib\site-packages\rest_framework\decorators.py", line 50, in handler
    return func(*args, **kwargs)
  File "D:\Jafar\AAD\doctorsApp\views.py", line 213, in ViewFamilyDetails
    testData  = serializer.data
  File "D:\Jafar\AAD\.env\lib\site-packages\rest_framework\serializers.py", line 555, in data
    ret = super().data
  File "D:\Jafar\AAD\.env\lib\site-packages\rest_framework\serializers.py", line 253, in data
    self._data = self.to_representation(self.instance)
  File "D:\Jafar\AAD\.env\lib\site-packages\rest_framework\serializers.py", line 522, in to_representation
    ret[field.field_name] = field.to_representation(attribute)
  File "D:\Jafar\AAD\.env\lib\site-packages\rest_framework\serializers.py", line 686, in to_representation
    return [
  File "D:\Jafar\AAD\.env\lib\site-packages\rest_framework\serializers.py", line 687, in <listcomp>
    self.child.to_representation(item) for item in iterable
  File "D:\Jafar\AAD\.env\lib\site-packages\rest_framework\serializers.py", line 507, in to_representation
    for field in fields:
  File "D:\Jafar\AAD\.env\lib\site-packages\rest_framework\serializers.py", line 368, in _readable_fields
    for field in self.fields.values():
  File "D:\Jafar\AAD\.env\lib\site-packages\django\utils\functional.py", line 57, in __get__
    res = instance.__dict__[self.name] = self.func(instance)
  File "D:\Jafar\AAD\.env\lib\site-packages\rest_framework\serializers.py", line 356, in fields
    for key, value in self.get_fields().items():
  File "D:\Jafar\AAD\.env\lib\site-packages\rest_framework\serializers.py", line 1076, in get_fields
    field_class, field_kwargs = self.build_field(
  File "D:\Jafar\AAD\.env\lib\site-packages\rest_framework\serializers.py", line 1222, in build_field
    return self.build_unknown_field(field_name, model_class)
  File "D:\Jafar\AAD\.env\lib\site-packages\rest_framework\serializers.py", line 1340, in build_unknown_field
    raise ImproperlyConfigured(
django.core.exceptions.ImproperlyConfigured: Field name `patientFamilyMember__patientPathLabReports` is not valid for model `familyMembers`.
[35;1mHTTP GET /doctor/api/ViewFamilyDetails/181/ 500 [0.12, 127.0.0.1:56311][0m
Internal Server Error: /doctor/api/ViewFamilyDetails/181/
Traceback (most recent call last):
  File "D:\Jafar\AAD\.env\lib\site-packages\asgiref\sync.py", line 534, in thread_handler
    raise exc_info[1]
  File "D:\Jafar\AAD\.env\lib\site-packages\django\core\handlers\exception.py", line 42, in inner
    response = await get_response(request)
  File "D:\Jafar\AAD\.env\lib\site-packages\django\core\handlers\base.py", line 284, in _get_response_async
    response = await sync_to_async(
  File "D:\Jafar\AAD\.env\lib\site-packages\asgiref\sync.py", line 479, in __call__
    ret: _R = await loop.run_in_executor(
  File "C:\Program Files\WindowsApps\PythonSoftwareFoundation.Python.3.10_3.10.3056.0_x64__qbz5n2kfra8p0\lib\concurrent\futures\thread.py", line 58, in run
    result = self.fn(*self.args, **self.kwargs)
  File "D:\Jafar\AAD\.env\lib\site-packages\asgiref\sync.py", line 538, in thread_handler
    return func(*args, **kwargs)
  File "D:\Jafar\AAD\.env\lib\site-packages\django\template\response.py", line 114, in render
    self.content = self.rendered_content
  File "D:\Jafar\AAD\.env\lib\site-packages\rest_framework\response.py", line 70, in rendered_content
    ret = renderer.render(self.data, accepted_media_type, context)
  File "D:\Jafar\AAD\.env\lib\site-packages\rest_framework\renderers.py", line 99, in render
    ret = json.dumps(
  File "D:\Jafar\AAD\.env\lib\site-packages\rest_framework\utils\json.py", line 25, in dumps
    return json.dumps(*args, **kwargs)
  File "C:\Program Files\WindowsApps\PythonSoftwareFoundation.Python.3.10_3.10.3056.0_x64__qbz5n2kfra8p0\lib\json\__init__.py", line 238, in dumps
    **kw).encode(obj)
  File "C:\Program Files\WindowsApps\PythonSoftwareFoundation.Python.3.10_3.10.3056.0_x64__qbz5n2kfra8p0\lib\json\encoder.py", line 199, in encode
    chunks = self.iterencode(o, _one_shot=True)
  File "C:\Program Files\WindowsApps\PythonSoftwareFoundation.Python.3.10_3.10.3056.0_x64__qbz5n2kfra8p0\lib\json\encoder.py", line 257, in iterencode
    return _iterencode(o, 0)
  File "D:\Jafar\AAD\.env\lib\site-packages\rest_framework\utils\encoders.py", line 50, in default
    return obj.decode()
UnicodeDecodeError: 'utf-8' codec can't decode byte 0xe2 in position 1: invalid continuation byte
[35;1mHTTP GET /doctor/api/ViewFamilyDetails/181/ 500 [0.34, 127.0.0.1:56360][0m
Internal Server Error: /doctor/api/ViewFamilyDetails/181/
Traceback (most recent call last):
  File "D:\Jafar\AAD\.env\lib\site-packages\asgiref\sync.py", line 534, in thread_handler
    raise exc_info[1]
  File "D:\Jafar\AAD\.env\lib\site-packages\django\core\handlers\exception.py", line 42, in inner
    response = await get_response(request)
  File "D:\Jafar\AAD\.env\lib\site-packages\django\core\handlers\base.py", line 284, in _get_response_async
    response = await sync_to_async(
  File "D:\Jafar\AAD\.env\lib\site-packages\asgiref\sync.py", line 479, in __call__
    ret: _R = await loop.run_in_executor(
  File "C:\Program Files\WindowsApps\PythonSoftwareFoundation.Python.3.10_3.10.3056.0_x64__qbz5n2kfra8p0\lib\concurrent\futures\thread.py", line 58, in run
    result = self.fn(*self.args, **self.kwargs)
  File "D:\Jafar\AAD\.env\lib\site-packages\asgiref\sync.py", line 538, in thread_handler
    return func(*args, **kwargs)
  File "D:\Jafar\AAD\.env\lib\site-packages\django\template\response.py", line 114, in render
    self.content = self.rendered_content
  File "D:\Jafar\AAD\.env\lib\site-packages\rest_framework\response.py", line 70, in rendered_content
    ret = renderer.render(self.data, accepted_media_type, context)
  File "D:\Jafar\AAD\.env\lib\site-packages\rest_framework\renderers.py", line 99, in render
    ret = json.dumps(
  File "D:\Jafar\AAD\.env\lib\site-packages\rest_framework\utils\json.py", line 25, in dumps
    return json.dumps(*args, **kwargs)
  File "C:\Program Files\WindowsApps\PythonSoftwareFoundation.Python.3.10_3.10.3056.0_x64__qbz5n2kfra8p0\lib\json\__init__.py", line 238, in dumps
    **kw).encode(obj)
  File "C:\Program Files\WindowsApps\PythonSoftwareFoundation.Python.3.10_3.10.3056.0_x64__qbz5n2kfra8p0\lib\json\encoder.py", line 199, in encode
    chunks = self.iterencode(o, _one_shot=True)
  File "C:\Program Files\WindowsApps\PythonSoftwareFoundation.Python.3.10_3.10.3056.0_x64__qbz5n2kfra8p0\lib\json\encoder.py", line 257, in iterencode
    return _iterencode(o, 0)
  File "D:\Jafar\AAD\.env\lib\site-packages\rest_framework\utils\encoders.py", line 50, in default
    return obj.decode()
UnicodeDecodeError: 'utf-8' codec can't decode byte 0xe2 in position 1: invalid continuation byte
[35;1mHTTP GET /doctor/api/ViewFamilyDetails/181/ 500 [0.34, 127.0.0.1:56396][0m
Internal Server Error: /doctor/api/ViewFamilyDetails/181/
Traceback (most recent call last):
  File "D:\Jafar\AAD\.env\lib\site-packages\asgiref\sync.py", line 534, in thread_handler
    raise exc_info[1]
  File "D:\Jafar\AAD\.env\lib\site-packages\django\core\handlers\exception.py", line 42, in inner
    response = await get_response(request)
  File "D:\Jafar\AAD\.env\lib\site-packages\django\core\handlers\base.py", line 284, in _get_response_async
    response = await sync_to_async(
  File "D:\Jafar\AAD\.env\lib\site-packages\asgiref\sync.py", line 479, in __call__
    ret: _R = await loop.run_in_executor(
  File "C:\Program Files\WindowsApps\PythonSoftwareFoundation.Python.3.10_3.10.3056.0_x64__qbz5n2kfra8p0\lib\concurrent\futures\thread.py", line 58, in run
    result = self.fn(*self.args, **self.kwargs)
  File "D:\Jafar\AAD\.env\lib\site-packages\asgiref\sync.py", line 538, in thread_handler
    return func(*args, **kwargs)
  File "D:\Jafar\AAD\.env\lib\site-packages\django\template\response.py", line 114, in render
    self.content = self.rendered_content
  File "D:\Jafar\AAD\.env\lib\site-packages\rest_framework\response.py", line 70, in rendered_content
    ret = renderer.render(self.data, accepted_media_type, context)
  File "D:\Jafar\AAD\.env\lib\site-packages\rest_framework\renderers.py", line 99, in render
    ret = json.dumps(
  File "D:\Jafar\AAD\.env\lib\site-packages\rest_framework\utils\json.py", line 25, in dumps
    return json.dumps(*args, **kwargs)
  File "C:\Program Files\WindowsApps\PythonSoftwareFoundation.Python.3.10_3.10.3056.0_x64__qbz5n2kfra8p0\lib\json\__init__.py", line 238, in dumps
    **kw).encode(obj)
  File "C:\Program Files\WindowsApps\PythonSoftwareFoundation.Python.3.10_3.10.3056.0_x64__qbz5n2kfra8p0\lib\json\encoder.py", line 199, in encode
    chunks = self.iterencode(o, _one_shot=True)
  File "C:\Program Files\WindowsApps\PythonSoftwareFoundation.Python.3.10_3.10.3056.0_x64__qbz5n2kfra8p0\lib\json\encoder.py", line 257, in iterencode
    return _iterencode(o, 0)
  File "D:\Jafar\AAD\.env\lib\site-packages\rest_framework\utils\encoders.py", line 50, in default
    return obj.decode()
UnicodeDecodeError: 'utf-8' codec can't decode byte 0xe2 in position 1: invalid continuation byte
[35;1mHTTP GET /doctor/api/ViewFamilyDetails/181/ 500 [0.32, 127.0.0.1:56429][0m
Internal Server Error: /doctor/api/ViewFamilyDetails/180/
Traceback (most recent call last):
  File "D:\Jafar\AAD\.env\lib\site-packages\asgiref\sync.py", line 534, in thread_handler
    raise exc_info[1]
  File "D:\Jafar\AAD\.env\lib\site-packages\django\core\handlers\exception.py", line 42, in inner
    response = await get_response(request)
  File "D:\Jafar\AAD\.env\lib\site-packages\django\core\handlers\base.py", line 253, in _get_response_async
    response = await wrapped_callback(
  File "D:\Jafar\AAD\.env\lib\site-packages\asgiref\sync.py", line 479, in __call__
    ret: _R = await loop.run_in_executor(
  File "C:\Program Files\WindowsApps\PythonSoftwareFoundation.Python.3.10_3.10.3056.0_x64__qbz5n2kfra8p0\lib\concurrent\futures\thread.py", line 58, in run
    result = self.fn(*self.args, **self.kwargs)
  File "D:\Jafar\AAD\.env\lib\site-packages\asgiref\sync.py", line 538, in thread_handler
    return func(*args, **kwargs)
  File "D:\Jafar\AAD\.env\lib\site-packages\django\views\decorators\csrf.py", line 56, in wrapper_view
    return view_func(*args, **kwargs)
  File "D:\Jafar\AAD\.env\lib\site-packages\django\views\generic\base.py", line 104, in view
    return self.dispatch(request, *args, **kwargs)
  File "D:\Jafar\AAD\.env\lib\site-packages\rest_framework\views.py", line 509, in dispatch
    response = self.handle_exception(exc)
  File "D:\Jafar\AAD\.env\lib\site-packages\rest_framework\views.py", line 469, in handle_exception
    self.raise_uncaught_exception(exc)
  File "D:\Jafar\AAD\.env\lib\site-packages\rest_framework\views.py", line 480, in raise_uncaught_exception
    raise exc
  File "D:\Jafar\AAD\.env\lib\site-packages\rest_framework\views.py", line 506, in dispatch
    response = handler(request, *args, **kwargs)
  File "D:\Jafar\AAD\.env\lib\site-packages\rest_framework\decorators.py", line 50, in handler
    return func(*args, **kwargs)
  File "D:\Jafar\AAD\doctorsApp\views.py", line 213, in ViewFamilyDetails
    testData  = serializer.data
  File "D:\Jafar\AAD\.env\lib\site-packages\rest_framework\serializers.py", line 555, in data
    ret = super().data
  File "D:\Jafar\AAD\.env\lib\site-packages\rest_framework\serializers.py", line 253, in data
    self._data = self.to_representation(self.instance)
  File "D:\Jafar\AAD\.env\lib\site-packages\rest_framework\serializers.py", line 522, in to_representation
    ret[field.field_name] = field.to_representation(attribute)
  File "D:\Jafar\AAD\.env\lib\site-packages\rest_framework\serializers.py", line 686, in to_representation
    return [
  File "D:\Jafar\AAD\.env\lib\site-packages\rest_framework\serializers.py", line 687, in <listcomp>
    self.child.to_representation(item) for item in iterable
  File "D:\Jafar\AAD\.env\lib\site-packages\rest_framework\serializers.py", line 522, in to_representation
    ret[field.field_name] = field.to_representation(attribute)
  File "D:\Jafar\AAD\.env\lib\site-packages\rest_framework\fields.py", line 1838, in to_representation
    return method(value)
  File "D:\Jafar\AAD\doctorsApp\serializers.py", line 167, in get_report
    return pdf_url
UnboundLocalError: local variable 'pdf_url' referenced before assignment
[35;1mHTTP GET /doctor/api/ViewFamilyDetails/180/ 500 [0.25, 127.0.0.1:56672][0m
Internal Server Error: /doctor/api/ViewFamilyDetails/180/
Traceback (most recent call last):
  File "D:\Jafar\AAD\.env\lib\site-packages\asgiref\sync.py", line 534, in thread_handler
    raise exc_info[1]
  File "D:\Jafar\AAD\.env\lib\site-packages\django\core\handlers\exception.py", line 42, in inner
    response = await get_response(request)
  File "D:\Jafar\AAD\.env\lib\site-packages\django\core\handlers\base.py", line 253, in _get_response_async
    response = await wrapped_callback(
  File "D:\Jafar\AAD\.env\lib\site-packages\asgiref\sync.py", line 479, in __call__
    ret: _R = await loop.run_in_executor(
  File "C:\Program Files\WindowsApps\PythonSoftwareFoundation.Python.3.10_3.10.3056.0_x64__qbz5n2kfra8p0\lib\concurrent\futures\thread.py", line 58, in run
    result = self.fn(*self.args, **self.kwargs)
  File "D:\Jafar\AAD\.env\lib\site-packages\asgiref\sync.py", line 538, in thread_handler
    return func(*args, **kwargs)
  File "D:\Jafar\AAD\.env\lib\site-packages\django\views\decorators\csrf.py", line 56, in wrapper_view
    return view_func(*args, **kwargs)
  File "D:\Jafar\AAD\.env\lib\site-packages\django\views\generic\base.py", line 104, in view
    return self.dispatch(request, *args, **kwargs)
  File "D:\Jafar\AAD\.env\lib\site-packages\rest_framework\views.py", line 509, in dispatch
    response = self.handle_exception(exc)
  File "D:\Jafar\AAD\.env\lib\site-packages\rest_framework\views.py", line 469, in handle_exception
    self.raise_uncaught_exception(exc)
  File "D:\Jafar\AAD\.env\lib\site-packages\rest_framework\views.py", line 480, in raise_uncaught_exception
    raise exc
  File "D:\Jafar\AAD\.env\lib\site-packages\rest_framework\views.py", line 506, in dispatch
    response = handler(request, *args, **kwargs)
  File "D:\Jafar\AAD\.env\lib\site-packages\rest_framework\decorators.py", line 50, in handler
    return func(*args, **kwargs)
  File "D:\Jafar\AAD\doctorsApp\views.py", line 213, in ViewFamilyDetails
    testData  = serializer.data
  File "D:\Jafar\AAD\.env\lib\site-packages\rest_framework\serializers.py", line 555, in data
    ret = super().data
  File "D:\Jafar\AAD\.env\lib\site-packages\rest_framework\serializers.py", line 253, in data
    self._data = self.to_representation(self.instance)
  File "D:\Jafar\AAD\.env\lib\site-packages\rest_framework\serializers.py", line 522, in to_representation
    ret[field.field_name] = field.to_representation(attribute)
  File "D:\Jafar\AAD\.env\lib\site-packages\rest_framework\serializers.py", line 686, in to_representation
    return [
  File "D:\Jafar\AAD\.env\lib\site-packages\rest_framework\serializers.py", line 687, in <listcomp>
    self.child.to_representation(item) for item in iterable
  File "D:\Jafar\AAD\.env\lib\site-packages\rest_framework\serializers.py", line 522, in to_representation
    ret[field.field_name] = field.to_representation(attribute)
  File "D:\Jafar\AAD\.env\lib\site-packages\rest_framework\fields.py", line 1838, in to_representation
    return method(value)
  File "D:\Jafar\AAD\doctorsApp\serializers.py", line 168, in get_report
    return pdf_url
UnboundLocalError: local variable 'pdf_url' referenced before assignment
[35;1mHTTP GET /doctor/api/ViewFamilyDetails/180/ 500 [0.15, 127.0.0.1:56710][0m
