view's UpdateUserDetails raised exception during schema generation; use `getattr(self, 'swagger_fake_view', False)` to detect and short-circuit this
Traceback (most recent call last):
  File "D:\Jafar\AAD\.env\lib\site-packages\drf_yasg\inspectors\base.py", line 42, in call_view_method
    return view_method()
  File "D:\Jafar\AAD\.env\lib\site-packages\rest_framework\generics.py", line 63, in get_queryset
    assert self.queryset is not None, (
AssertionError: 'UpdateUserDetails' should either include a `queryset` attribute, or override the `get_queryset()` method.
view's UpdateUserDetails raised exception during schema generation; use `getattr(self, 'swagger_fake_view', False)` to detect and short-circuit this
Traceback (most recent call last):
  File "D:\Jafar\AAD\.env\lib\site-packages\drf_yasg\inspectors\base.py", line 42, in call_view_method
    return view_method()
  File "D:\Jafar\AAD\.env\lib\site-packages\rest_framework\generics.py", line 63, in get_queryset
    assert self.queryset is not None, (
AssertionError: 'UpdateUserDetails' should either include a `queryset` attribute, or override the `get_queryset()` method.
view's UpdateUserDetails raised exception during schema generation; use `getattr(self, 'swagger_fake_view', False)` to detect and short-circuit this
Traceback (most recent call last):
  File "D:\Jafar\AAD\.env\lib\site-packages\drf_yasg\inspectors\base.py", line 42, in call_view_method
    return view_method()
  File "D:\Jafar\AAD\.env\lib\site-packages\rest_framework\generics.py", line 63, in get_queryset
    assert self.queryset is not None, (
AssertionError: 'UpdateUserDetails' should either include a `queryset` attribute, or override the `get_queryset()` method.
view's UpdateUserDetails raised exception during schema generation; use `getattr(self, 'swagger_fake_view', False)` to detect and short-circuit this
Traceback (most recent call last):
  File "D:\Jafar\AAD\.env\lib\site-packages\drf_yasg\inspectors\base.py", line 42, in call_view_method
    return view_method()
  File "D:\Jafar\AAD\.env\lib\site-packages\rest_framework\generics.py", line 63, in get_queryset
    assert self.queryset is not None, (
AssertionError: 'UpdateUserDetails' should either include a `queryset` attribute, or override the `get_queryset()` method.
Not Found: /media/consent_audios/audio.mp3
[33mHTTP GET /media/consent_audios/audio.mp3 404 [0.04, 127.0.0.1:50761][0m
Unauthorized: /abdm/api/v1/account/getCard
[31;1mHTTP GET /abdm/api/v1/account/getCard 401 [0.25, 127.0.0.1:53567][0m
Not Found: /
[33mHTTP GET / 404 [0.10, 127.0.0.1:53494][0m
Not Found: /favicon.ico
[33mHTTP GET /favicon.ico 404 [0.02, 127.0.0.1:53494][0m
view's UpdateUserDetails raised exception during schema generation; use `getattr(self, 'swagger_fake_view', False)` to detect and short-circuit this
Traceback (most recent call last):
  File "D:\Jafar\AAD\.env\lib\site-packages\drf_yasg\inspectors\base.py", line 42, in call_view_method
    return view_method()
  File "D:\Jafar\AAD\.env\lib\site-packages\rest_framework\generics.py", line 63, in get_queryset
    assert self.queryset is not None, (
AssertionError: 'UpdateUserDetails' should either include a `queryset` attribute, or override the `get_queryset()` method.
view's UpdateUserDetails raised exception during schema generation; use `getattr(self, 'swagger_fake_view', False)` to detect and short-circuit this
Traceback (most recent call last):
  File "D:\Jafar\AAD\.env\lib\site-packages\drf_yasg\inspectors\base.py", line 42, in call_view_method
    return view_method()
  File "D:\Jafar\AAD\.env\lib\site-packages\rest_framework\generics.py", line 63, in get_queryset
    assert self.queryset is not None, (
AssertionError: 'UpdateUserDetails' should either include a `queryset` attribute, or override the `get_queryset()` method.
view's UpdateUserDetails raised exception during schema generation; use `getattr(self, 'swagger_fake_view', False)` to detect and short-circuit this
Traceback (most recent call last):
  File "D:\Jafar\AAD\.env\lib\site-packages\drf_yasg\inspectors\base.py", line 42, in call_view_method
    return view_method()
  File "D:\Jafar\AAD\.env\lib\site-packages\rest_framework\generics.py", line 63, in get_queryset
    assert self.queryset is not None, (
AssertionError: 'UpdateUserDetails' should either include a `queryset` attribute, or override the `get_queryset()` method.
Internal Server Error: /adminportal/api/GetuserListAPI/mo
Traceback (most recent call last):
  File "D:\Jafar\AAD\adminportal\serializers.py", line 72, in get_ward
    Ward_Name = data.section.healthPost.ward.wardName
AttributeError: 'NoneType' object has no attribute 'healthPost'

During handling of the above exception, another exception occurred:

Traceback (most recent call last):
  File "D:\Jafar\AAD\.env\lib\site-packages\asgiref\sync.py", line 534, in thread_handler
    raise exc_info[1]
  File "D:\Jafar\AAD\.env\lib\site-packages\django\core\handlers\exception.py", line 42, in inner
    response = await get_response(request)
  File "D:\Jafar\AAD\.env\lib\site-packages\django\core\handlers\base.py", line 253, in _get_response_async
    response = await wrapped_callback(
  File "D:\Jafar\AAD\.env\lib\site-packages\asgiref\sync.py", line 479, in __call__
    ret: _R = await loop.run_in_executor(
  File "C:\Program Files\WindowsApps\PythonSoftwareFoundation.Python.3.10_3.10.3056.0_x64__qbz5n2kfra8p0\lib\concurrent\futures\thread.py", line 58, in run
    result = self.fn(*self.args, **self.kwargs)
  File "D:\Jafar\AAD\.env\lib\site-packages\asgiref\sync.py", line 538, in thread_handler
    return func(*args, **kwargs)
  File "D:\Jafar\AAD\.env\lib\site-packages\django\views\decorators\csrf.py", line 56, in wrapper_view
    return view_func(*args, **kwargs)
  File "D:\Jafar\AAD\.env\lib\site-packages\django\views\generic\base.py", line 104, in view
    return self.dispatch(request, *args, **kwargs)
  File "D:\Jafar\AAD\.env\lib\site-packages\rest_framework\views.py", line 509, in dispatch
    response = self.handle_exception(exc)
  File "D:\Jafar\AAD\.env\lib\site-packages\rest_framework\views.py", line 469, in handle_exception
    self.raise_uncaught_exception(exc)
  File "D:\Jafar\AAD\.env\lib\site-packages\rest_framework\views.py", line 480, in raise_uncaught_exception
    raise exc
  File "D:\Jafar\AAD\.env\lib\site-packages\rest_framework\views.py", line 506, in dispatch
    response = handler(request, *args, **kwargs)
  File "D:\Jafar\AAD\adminportal\views.py", line 188, in get
    'data': serializer.data})
  File "D:\Jafar\AAD\.env\lib\site-packages\rest_framework\serializers.py", line 768, in data
    ret = super().data
  File "D:\Jafar\AAD\.env\lib\site-packages\rest_framework\serializers.py", line 253, in data
    self._data = self.to_representation(self.instance)
  File "D:\Jafar\AAD\.env\lib\site-packages\rest_framework\serializers.py", line 686, in to_representation
    return [
  File "D:\Jafar\AAD\.env\lib\site-packages\rest_framework\serializers.py", line 687, in <listcomp>
    self.child.to_representation(item) for item in iterable
  File "D:\Jafar\AAD\.env\lib\site-packages\rest_framework\serializers.py", line 522, in to_representation
    ret[field.field_name] = field.to_representation(attribute)
  File "D:\Jafar\AAD\.env\lib\site-packages\rest_framework\fields.py", line 1838, in to_representation
    return method(value)
  File "D:\Jafar\AAD\adminportal\serializers.py", line 74, in get_ward
    Ward_Name = data.dispensary.ward.wardName
AttributeError: 'NoneType' object has no attribute 'ward'
[35;1mHTTP GET /adminportal/api/GetuserListAPI/mo 500 [0.88, 127.0.0.1:52319][0m
Unauthorized: /allauth/api/GetDispensaryListAPI
[31;1mHTTP GET /allauth/api/GetDispensaryListAPI 401 [0.01, 127.0.0.1:52832][0m
view's UpdateUserDetails raised exception during schema generation; use `getattr(self, 'swagger_fake_view', False)` to detect and short-circuit this
Traceback (most recent call last):
  File "D:\Jafar\AAD\.env\lib\site-packages\drf_yasg\inspectors\base.py", line 42, in call_view_method
    return view_method()
  File "D:\Jafar\AAD\.env\lib\site-packages\rest_framework\generics.py", line 63, in get_queryset
    assert self.queryset is not None, (
AssertionError: 'UpdateUserDetails' should either include a `queryset` attribute, or override the `get_queryset()` method.
view's UpdateUserDetails raised exception during schema generation; use `getattr(self, 'swagger_fake_view', False)` to detect and short-circuit this
Traceback (most recent call last):
  File "D:\Jafar\AAD\.env\lib\site-packages\drf_yasg\inspectors\base.py", line 42, in call_view_method
    return view_method()
  File "D:\Jafar\AAD\.env\lib\site-packages\rest_framework\generics.py", line 63, in get_queryset
    assert self.queryset is not None, (
AssertionError: 'UpdateUserDetails' should either include a `queryset` attribute, or override the `get_queryset()` method.
Internal Server Error: /doctor/api/ViewFamilyDetails/181/
Traceback (most recent call last):
  File "D:\Jafar\AAD\.env\lib\site-packages\asgiref\sync.py", line 534, in thread_handler
    raise exc_info[1]
  File "D:\Jafar\AAD\.env\lib\site-packages\django\core\handlers\exception.py", line 42, in inner
    response = await get_response(request)
  File "D:\Jafar\AAD\.env\lib\site-packages\django\core\handlers\base.py", line 253, in _get_response_async
    response = await wrapped_callback(
  File "D:\Jafar\AAD\.env\lib\site-packages\asgiref\sync.py", line 479, in __call__
    ret: _R = await loop.run_in_executor(
  File "C:\Program Files\WindowsApps\PythonSoftwareFoundation.Python.3.10_3.10.3056.0_x64__qbz5n2kfra8p0\lib\concurrent\futures\thread.py", line 58, in run
    result = self.fn(*self.args, **self.kwargs)
  File "D:\Jafar\AAD\.env\lib\site-packages\asgiref\sync.py", line 538, in thread_handler
    return func(*args, **kwargs)
  File "D:\Jafar\AAD\.env\lib\site-packages\django\views\decorators\csrf.py", line 56, in wrapper_view
    return view_func(*args, **kwargs)
  File "D:\Jafar\AAD\.env\lib\site-packages\django\views\generic\base.py", line 104, in view
    return self.dispatch(request, *args, **kwargs)
  File "D:\Jafar\AAD\.env\lib\site-packages\rest_framework\views.py", line 509, in dispatch
    response = self.handle_exception(exc)
  File "D:\Jafar\AAD\.env\lib\site-packages\rest_framework\views.py", line 469, in handle_exception
    self.raise_uncaught_exception(exc)
  File "D:\Jafar\AAD\.env\lib\site-packages\rest_framework\views.py", line 480, in raise_uncaught_exception
    raise exc
  File "D:\Jafar\AAD\.env\lib\site-packages\rest_framework\views.py", line 506, in dispatch
    response = handler(request, *args, **kwargs)
  File "D:\Jafar\AAD\.env\lib\site-packages\rest_framework\decorators.py", line 50, in handler
    return func(*args, **kwargs)
  File "D:\Jafar\AAD\doctorsApp\views.py", line 213, in ViewFamilyDetails
    testData  = serializer.data
  File "D:\Jafar\AAD\.env\lib\site-packages\rest_framework\serializers.py", line 555, in data
    ret = super().data
  File "D:\Jafar\AAD\.env\lib\site-packages\rest_framework\serializers.py", line 253, in data
    self._data = self.to_representation(self.instance)
  File "D:\Jafar\AAD\.env\lib\site-packages\rest_framework\serializers.py", line 522, in to_representation
    ret[field.field_name] = field.to_representation(attribute)
  File "D:\Jafar\AAD\.env\lib\site-packages\rest_framework\serializers.py", line 686, in to_representation
    return [
  File "D:\Jafar\AAD\.env\lib\site-packages\rest_framework\serializers.py", line 687, in <listcomp>
    self.child.to_representation(item) for item in iterable
  File "D:\Jafar\AAD\.env\lib\site-packages\rest_framework\serializers.py", line 522, in to_representation
    ret[field.field_name] = field.to_representation(attribute)
  File "D:\Jafar\AAD\.env\lib\site-packages\rest_framework\fields.py", line 1838, in to_representation
    return method(value)
  File "D:\Jafar\AAD\doctorsApp\serializers.py", line 156, in get_report
    print(data.patientFamilyMember_id)
AttributeError: 'familyMembers' object has no attribute 'patientFamilyMember_id'
[35;1mHTTP GET /doctor/api/ViewFamilyDetails/181/ 500 [0.52, 127.0.0.1:54099][0m
Internal Server Error: /doctor/api/ViewFamilyDetails/181/
Traceback (most recent call last):
  File "D:\Jafar\AAD\.env\lib\site-packages\asgiref\sync.py", line 534, in thread_handler
    raise exc_info[1]
  File "D:\Jafar\AAD\.env\lib\site-packages\django\core\handlers\exception.py", line 42, in inner
    response = await get_response(request)
  File "D:\Jafar\AAD\.env\lib\site-packages\django\core\handlers\base.py", line 253, in _get_response_async
    response = await wrapped_callback(
  File "D:\Jafar\AAD\.env\lib\site-packages\asgiref\sync.py", line 479, in __call__
    ret: _R = await loop.run_in_executor(
  File "C:\Program Files\WindowsApps\PythonSoftwareFoundation.Python.3.10_3.10.3056.0_x64__qbz5n2kfra8p0\lib\concurrent\futures\thread.py", line 58, in run
    result = self.fn(*self.args, **self.kwargs)
  File "D:\Jafar\AAD\.env\lib\site-packages\asgiref\sync.py", line 538, in thread_handler
    return func(*args, **kwargs)
  File "D:\Jafar\AAD\.env\lib\site-packages\django\views\decorators\csrf.py", line 56, in wrapper_view
    return view_func(*args, **kwargs)
  File "D:\Jafar\AAD\.env\lib\site-packages\django\views\generic\base.py", line 104, in view
    return self.dispatch(request, *args, **kwargs)
  File "D:\Jafar\AAD\.env\lib\site-packages\rest_framework\views.py", line 509, in dispatch
    response = self.handle_exception(exc)
  File "D:\Jafar\AAD\.env\lib\site-packages\rest_framework\views.py", line 469, in handle_exception
    self.raise_uncaught_exception(exc)
  File "D:\Jafar\AAD\.env\lib\site-packages\rest_framework\views.py", line 480, in raise_uncaught_exception
    raise exc
  File "D:\Jafar\AAD\.env\lib\site-packages\rest_framework\views.py", line 506, in dispatch
    response = handler(request, *args, **kwargs)
  File "D:\Jafar\AAD\.env\lib\site-packages\rest_framework\decorators.py", line 50, in handler
    return func(*args, **kwargs)
  File "D:\Jafar\AAD\doctorsApp\views.py", line 213, in ViewFamilyDetails
    testData  = serializer.data
  File "D:\Jafar\AAD\.env\lib\site-packages\rest_framework\serializers.py", line 555, in data
    ret = super().data
  File "D:\Jafar\AAD\.env\lib\site-packages\rest_framework\serializers.py", line 253, in data
    self._data = self.to_representation(self.instance)
  File "D:\Jafar\AAD\.env\lib\site-packages\rest_framework\serializers.py", line 522, in to_representation
    ret[field.field_name] = field.to_representation(attribute)
  File "D:\Jafar\AAD\.env\lib\site-packages\rest_framework\serializers.py", line 686, in to_representation
    return [
  File "D:\Jafar\AAD\.env\lib\site-packages\rest_framework\serializers.py", line 687, in <listcomp>
    self.child.to_representation(item) for item in iterable
  File "D:\Jafar\AAD\.env\lib\site-packages\rest_framework\serializers.py", line 522, in to_representation
    ret[field.field_name] = field.to_representation(attribute)
  File "D:\Jafar\AAD\.env\lib\site-packages\rest_framework\fields.py", line 1838, in to_representation
    return method(value)
  File "D:\Jafar\AAD\doctorsApp\serializers.py", line 156, in get_report
    print(data.patientFamilyMember())
TypeError: create_reverse_many_to_one_manager.<locals>.RelatedManager.__call__() missing 1 required keyword-only argument: 'manager'
[35;1mHTTP GET /doctor/api/ViewFamilyDetails/181/ 500 [0.20, 127.0.0.1:54128][0m
Internal Server Error: /doctor/api/ViewFamilyDetails/181/
Traceback (most recent call last):
  File "D:\Jafar\AAD\.env\lib\site-packages\asgiref\sync.py", line 534, in thread_handler
    raise exc_info[1]
  File "D:\Jafar\AAD\.env\lib\site-packages\django\core\handlers\exception.py", line 42, in inner
    response = await get_response(request)
  File "D:\Jafar\AAD\.env\lib\site-packages\django\core\handlers\base.py", line 253, in _get_response_async
    response = await wrapped_callback(
  File "D:\Jafar\AAD\.env\lib\site-packages\asgiref\sync.py", line 479, in __call__
    ret: _R = await loop.run_in_executor(
  File "C:\Program Files\WindowsApps\PythonSoftwareFoundation.Python.3.10_3.10.3056.0_x64__qbz5n2kfra8p0\lib\concurrent\futures\thread.py", line 58, in run
    result = self.fn(*self.args, **self.kwargs)
  File "D:\Jafar\AAD\.env\lib\site-packages\asgiref\sync.py", line 538, in thread_handler
    return func(*args, **kwargs)
  File "D:\Jafar\AAD\.env\lib\site-packages\django\views\decorators\csrf.py", line 56, in wrapper_view
    return view_func(*args, **kwargs)
  File "D:\Jafar\AAD\.env\lib\site-packages\django\views\generic\base.py", line 104, in view
    return self.dispatch(request, *args, **kwargs)
  File "D:\Jafar\AAD\.env\lib\site-packages\rest_framework\views.py", line 509, in dispatch
    response = self.handle_exception(exc)
  File "D:\Jafar\AAD\.env\lib\site-packages\rest_framework\views.py", line 469, in handle_exception
    self.raise_uncaught_exception(exc)
  File "D:\Jafar\AAD\.env\lib\site-packages\rest_framework\views.py", line 480, in raise_uncaught_exception
    raise exc
  File "D:\Jafar\AAD\.env\lib\site-packages\rest_framework\views.py", line 506, in dispatch
    response = handler(request, *args, **kwargs)
  File "D:\Jafar\AAD\.env\lib\site-packages\rest_framework\decorators.py", line 50, in handler
    return func(*args, **kwargs)
  File "D:\Jafar\AAD\doctorsApp\views.py", line 213, in ViewFamilyDetails
    testData  = serializer.data
  File "D:\Jafar\AAD\.env\lib\site-packages\rest_framework\serializers.py", line 555, in data
    ret = super().data
  File "D:\Jafar\AAD\.env\lib\site-packages\rest_framework\serializers.py", line 253, in data
    self._data = self.to_representation(self.instance)
  File "D:\Jafar\AAD\.env\lib\site-packages\rest_framework\serializers.py", line 522, in to_representation
    ret[field.field_name] = field.to_representation(attribute)
  File "D:\Jafar\AAD\.env\lib\site-packages\rest_framework\serializers.py", line 686, in to_representation
    return [
  File "D:\Jafar\AAD\.env\lib\site-packages\rest_framework\serializers.py", line 687, in <listcomp>
    self.child.to_representation(item) for item in iterable
  File "D:\Jafar\AAD\.env\lib\site-packages\rest_framework\serializers.py", line 522, in to_representation
    ret[field.field_name] = field.to_representation(attribute)
  File "D:\Jafar\AAD\.env\lib\site-packages\rest_framework\fields.py", line 1838, in to_representation
    return method(value)
  File "D:\Jafar\AAD\doctorsApp\serializers.py", line 156, in get_report
    print(data.patientFamilyMember.patientPathLabReports)
AttributeError: 'RelatedManager' object has no attribute 'patientPathLabReports'
[35;1mHTTP GET /doctor/api/ViewFamilyDetails/181/ 500 [0.13, 127.0.0.1:54231][0m
The joined path (D:\home\bgisadmin\AAD_backend\AAD_Backend\media\patientPathLabResults\Sanjay Guptae1af10a2-773d-4588-93ed-c36a5bc71059.pdf) is located outside of the base path component (D:\Jafar\AAD\media)
Traceback (most recent call last):
  File "D:\Jafar\AAD\.env\lib\site-packages\asgiref\sync.py", line 534, in thread_handler
    raise exc_info[1]
  File "D:\Jafar\AAD\.env\lib\site-packages\django\core\handlers\exception.py", line 42, in inner
    response = await get_response(request)
  File "D:\Jafar\AAD\.env\lib\site-packages\django\core\handlers\base.py", line 284, in _get_response_async
    response = await sync_to_async(
  File "D:\Jafar\AAD\.env\lib\site-packages\asgiref\sync.py", line 479, in __call__
    ret: _R = await loop.run_in_executor(
  File "C:\Program Files\WindowsApps\PythonSoftwareFoundation.Python.3.10_3.10.3056.0_x64__qbz5n2kfra8p0\lib\concurrent\futures\thread.py", line 58, in run
    result = self.fn(*self.args, **self.kwargs)
  File "D:\Jafar\AAD\.env\lib\site-packages\asgiref\sync.py", line 538, in thread_handler
    return func(*args, **kwargs)
  File "D:\Jafar\AAD\.env\lib\site-packages\django\template\response.py", line 114, in render
    self.content = self.rendered_content
  File "D:\Jafar\AAD\.env\lib\site-packages\rest_framework\response.py", line 70, in rendered_content
    ret = renderer.render(self.data, accepted_media_type, context)
  File "D:\Jafar\AAD\.env\lib\site-packages\rest_framework\renderers.py", line 99, in render
    ret = json.dumps(
  File "D:\Jafar\AAD\.env\lib\site-packages\rest_framework\utils\json.py", line 25, in dumps
    return json.dumps(*args, **kwargs)
  File "C:\Program Files\WindowsApps\PythonSoftwareFoundation.Python.3.10_3.10.3056.0_x64__qbz5n2kfra8p0\lib\json\__init__.py", line 238, in dumps
    **kw).encode(obj)
  File "C:\Program Files\WindowsApps\PythonSoftwareFoundation.Python.3.10_3.10.3056.0_x64__qbz5n2kfra8p0\lib\json\encoder.py", line 199, in encode
    chunks = self.iterencode(o, _one_shot=True)
  File "C:\Program Files\WindowsApps\PythonSoftwareFoundation.Python.3.10_3.10.3056.0_x64__qbz5n2kfra8p0\lib\json\encoder.py", line 257, in iterencode
    return _iterencode(o, 0)
  File "D:\Jafar\AAD\.env\lib\site-packages\rest_framework\utils\encoders.py", line 66, in default
    return tuple(item for item in obj)
  File "D:\Jafar\AAD\.env\lib\site-packages\rest_framework\utils\encoders.py", line 66, in <genexpr>
    return tuple(item for item in obj)
  File "D:\Jafar\AAD\.env\lib\site-packages\django\core\files\base.py", line 78, in __iter__
    for chunk in self.chunks():
  File "D:\Jafar\AAD\.env\lib\site-packages\django\core\files\base.py", line 55, in chunks
    self.seek(0)
  File "D:\Jafar\AAD\.env\lib\site-packages\django\core\files\utils.py", line 46, in <lambda>
    seek = property(lambda self: self.file.seek)
  File "D:\Jafar\AAD\.env\lib\site-packages\django\db\models\fields\files.py", line 48, in _get_file
    self._file = self.storage.open(self.name, "rb")
  File "D:\Jafar\AAD\.env\lib\site-packages\django\core\files\storage\base.py", line 22, in open
    return self._open(name, mode)
  File "D:\Jafar\AAD\.env\lib\site-packages\django\core\files\storage\filesystem.py", line 68, in _open
    return File(open(self.path(name), mode))
  File "D:\Jafar\AAD\.env\lib\site-packages\django\core\files\storage\filesystem.py", line 179, in path
    return safe_join(self.location, name)
  File "D:\Jafar\AAD\.env\lib\site-packages\django\utils\_os.py", line 31, in safe_join
    raise SuspiciousFileOperation(
django.core.exceptions.SuspiciousFileOperation: The joined path (D:\home\bgisadmin\AAD_backend\AAD_Backend\media\patientPathLabResults\Sanjay Guptae1af10a2-773d-4588-93ed-c36a5bc71059.pdf) is located outside of the base path component (D:\Jafar\AAD\media)
Bad Request: /doctor/api/ViewFamilyDetails/181/
[31;1mHTTP GET /doctor/api/ViewFamilyDetails/181/ 400 [0.24, 127.0.0.1:54570][0m
The joined path (D:\home\bgisadmin\AAD_backend\AAD_Backend\media\patientPathLabResults\Sanjay Guptae1af10a2-773d-4588-93ed-c36a5bc71059.pdf) is located outside of the base path component (D:\Jafar\AAD\media)
Traceback (most recent call last):
  File "D:\Jafar\AAD\.env\lib\site-packages\asgiref\sync.py", line 534, in thread_handler
    raise exc_info[1]
  File "D:\Jafar\AAD\.env\lib\site-packages\django\core\handlers\exception.py", line 42, in inner
    response = await get_response(request)
  File "D:\Jafar\AAD\.env\lib\site-packages\django\core\handlers\base.py", line 284, in _get_response_async
    response = await sync_to_async(
  File "D:\Jafar\AAD\.env\lib\site-packages\asgiref\sync.py", line 479, in __call__
    ret: _R = await loop.run_in_executor(
  File "C:\Program Files\WindowsApps\PythonSoftwareFoundation.Python.3.10_3.10.3056.0_x64__qbz5n2kfra8p0\lib\concurrent\futures\thread.py", line 58, in run
    result = self.fn(*self.args, **self.kwargs)
  File "D:\Jafar\AAD\.env\lib\site-packages\asgiref\sync.py", line 538, in thread_handler
    return func(*args, **kwargs)
  File "D:\Jafar\AAD\.env\lib\site-packages\django\template\response.py", line 114, in render
    self.content = self.rendered_content
  File "D:\Jafar\AAD\.env\lib\site-packages\rest_framework\response.py", line 70, in rendered_content
    ret = renderer.render(self.data, accepted_media_type, context)
  File "D:\Jafar\AAD\.env\lib\site-packages\rest_framework\renderers.py", line 99, in render
    ret = json.dumps(
  File "D:\Jafar\AAD\.env\lib\site-packages\rest_framework\utils\json.py", line 25, in dumps
    return json.dumps(*args, **kwargs)
  File "C:\Program Files\WindowsApps\PythonSoftwareFoundation.Python.3.10_3.10.3056.0_x64__qbz5n2kfra8p0\lib\json\__init__.py", line 238, in dumps
    **kw).encode(obj)
  File "C:\Program Files\WindowsApps\PythonSoftwareFoundation.Python.3.10_3.10.3056.0_x64__qbz5n2kfra8p0\lib\json\encoder.py", line 199, in encode
    chunks = self.iterencode(o, _one_shot=True)
  File "C:\Program Files\WindowsApps\PythonSoftwareFoundation.Python.3.10_3.10.3056.0_x64__qbz5n2kfra8p0\lib\json\encoder.py", line 257, in iterencode
    return _iterencode(o, 0)
  File "D:\Jafar\AAD\.env\lib\site-packages\rest_framework\utils\encoders.py", line 66, in default
    return tuple(item for item in obj)
  File "D:\Jafar\AAD\.env\lib\site-packages\rest_framework\utils\encoders.py", line 66, in <genexpr>
    return tuple(item for item in obj)
  File "D:\Jafar\AAD\.env\lib\site-packages\django\core\files\base.py", line 78, in __iter__
    for chunk in self.chunks():
  File "D:\Jafar\AAD\.env\lib\site-packages\django\core\files\base.py", line 55, in chunks
    self.seek(0)
  File "D:\Jafar\AAD\.env\lib\site-packages\django\core\files\utils.py", line 46, in <lambda>
    seek = property(lambda self: self.file.seek)
  File "D:\Jafar\AAD\.env\lib\site-packages\django\db\models\fields\files.py", line 48, in _get_file
    self._file = self.storage.open(self.name, "rb")
  File "D:\Jafar\AAD\.env\lib\site-packages\django\core\files\storage\base.py", line 22, in open
    return self._open(name, mode)
  File "D:\Jafar\AAD\.env\lib\site-packages\django\core\files\storage\filesystem.py", line 68, in _open
    return File(open(self.path(name), mode))
  File "D:\Jafar\AAD\.env\lib\site-packages\django\core\files\storage\filesystem.py", line 179, in path
    return safe_join(self.location, name)
  File "D:\Jafar\AAD\.env\lib\site-packages\django\utils\_os.py", line 31, in safe_join
    raise SuspiciousFileOperation(
django.core.exceptions.SuspiciousFileOperation: The joined path (D:\home\bgisadmin\AAD_backend\AAD_Backend\media\patientPathLabResults\Sanjay Guptae1af10a2-773d-4588-93ed-c36a5bc71059.pdf) is located outside of the base path component (D:\Jafar\AAD\media)
Bad Request: /doctor/api/ViewFamilyDetails/181/
[31;1mHTTP GET /doctor/api/ViewFamilyDetails/181/ 400 [0.19, 127.0.0.1:54774][0m
The joined path (D:\home\bgisadmin\AAD_backend\AAD_Backend\media\patientPathLabResults\SanjayGuptae1af10a2-773d-4588-93ed-c36a5bc71059.pdf) is located outside of the base path component (D:\Jafar\AAD\media)
Traceback (most recent call last):
  File "D:\Jafar\AAD\.env\lib\site-packages\asgiref\sync.py", line 534, in thread_handler
    raise exc_info[1]
  File "D:\Jafar\AAD\.env\lib\site-packages\django\core\handlers\exception.py", line 42, in inner
    response = await get_response(request)
  File "D:\Jafar\AAD\.env\lib\site-packages\django\core\handlers\base.py", line 284, in _get_response_async
    response = await sync_to_async(
  File "D:\Jafar\AAD\.env\lib\site-packages\asgiref\sync.py", line 479, in __call__
    ret: _R = await loop.run_in_executor(
  File "C:\Program Files\WindowsApps\PythonSoftwareFoundation.Python.3.10_3.10.3056.0_x64__qbz5n2kfra8p0\lib\concurrent\futures\thread.py", line 58, in run
    result = self.fn(*self.args, **self.kwargs)
  File "D:\Jafar\AAD\.env\lib\site-packages\asgiref\sync.py", line 538, in thread_handler
    return func(*args, **kwargs)
  File "D:\Jafar\AAD\.env\lib\site-packages\django\template\response.py", line 114, in render
    self.content = self.rendered_content
  File "D:\Jafar\AAD\.env\lib\site-packages\rest_framework\response.py", line 70, in rendered_content
    ret = renderer.render(self.data, accepted_media_type, context)
  File "D:\Jafar\AAD\.env\lib\site-packages\rest_framework\renderers.py", line 99, in render
    ret = json.dumps(
  File "D:\Jafar\AAD\.env\lib\site-packages\rest_framework\utils\json.py", line 25, in dumps
    return json.dumps(*args, **kwargs)
  File "C:\Program Files\WindowsApps\PythonSoftwareFoundation.Python.3.10_3.10.3056.0_x64__qbz5n2kfra8p0\lib\json\__init__.py", line 238, in dumps
    **kw).encode(obj)
  File "C:\Program Files\WindowsApps\PythonSoftwareFoundation.Python.3.10_3.10.3056.0_x64__qbz5n2kfra8p0\lib\json\encoder.py", line 199, in encode
    chunks = self.iterencode(o, _one_shot=True)
  File "C:\Program Files\WindowsApps\PythonSoftwareFoundation.Python.3.10_3.10.3056.0_x64__qbz5n2kfra8p0\lib\json\encoder.py", line 257, in iterencode
    return _iterencode(o, 0)
  File "D:\Jafar\AAD\.env\lib\site-packages\rest_framework\utils\encoders.py", line 66, in default
    return tuple(item for item in obj)
  File "D:\Jafar\AAD\.env\lib\site-packages\rest_framework\utils\encoders.py", line 66, in <genexpr>
    return tuple(item for item in obj)
  File "D:\Jafar\AAD\.env\lib\site-packages\django\core\files\base.py", line 78, in __iter__
    for chunk in self.chunks():
  File "D:\Jafar\AAD\.env\lib\site-packages\django\core\files\base.py", line 55, in chunks
    self.seek(0)
  File "D:\Jafar\AAD\.env\lib\site-packages\django\core\files\utils.py", line 46, in <lambda>
    seek = property(lambda self: self.file.seek)
  File "D:\Jafar\AAD\.env\lib\site-packages\django\db\models\fields\files.py", line 48, in _get_file
    self._file = self.storage.open(self.name, "rb")
  File "D:\Jafar\AAD\.env\lib\site-packages\django\core\files\storage\base.py", line 22, in open
    return self._open(name, mode)
  File "D:\Jafar\AAD\.env\lib\site-packages\django\core\files\storage\filesystem.py", line 68, in _open
    return File(open(self.path(name), mode))
  File "D:\Jafar\AAD\.env\lib\site-packages\django\core\files\storage\filesystem.py", line 179, in path
    return safe_join(self.location, name)
  File "D:\Jafar\AAD\.env\lib\site-packages\django\utils\_os.py", line 31, in safe_join
    raise SuspiciousFileOperation(
django.core.exceptions.SuspiciousFileOperation: The joined path (D:\home\bgisadmin\AAD_backend\AAD_Backend\media\patientPathLabResults\SanjayGuptae1af10a2-773d-4588-93ed-c36a5bc71059.pdf) is located outside of the base path component (D:\Jafar\AAD\media)
Bad Request: /doctor/api/ViewFamilyDetails/181/
[31;1mHTTP GET /doctor/api/ViewFamilyDetails/181/ 400 [0.17, 127.0.0.1:55004][0m
Internal Server Error: /doctor/api/ViewFamilyDetails/181/
Traceback (most recent call last):
  File "D:\Jafar\AAD\.env\lib\site-packages\asgiref\sync.py", line 534, in thread_handler
    raise exc_info[1]
  File "D:\Jafar\AAD\.env\lib\site-packages\django\core\handlers\exception.py", line 42, in inner
    response = await get_response(request)
  File "D:\Jafar\AAD\.env\lib\site-packages\django\core\handlers\base.py", line 284, in _get_response_async
    response = await sync_to_async(
  File "D:\Jafar\AAD\.env\lib\site-packages\asgiref\sync.py", line 479, in __call__
    ret: _R = await loop.run_in_executor(
  File "C:\Program Files\WindowsApps\PythonSoftwareFoundation.Python.3.10_3.10.3056.0_x64__qbz5n2kfra8p0\lib\concurrent\futures\thread.py", line 58, in run
    result = self.fn(*self.args, **self.kwargs)
  File "D:\Jafar\AAD\.env\lib\site-packages\asgiref\sync.py", line 538, in thread_handler
    return func(*args, **kwargs)
  File "D:\Jafar\AAD\.env\lib\site-packages\django\template\response.py", line 114, in render
    self.content = self.rendered_content
  File "D:\Jafar\AAD\.env\lib\site-packages\rest_framework\response.py", line 70, in rendered_content
    ret = renderer.render(self.data, accepted_media_type, context)
  File "D:\Jafar\AAD\.env\lib\site-packages\rest_framework\renderers.py", line 99, in render
    ret = json.dumps(
  File "D:\Jafar\AAD\.env\lib\site-packages\rest_framework\utils\json.py", line 25, in dumps
    return json.dumps(*args, **kwargs)
  File "C:\Program Files\WindowsApps\PythonSoftwareFoundation.Python.3.10_3.10.3056.0_x64__qbz5n2kfra8p0\lib\json\__init__.py", line 238, in dumps
    **kw).encode(obj)
  File "C:\Program Files\WindowsApps\PythonSoftwareFoundation.Python.3.10_3.10.3056.0_x64__qbz5n2kfra8p0\lib\json\encoder.py", line 199, in encode
    chunks = self.iterencode(o, _one_shot=True)
  File "C:\Program Files\WindowsApps\PythonSoftwareFoundation.Python.3.10_3.10.3056.0_x64__qbz5n2kfra8p0\lib\json\encoder.py", line 257, in iterencode
    return _iterencode(o, 0)
  File "D:\Jafar\AAD\.env\lib\site-packages\rest_framework\utils\encoders.py", line 50, in default
    return obj.decode()
UnicodeDecodeError: 'utf-8' codec can't decode byte 0xe2 in position 1: invalid continuation byte
[35;1mHTTP GET /doctor/api/ViewFamilyDetails/181/ 500 [0.30, 127.0.0.1:55889][0m
Internal Server Error: /doctor/api/ViewFamilyDetails/181/
Traceback (most recent call last):
  File "D:\Jafar\AAD\.env\lib\site-packages\asgiref\sync.py", line 534, in thread_handler
    raise exc_info[1]
  File "D:\Jafar\AAD\.env\lib\site-packages\django\core\handlers\exception.py", line 42, in inner
    response = await get_response(request)
  File "D:\Jafar\AAD\.env\lib\site-packages\django\core\handlers\base.py", line 253, in _get_response_async
    response = await wrapped_callback(
  File "D:\Jafar\AAD\.env\lib\site-packages\asgiref\sync.py", line 479, in __call__
    ret: _R = await loop.run_in_executor(
  File "C:\Program Files\WindowsApps\PythonSoftwareFoundation.Python.3.10_3.10.3056.0_x64__qbz5n2kfra8p0\lib\concurrent\futures\thread.py", line 58, in run
    result = self.fn(*self.args, **self.kwargs)
  File "D:\Jafar\AAD\.env\lib\site-packages\asgiref\sync.py", line 538, in thread_handler
    return func(*args, **kwargs)
  File "D:\Jafar\AAD\.env\lib\site-packages\django\views\decorators\csrf.py", line 56, in wrapper_view
    return view_func(*args, **kwargs)
  File "D:\Jafar\AAD\.env\lib\site-packages\django\views\generic\base.py", line 104, in view
    return self.dispatch(request, *args, **kwargs)
  File "D:\Jafar\AAD\.env\lib\site-packages\rest_framework\views.py", line 509, in dispatch
    response = self.handle_exception(exc)
  File "D:\Jafar\AAD\.env\lib\site-packages\rest_framework\views.py", line 469, in handle_exception
    self.raise_uncaught_exception(exc)
  File "D:\Jafar\AAD\.env\lib\site-packages\rest_framework\views.py", line 480, in raise_uncaught_exception
    raise exc
  File "D:\Jafar\AAD\.env\lib\site-packages\rest_framework\views.py", line 506, in dispatch
    response = handler(request, *args, **kwargs)
  File "D:\Jafar\AAD\.env\lib\site-packages\rest_framework\decorators.py", line 50, in handler
    return func(*args, **kwargs)
  File "D:\Jafar\AAD\doctorsApp\views.py", line 213, in ViewFamilyDetails
    testData  = serializer.data
  File "D:\Jafar\AAD\.env\lib\site-packages\rest_framework\serializers.py", line 555, in data
    ret = super().data
  File "D:\Jafar\AAD\.env\lib\site-packages\rest_framework\serializers.py", line 253, in data
    self._data = self.to_representation(self.instance)
  File "D:\Jafar\AAD\.env\lib\site-packages\rest_framework\serializers.py", line 522, in to_representation
    ret[field.field_name] = field.to_representation(attribute)
  File "D:\Jafar\AAD\.env\lib\site-packages\rest_framework\serializers.py", line 686, in to_representation
    return [
  File "D:\Jafar\AAD\.env\lib\site-packages\rest_framework\serializers.py", line 687, in <listcomp>
    self.child.to_representation(item) for item in iterable
  File "D:\Jafar\AAD\.env\lib\site-packages\rest_framework\serializers.py", line 507, in to_representation
    for field in fields:
  File "D:\Jafar\AAD\.env\lib\site-packages\rest_framework\serializers.py", line 368, in _readable_fields
    for field in self.fields.values():
  File "D:\Jafar\AAD\.env\lib\site-packages\django\utils\functional.py", line 57, in __get__
    res = instance.__dict__[self.name] = self.func(instance)
  File "D:\Jafar\AAD\.env\lib\site-packages\rest_framework\serializers.py", line 356, in fields
    for key, value in self.get_fields().items():
  File "D:\Jafar\AAD\.env\lib\site-packages\rest_framework\serializers.py", line 1076, in get_fields
    field_class, field_kwargs = self.build_field(
  File "D:\Jafar\AAD\.env\lib\site-packages\rest_framework\serializers.py", line 1222, in build_field
    return self.build_unknown_field(field_name, model_class)
  File "D:\Jafar\AAD\.env\lib\site-packages\rest_framework\serializers.py", line 1340, in build_unknown_field
    raise ImproperlyConfigured(
django.core.exceptions.ImproperlyConfigured: Field name `patientFamilyMember__patientPathLabReports` is not valid for model `familyMembers`.
[35;1mHTTP GET /doctor/api/ViewFamilyDetails/181/ 500 [0.12, 127.0.0.1:56311][0m
Internal Server Error: /doctor/api/ViewFamilyDetails/181/
Traceback (most recent call last):
  File "D:\Jafar\AAD\.env\lib\site-packages\asgiref\sync.py", line 534, in thread_handler
    raise exc_info[1]
  File "D:\Jafar\AAD\.env\lib\site-packages\django\core\handlers\exception.py", line 42, in inner
    response = await get_response(request)
  File "D:\Jafar\AAD\.env\lib\site-packages\django\core\handlers\base.py", line 284, in _get_response_async
    response = await sync_to_async(
  File "D:\Jafar\AAD\.env\lib\site-packages\asgiref\sync.py", line 479, in __call__
    ret: _R = await loop.run_in_executor(
  File "C:\Program Files\WindowsApps\PythonSoftwareFoundation.Python.3.10_3.10.3056.0_x64__qbz5n2kfra8p0\lib\concurrent\futures\thread.py", line 58, in run
    result = self.fn(*self.args, **self.kwargs)
  File "D:\Jafar\AAD\.env\lib\site-packages\asgiref\sync.py", line 538, in thread_handler
    return func(*args, **kwargs)
  File "D:\Jafar\AAD\.env\lib\site-packages\django\template\response.py", line 114, in render
    self.content = self.rendered_content
  File "D:\Jafar\AAD\.env\lib\site-packages\rest_framework\response.py", line 70, in rendered_content
    ret = renderer.render(self.data, accepted_media_type, context)
  File "D:\Jafar\AAD\.env\lib\site-packages\rest_framework\renderers.py", line 99, in render
    ret = json.dumps(
  File "D:\Jafar\AAD\.env\lib\site-packages\rest_framework\utils\json.py", line 25, in dumps
    return json.dumps(*args, **kwargs)
  File "C:\Program Files\WindowsApps\PythonSoftwareFoundation.Python.3.10_3.10.3056.0_x64__qbz5n2kfra8p0\lib\json\__init__.py", line 238, in dumps
    **kw).encode(obj)
  File "C:\Program Files\WindowsApps\PythonSoftwareFoundation.Python.3.10_3.10.3056.0_x64__qbz5n2kfra8p0\lib\json\encoder.py", line 199, in encode
    chunks = self.iterencode(o, _one_shot=True)
  File "C:\Program Files\WindowsApps\PythonSoftwareFoundation.Python.3.10_3.10.3056.0_x64__qbz5n2kfra8p0\lib\json\encoder.py", line 257, in iterencode
    return _iterencode(o, 0)
  File "D:\Jafar\AAD\.env\lib\site-packages\rest_framework\utils\encoders.py", line 50, in default
    return obj.decode()
UnicodeDecodeError: 'utf-8' codec can't decode byte 0xe2 in position 1: invalid continuation byte
[35;1mHTTP GET /doctor/api/ViewFamilyDetails/181/ 500 [0.34, 127.0.0.1:56360][0m
Internal Server Error: /doctor/api/ViewFamilyDetails/181/
Traceback (most recent call last):
  File "D:\Jafar\AAD\.env\lib\site-packages\asgiref\sync.py", line 534, in thread_handler
    raise exc_info[1]
  File "D:\Jafar\AAD\.env\lib\site-packages\django\core\handlers\exception.py", line 42, in inner
    response = await get_response(request)
  File "D:\Jafar\AAD\.env\lib\site-packages\django\core\handlers\base.py", line 284, in _get_response_async
    response = await sync_to_async(
  File "D:\Jafar\AAD\.env\lib\site-packages\asgiref\sync.py", line 479, in __call__
    ret: _R = await loop.run_in_executor(
  File "C:\Program Files\WindowsApps\PythonSoftwareFoundation.Python.3.10_3.10.3056.0_x64__qbz5n2kfra8p0\lib\concurrent\futures\thread.py", line 58, in run
    result = self.fn(*self.args, **self.kwargs)
  File "D:\Jafar\AAD\.env\lib\site-packages\asgiref\sync.py", line 538, in thread_handler
    return func(*args, **kwargs)
  File "D:\Jafar\AAD\.env\lib\site-packages\django\template\response.py", line 114, in render
    self.content = self.rendered_content
  File "D:\Jafar\AAD\.env\lib\site-packages\rest_framework\response.py", line 70, in rendered_content
    ret = renderer.render(self.data, accepted_media_type, context)
  File "D:\Jafar\AAD\.env\lib\site-packages\rest_framework\renderers.py", line 99, in render
    ret = json.dumps(
  File "D:\Jafar\AAD\.env\lib\site-packages\rest_framework\utils\json.py", line 25, in dumps
    return json.dumps(*args, **kwargs)
  File "C:\Program Files\WindowsApps\PythonSoftwareFoundation.Python.3.10_3.10.3056.0_x64__qbz5n2kfra8p0\lib\json\__init__.py", line 238, in dumps
    **kw).encode(obj)
  File "C:\Program Files\WindowsApps\PythonSoftwareFoundation.Python.3.10_3.10.3056.0_x64__qbz5n2kfra8p0\lib\json\encoder.py", line 199, in encode
    chunks = self.iterencode(o, _one_shot=True)
  File "C:\Program Files\WindowsApps\PythonSoftwareFoundation.Python.3.10_3.10.3056.0_x64__qbz5n2kfra8p0\lib\json\encoder.py", line 257, in iterencode
    return _iterencode(o, 0)
  File "D:\Jafar\AAD\.env\lib\site-packages\rest_framework\utils\encoders.py", line 50, in default
    return obj.decode()
UnicodeDecodeError: 'utf-8' codec can't decode byte 0xe2 in position 1: invalid continuation byte
[35;1mHTTP GET /doctor/api/ViewFamilyDetails/181/ 500 [0.34, 127.0.0.1:56396][0m
Internal Server Error: /doctor/api/ViewFamilyDetails/181/
Traceback (most recent call last):
  File "D:\Jafar\AAD\.env\lib\site-packages\asgiref\sync.py", line 534, in thread_handler
    raise exc_info[1]
  File "D:\Jafar\AAD\.env\lib\site-packages\django\core\handlers\exception.py", line 42, in inner
    response = await get_response(request)
  File "D:\Jafar\AAD\.env\lib\site-packages\django\core\handlers\base.py", line 284, in _get_response_async
    response = await sync_to_async(
  File "D:\Jafar\AAD\.env\lib\site-packages\asgiref\sync.py", line 479, in __call__
    ret: _R = await loop.run_in_executor(
  File "C:\Program Files\WindowsApps\PythonSoftwareFoundation.Python.3.10_3.10.3056.0_x64__qbz5n2kfra8p0\lib\concurrent\futures\thread.py", line 58, in run
    result = self.fn(*self.args, **self.kwargs)
  File "D:\Jafar\AAD\.env\lib\site-packages\asgiref\sync.py", line 538, in thread_handler
    return func(*args, **kwargs)
  File "D:\Jafar\AAD\.env\lib\site-packages\django\template\response.py", line 114, in render
    self.content = self.rendered_content
  File "D:\Jafar\AAD\.env\lib\site-packages\rest_framework\response.py", line 70, in rendered_content
    ret = renderer.render(self.data, accepted_media_type, context)
  File "D:\Jafar\AAD\.env\lib\site-packages\rest_framework\renderers.py", line 99, in render
    ret = json.dumps(
  File "D:\Jafar\AAD\.env\lib\site-packages\rest_framework\utils\json.py", line 25, in dumps
    return json.dumps(*args, **kwargs)
  File "C:\Program Files\WindowsApps\PythonSoftwareFoundation.Python.3.10_3.10.3056.0_x64__qbz5n2kfra8p0\lib\json\__init__.py", line 238, in dumps
    **kw).encode(obj)
  File "C:\Program Files\WindowsApps\PythonSoftwareFoundation.Python.3.10_3.10.3056.0_x64__qbz5n2kfra8p0\lib\json\encoder.py", line 199, in encode
    chunks = self.iterencode(o, _one_shot=True)
  File "C:\Program Files\WindowsApps\PythonSoftwareFoundation.Python.3.10_3.10.3056.0_x64__qbz5n2kfra8p0\lib\json\encoder.py", line 257, in iterencode
    return _iterencode(o, 0)
  File "D:\Jafar\AAD\.env\lib\site-packages\rest_framework\utils\encoders.py", line 50, in default
    return obj.decode()
UnicodeDecodeError: 'utf-8' codec can't decode byte 0xe2 in position 1: invalid continuation byte
[35;1mHTTP GET /doctor/api/ViewFamilyDetails/181/ 500 [0.32, 127.0.0.1:56429][0m
Internal Server Error: /doctor/api/ViewFamilyDetails/180/
Traceback (most recent call last):
  File "D:\Jafar\AAD\.env\lib\site-packages\asgiref\sync.py", line 534, in thread_handler
    raise exc_info[1]
  File "D:\Jafar\AAD\.env\lib\site-packages\django\core\handlers\exception.py", line 42, in inner
    response = await get_response(request)
  File "D:\Jafar\AAD\.env\lib\site-packages\django\core\handlers\base.py", line 253, in _get_response_async
    response = await wrapped_callback(
  File "D:\Jafar\AAD\.env\lib\site-packages\asgiref\sync.py", line 479, in __call__
    ret: _R = await loop.run_in_executor(
  File "C:\Program Files\WindowsApps\PythonSoftwareFoundation.Python.3.10_3.10.3056.0_x64__qbz5n2kfra8p0\lib\concurrent\futures\thread.py", line 58, in run
    result = self.fn(*self.args, **self.kwargs)
  File "D:\Jafar\AAD\.env\lib\site-packages\asgiref\sync.py", line 538, in thread_handler
    return func(*args, **kwargs)
  File "D:\Jafar\AAD\.env\lib\site-packages\django\views\decorators\csrf.py", line 56, in wrapper_view
    return view_func(*args, **kwargs)
  File "D:\Jafar\AAD\.env\lib\site-packages\django\views\generic\base.py", line 104, in view
    return self.dispatch(request, *args, **kwargs)
  File "D:\Jafar\AAD\.env\lib\site-packages\rest_framework\views.py", line 509, in dispatch
    response = self.handle_exception(exc)
  File "D:\Jafar\AAD\.env\lib\site-packages\rest_framework\views.py", line 469, in handle_exception
    self.raise_uncaught_exception(exc)
  File "D:\Jafar\AAD\.env\lib\site-packages\rest_framework\views.py", line 480, in raise_uncaught_exception
    raise exc
  File "D:\Jafar\AAD\.env\lib\site-packages\rest_framework\views.py", line 506, in dispatch
    response = handler(request, *args, **kwargs)
  File "D:\Jafar\AAD\.env\lib\site-packages\rest_framework\decorators.py", line 50, in handler
    return func(*args, **kwargs)
  File "D:\Jafar\AAD\doctorsApp\views.py", line 213, in ViewFamilyDetails
    testData  = serializer.data
  File "D:\Jafar\AAD\.env\lib\site-packages\rest_framework\serializers.py", line 555, in data
    ret = super().data
  File "D:\Jafar\AAD\.env\lib\site-packages\rest_framework\serializers.py", line 253, in data
    self._data = self.to_representation(self.instance)
  File "D:\Jafar\AAD\.env\lib\site-packages\rest_framework\serializers.py", line 522, in to_representation
    ret[field.field_name] = field.to_representation(attribute)
  File "D:\Jafar\AAD\.env\lib\site-packages\rest_framework\serializers.py", line 686, in to_representation
    return [
  File "D:\Jafar\AAD\.env\lib\site-packages\rest_framework\serializers.py", line 687, in <listcomp>
    self.child.to_representation(item) for item in iterable
  File "D:\Jafar\AAD\.env\lib\site-packages\rest_framework\serializers.py", line 522, in to_representation
    ret[field.field_name] = field.to_representation(attribute)
  File "D:\Jafar\AAD\.env\lib\site-packages\rest_framework\fields.py", line 1838, in to_representation
    return method(value)
  File "D:\Jafar\AAD\doctorsApp\serializers.py", line 167, in get_report
    return pdf_url
UnboundLocalError: local variable 'pdf_url' referenced before assignment
[35;1mHTTP GET /doctor/api/ViewFamilyDetails/180/ 500 [0.25, 127.0.0.1:56672][0m
Internal Server Error: /doctor/api/ViewFamilyDetails/180/
Traceback (most recent call last):
  File "D:\Jafar\AAD\.env\lib\site-packages\asgiref\sync.py", line 534, in thread_handler
    raise exc_info[1]
  File "D:\Jafar\AAD\.env\lib\site-packages\django\core\handlers\exception.py", line 42, in inner
    response = await get_response(request)
  File "D:\Jafar\AAD\.env\lib\site-packages\django\core\handlers\base.py", line 253, in _get_response_async
    response = await wrapped_callback(
  File "D:\Jafar\AAD\.env\lib\site-packages\asgiref\sync.py", line 479, in __call__
    ret: _R = await loop.run_in_executor(
  File "C:\Program Files\WindowsApps\PythonSoftwareFoundation.Python.3.10_3.10.3056.0_x64__qbz5n2kfra8p0\lib\concurrent\futures\thread.py", line 58, in run
    result = self.fn(*self.args, **self.kwargs)
  File "D:\Jafar\AAD\.env\lib\site-packages\asgiref\sync.py", line 538, in thread_handler
    return func(*args, **kwargs)
  File "D:\Jafar\AAD\.env\lib\site-packages\django\views\decorators\csrf.py", line 56, in wrapper_view
    return view_func(*args, **kwargs)
  File "D:\Jafar\AAD\.env\lib\site-packages\django\views\generic\base.py", line 104, in view
    return self.dispatch(request, *args, **kwargs)
  File "D:\Jafar\AAD\.env\lib\site-packages\rest_framework\views.py", line 509, in dispatch
    response = self.handle_exception(exc)
  File "D:\Jafar\AAD\.env\lib\site-packages\rest_framework\views.py", line 469, in handle_exception
    self.raise_uncaught_exception(exc)
  File "D:\Jafar\AAD\.env\lib\site-packages\rest_framework\views.py", line 480, in raise_uncaught_exception
    raise exc
  File "D:\Jafar\AAD\.env\lib\site-packages\rest_framework\views.py", line 506, in dispatch
    response = handler(request, *args, **kwargs)
  File "D:\Jafar\AAD\.env\lib\site-packages\rest_framework\decorators.py", line 50, in handler
    return func(*args, **kwargs)
  File "D:\Jafar\AAD\doctorsApp\views.py", line 213, in ViewFamilyDetails
    testData  = serializer.data
  File "D:\Jafar\AAD\.env\lib\site-packages\rest_framework\serializers.py", line 555, in data
    ret = super().data
  File "D:\Jafar\AAD\.env\lib\site-packages\rest_framework\serializers.py", line 253, in data
    self._data = self.to_representation(self.instance)
  File "D:\Jafar\AAD\.env\lib\site-packages\rest_framework\serializers.py", line 522, in to_representation
    ret[field.field_name] = field.to_representation(attribute)
  File "D:\Jafar\AAD\.env\lib\site-packages\rest_framework\serializers.py", line 686, in to_representation
    return [
  File "D:\Jafar\AAD\.env\lib\site-packages\rest_framework\serializers.py", line 687, in <listcomp>
    self.child.to_representation(item) for item in iterable
  File "D:\Jafar\AAD\.env\lib\site-packages\rest_framework\serializers.py", line 522, in to_representation
    ret[field.field_name] = field.to_representation(attribute)
  File "D:\Jafar\AAD\.env\lib\site-packages\rest_framework\fields.py", line 1838, in to_representation
    return method(value)
  File "D:\Jafar\AAD\doctorsApp\serializers.py", line 168, in get_report
    return pdf_url
UnboundLocalError: local variable 'pdf_url' referenced before assignment
[35;1mHTTP GET /doctor/api/ViewFamilyDetails/180/ 500 [0.15, 127.0.0.1:56710][0m
view's UpdateUserDetails raised exception during schema generation; use `getattr(self, 'swagger_fake_view', False)` to detect and short-circuit this
Traceback (most recent call last):
  File "D:\Jafar\AAD\.env\lib\site-packages\drf_yasg\inspectors\base.py", line 42, in call_view_method
    return view_method()
  File "D:\Jafar\AAD\.env\lib\site-packages\rest_framework\generics.py", line 63, in get_queryset
    assert self.queryset is not None, (
AssertionError: 'UpdateUserDetails' should either include a `queryset` attribute, or override the `get_queryset()` method.
Bad Request: /allauth/api/login
[31;1mHTTP POST /allauth/api/login 400 [1.00, 127.0.0.1:58611][0m
Bad Request: /allauth/api/login
[31;1mHTTP POST /allauth/api/login 400 [1.02, 127.0.0.1:58611][0m
view's UpdateUserDetails raised exception during schema generation; use `getattr(self, 'swagger_fake_view', False)` to detect and short-circuit this
Traceback (most recent call last):
  File "D:\Jafar\AAD\.env\lib\site-packages\drf_yasg\inspectors\base.py", line 42, in call_view_method
    return view_method()
  File "D:\Jafar\AAD\.env\lib\site-packages\rest_framework\generics.py", line 63, in get_queryset
    assert self.queryset is not None, (
AssertionError: 'UpdateUserDetails' should either include a `queryset` attribute, or override the `get_queryset()` method.
Not Found: /
[33mHTTP GET / 404 [0.11, 127.0.0.1:65338][0m
Not Found: /favicon.ico
[33mHTTP GET /favicon.ico 404 [0.03, 127.0.0.1:65338][0m
view's UpdateUserDetails raised exception during schema generation; use `getattr(self, 'swagger_fake_view', False)` to detect and short-circuit this
Traceback (most recent call last):
  File "D:\Jafar\AAD\.env\lib\site-packages\drf_yasg\inspectors\base.py", line 42, in call_view_method
    return view_method()
  File "D:\Jafar\AAD\.env\lib\site-packages\rest_framework\generics.py", line 63, in get_queryset
    assert self.queryset is not None, (
AssertionError: 'UpdateUserDetails' should either include a `queryset` attribute, or override the `get_queryset()` method.
view's UpdateUserDetails raised exception during schema generation; use `getattr(self, 'swagger_fake_view', False)` to detect and short-circuit this
Traceback (most recent call last):
  File "D:\Jafar\AAD\.env\lib\site-packages\drf_yasg\inspectors\base.py", line 42, in call_view_method
    return view_method()
  File "D:\Jafar\AAD\.env\lib\site-packages\rest_framework\generics.py", line 63, in get_queryset
    assert self.queryset is not None, (
AssertionError: 'UpdateUserDetails' should either include a `queryset` attribute, or override the `get_queryset()` method.
Unauthorized: /healthworker/api/PostSurveyForm
[31;1mHTTP POST /healthworker/api/PostSurveyForm 401 [0.02, 127.0.0.1:49692][0m
Bad Request: /allauth/api/login
[31;1mHTTP POST /allauth/api/login 400 [0.35, 127.0.0.1:49828][0m
Bad Request: /allauth/api/login
[31;1mHTTP POST /allauth/api/login 400 [0.33, 127.0.0.1:49828][0m
Bad Request: /allauth/api/login
[31;1mHTTP POST /allauth/api/login 400 [0.39, 127.0.0.1:49828][0m
Bad Request: /allauth/api/login
[31;1mHTTP POST /allauth/api/login 400 [0.78, 127.0.0.1:49828][0m
Bad Request: /healthworker/api/PostSurveyForm
[31;1mHTTP POST /healthworker/api/PostSurveyForm 400 [0.20, 127.0.0.1:49828][0m
Bad Request: /healthworker/api/PostSurveyForm
[31;1mHTTP POST /healthworker/api/PostSurveyForm 400 [0.22, 127.0.0.1:49993][0m
Internal Server Error: /healthworker/api/PostSurveyForm
Traceback (most recent call last):
  File "D:\Jafar\AAD\.env\lib\site-packages\asgiref\sync.py", line 534, in thread_handler
    raise exc_info[1]
  File "D:\Jafar\AAD\.env\lib\site-packages\django\core\handlers\exception.py", line 42, in inner
    response = await get_response(request)
  File "D:\Jafar\AAD\.env\lib\site-packages\django\core\handlers\base.py", line 253, in _get_response_async
    response = await wrapped_callback(
  File "D:\Jafar\AAD\.env\lib\site-packages\asgiref\sync.py", line 479, in __call__
    ret: _R = await loop.run_in_executor(
  File "C:\Program Files\WindowsApps\PythonSoftwareFoundation.Python.3.10_3.10.3056.0_x64__qbz5n2kfra8p0\lib\concurrent\futures\thread.py", line 58, in run
    result = self.fn(*self.args, **self.kwargs)
  File "D:\Jafar\AAD\.env\lib\site-packages\asgiref\sync.py", line 538, in thread_handler
    return func(*args, **kwargs)
  File "D:\Jafar\AAD\.env\lib\site-packages\django\views\decorators\csrf.py", line 56, in wrapper_view
    return view_func(*args, **kwargs)
  File "D:\Jafar\AAD\.env\lib\site-packages\django\views\generic\base.py", line 104, in view
    return self.dispatch(request, *args, **kwargs)
  File "D:\Jafar\AAD\.env\lib\site-packages\rest_framework\views.py", line 509, in dispatch
    response = self.handle_exception(exc)
  File "D:\Jafar\AAD\.env\lib\site-packages\rest_framework\views.py", line 469, in handle_exception
    self.raise_uncaught_exception(exc)
  File "D:\Jafar\AAD\.env\lib\site-packages\rest_framework\views.py", line 480, in raise_uncaught_exception
    raise exc
  File "D:\Jafar\AAD\.env\lib\site-packages\rest_framework\views.py", line 506, in dispatch
    response = handler(request, *args, **kwargs)
  File "D:\Jafar\AAD\healthworker\views.py", line 106, in post
    serializer.save(location = location , familyId = familyId ,user = user )
  File "D:\Jafar\AAD\.env\lib\site-packages\rest_framework\serializers.py", line 212, in save
    self.instance = self.create(validated_data)
  File "D:\Jafar\AAD\healthworker\serializer.py", line 107, in create
    familyMembers.objects.create(familyHead = head, familySurveyor = head.user, memberId = member_id , **family)
  File "D:\Jafar\AAD\.env\lib\site-packages\django\db\models\manager.py", line 87, in manager_method
    return getattr(self.get_queryset(), name)(*args, **kwargs)
  File "D:\Jafar\AAD\.env\lib\site-packages\django\db\models\query.py", line 656, in create
    obj = self.model(**kwargs)
  File "D:\Jafar\AAD\.env\lib\site-packages\django\db\models\base.py", line 564, in __init__
    _setattr(self, prop, value)
  File "D:\Jafar\AAD\.env\lib\site-packages\django\db\models\fields\related_descriptors.py", line 626, in __set__
    raise TypeError(
TypeError: Direct assignment to the forward side of a many-to-many set is prohibited. Use referels.set() instead.
[35;1mHTTP POST /healthworker/api/PostSurveyForm 500 [1.30, 127.0.0.1:50248][0m
Unauthorized: /healthworker/api/PostSurveyForm
[31;1mHTTP POST /healthworker/api/PostSurveyForm 401 [0.10, 127.0.0.1:50635][0m
Bad Request: /healthworker/api/PostSurveyForm
[31;1mHTTP POST /healthworker/api/PostSurveyForm 400 [0.12, 127.0.0.1:50635][0m
Internal Server Error: /healthworker/api/PostSurveyForm
Traceback (most recent call last):
  File "D:\Jafar\AAD\.env\lib\site-packages\asgiref\sync.py", line 534, in thread_handler
    raise exc_info[1]
  File "D:\Jafar\AAD\.env\lib\site-packages\django\core\handlers\exception.py", line 42, in inner
    response = await get_response(request)
  File "D:\Jafar\AAD\.env\lib\site-packages\django\core\handlers\base.py", line 253, in _get_response_async
    response = await wrapped_callback(
  File "D:\Jafar\AAD\.env\lib\site-packages\asgiref\sync.py", line 479, in __call__
    ret: _R = await loop.run_in_executor(
  File "C:\Program Files\WindowsApps\PythonSoftwareFoundation.Python.3.10_3.10.3056.0_x64__qbz5n2kfra8p0\lib\concurrent\futures\thread.py", line 58, in run
    result = self.fn(*self.args, **self.kwargs)
  File "D:\Jafar\AAD\.env\lib\site-packages\asgiref\sync.py", line 538, in thread_handler
    return func(*args, **kwargs)
  File "D:\Jafar\AAD\.env\lib\site-packages\django\views\decorators\csrf.py", line 56, in wrapper_view
    return view_func(*args, **kwargs)
  File "D:\Jafar\AAD\.env\lib\site-packages\django\views\generic\base.py", line 104, in view
    return self.dispatch(request, *args, **kwargs)
  File "D:\Jafar\AAD\.env\lib\site-packages\rest_framework\views.py", line 509, in dispatch
    response = self.handle_exception(exc)
  File "D:\Jafar\AAD\.env\lib\site-packages\rest_framework\views.py", line 469, in handle_exception
    self.raise_uncaught_exception(exc)
  File "D:\Jafar\AAD\.env\lib\site-packages\rest_framework\views.py", line 480, in raise_uncaught_exception
    raise exc
  File "D:\Jafar\AAD\.env\lib\site-packages\rest_framework\views.py", line 506, in dispatch
    response = handler(request, *args, **kwargs)
  File "D:\Jafar\AAD\healthworker\views.py", line 106, in post
    serializer.save(location = location , familyId = familyId ,user = user )
  File "D:\Jafar\AAD\.env\lib\site-packages\rest_framework\serializers.py", line 212, in save
    self.instance = self.create(validated_data)
  File "D:\Jafar\AAD\healthworker\serializer.py", line 104, in create
    refereloption = data.pop('referels')
KeyError: 'referels'
[35;1mHTTP POST /healthworker/api/PostSurveyForm 500 [1.01, 127.0.0.1:50635][0m
Bad Request: /healthworker/api/PostSurveyForm
[31;1mHTTP POST /healthworker/api/PostSurveyForm 400 [0.18, 127.0.0.1:50906][0m
Internal Server Error: /healthworker/api/PostSurveyForm
Traceback (most recent call last):
  File "D:\Jafar\AAD\.env\lib\site-packages\asgiref\sync.py", line 534, in thread_handler
    raise exc_info[1]
  File "D:\Jafar\AAD\.env\lib\site-packages\django\core\handlers\exception.py", line 42, in inner
    response = await get_response(request)
  File "D:\Jafar\AAD\.env\lib\site-packages\django\core\handlers\base.py", line 253, in _get_response_async
    response = await wrapped_callback(
  File "D:\Jafar\AAD\.env\lib\site-packages\asgiref\sync.py", line 479, in __call__
    ret: _R = await loop.run_in_executor(
  File "C:\Program Files\WindowsApps\PythonSoftwareFoundation.Python.3.10_3.10.3056.0_x64__qbz5n2kfra8p0\lib\concurrent\futures\thread.py", line 58, in run
    result = self.fn(*self.args, **self.kwargs)
  File "D:\Jafar\AAD\.env\lib\site-packages\asgiref\sync.py", line 538, in thread_handler
    return func(*args, **kwargs)
  File "D:\Jafar\AAD\.env\lib\site-packages\django\views\decorators\csrf.py", line 56, in wrapper_view
    return view_func(*args, **kwargs)
  File "D:\Jafar\AAD\.env\lib\site-packages\django\views\generic\base.py", line 104, in view
    return self.dispatch(request, *args, **kwargs)
  File "D:\Jafar\AAD\.env\lib\site-packages\rest_framework\views.py", line 509, in dispatch
    response = self.handle_exception(exc)
  File "D:\Jafar\AAD\.env\lib\site-packages\rest_framework\views.py", line 469, in handle_exception
    self.raise_uncaught_exception(exc)
  File "D:\Jafar\AAD\.env\lib\site-packages\rest_framework\views.py", line 480, in raise_uncaught_exception
    raise exc
  File "D:\Jafar\AAD\.env\lib\site-packages\rest_framework\views.py", line 506, in dispatch
    response = handler(request, *args, **kwargs)
  File "D:\Jafar\AAD\healthworker\views.py", line 106, in post
    serializer.save(location = location , familyId = familyId ,user = user )
  File "D:\Jafar\AAD\.env\lib\site-packages\rest_framework\serializers.py", line 212, in save
    self.instance = self.create(validated_data)
  File "D:\Jafar\AAD\healthworker\serializer.py", line 107, in create
    familyMembers.objects.create(familyHead = head, familySurveyor = head.user, memberId = member_id , **family)
  File "D:\Jafar\AAD\.env\lib\site-packages\django\db\models\manager.py", line 87, in manager_method
    return getattr(self.get_queryset(), name)(*args, **kwargs)
  File "D:\Jafar\AAD\.env\lib\site-packages\django\db\models\query.py", line 656, in create
    obj = self.model(**kwargs)
  File "D:\Jafar\AAD\.env\lib\site-packages\django\db\models\base.py", line 564, in __init__
    _setattr(self, prop, value)
  File "D:\Jafar\AAD\.env\lib\site-packages\django\db\models\fields\related_descriptors.py", line 626, in __set__
    raise TypeError(
TypeError: Direct assignment to the forward side of a many-to-many set is prohibited. Use referels.set() instead.
[35;1mHTTP POST /healthworker/api/PostSurveyForm 500 [0.63, 127.0.0.1:50906][0m
Internal Server Error: /healthworker/api/PostSurveyForm
Traceback (most recent call last):
  File "D:\Jafar\AAD\.env\lib\site-packages\asgiref\sync.py", line 534, in thread_handler
    raise exc_info[1]
  File "D:\Jafar\AAD\.env\lib\site-packages\django\core\handlers\exception.py", line 42, in inner
    response = await get_response(request)
  File "D:\Jafar\AAD\.env\lib\site-packages\django\core\handlers\base.py", line 253, in _get_response_async
    response = await wrapped_callback(
  File "D:\Jafar\AAD\.env\lib\site-packages\asgiref\sync.py", line 479, in __call__
    ret: _R = await loop.run_in_executor(
  File "C:\Program Files\WindowsApps\PythonSoftwareFoundation.Python.3.10_3.10.3056.0_x64__qbz5n2kfra8p0\lib\concurrent\futures\thread.py", line 58, in run
    result = self.fn(*self.args, **self.kwargs)
  File "D:\Jafar\AAD\.env\lib\site-packages\asgiref\sync.py", line 538, in thread_handler
    return func(*args, **kwargs)
  File "D:\Jafar\AAD\.env\lib\site-packages\django\views\decorators\csrf.py", line 56, in wrapper_view
    return view_func(*args, **kwargs)
  File "D:\Jafar\AAD\.env\lib\site-packages\django\views\generic\base.py", line 104, in view
    return self.dispatch(request, *args, **kwargs)
  File "D:\Jafar\AAD\.env\lib\site-packages\rest_framework\views.py", line 509, in dispatch
    response = self.handle_exception(exc)
  File "D:\Jafar\AAD\.env\lib\site-packages\rest_framework\views.py", line 469, in handle_exception
    self.raise_uncaught_exception(exc)
  File "D:\Jafar\AAD\.env\lib\site-packages\rest_framework\views.py", line 480, in raise_uncaught_exception
    raise exc
  File "D:\Jafar\AAD\.env\lib\site-packages\rest_framework\views.py", line 506, in dispatch
    response = handler(request, *args, **kwargs)
  File "D:\Jafar\AAD\healthworker\views.py", line 106, in post
    serializer.save(location = location , familyId = familyId ,user = user )
  File "D:\Jafar\AAD\.env\lib\site-packages\rest_framework\serializers.py", line 212, in save
    self.instance = self.create(validated_data)
  File "D:\Jafar\AAD\healthworker\serializer.py", line 108, in create
    familyMembers.objects.create(familyHead = head, familySurveyor = head.user, memberId = member_id , **family)
  File "D:\Jafar\AAD\.env\lib\site-packages\django\db\models\manager.py", line 87, in manager_method
    return getattr(self.get_queryset(), name)(*args, **kwargs)
  File "D:\Jafar\AAD\.env\lib\site-packages\django\db\models\query.py", line 656, in create
    obj = self.model(**kwargs)
  File "D:\Jafar\AAD\.env\lib\site-packages\django\db\models\base.py", line 564, in __init__
    _setattr(self, prop, value)
  File "D:\Jafar\AAD\.env\lib\site-packages\django\db\models\fields\related_descriptors.py", line 626, in __set__
    raise TypeError(
TypeError: Direct assignment to the forward side of a many-to-many set is prohibited. Use referels.set() instead.
[35;1mHTTP POST /healthworker/api/PostSurveyForm 500 [1.39, 127.0.0.1:51005][0m
Bad Request: /healthworker/api/PostSurveyForm
[31;1mHTTP POST /healthworker/api/PostSurveyForm 400 [0.28, 127.0.0.1:51045][0m
Internal Server Error: /healthworker/api/PostSurveyForm
Traceback (most recent call last):
  File "D:\Jafar\AAD\.env\lib\site-packages\asgiref\sync.py", line 534, in thread_handler
    raise exc_info[1]
  File "D:\Jafar\AAD\.env\lib\site-packages\django\core\handlers\exception.py", line 42, in inner
    response = await get_response(request)
  File "D:\Jafar\AAD\.env\lib\site-packages\django\core\handlers\base.py", line 253, in _get_response_async
    response = await wrapped_callback(
  File "D:\Jafar\AAD\.env\lib\site-packages\asgiref\sync.py", line 479, in __call__
    ret: _R = await loop.run_in_executor(
  File "C:\Program Files\WindowsApps\PythonSoftwareFoundation.Python.3.10_3.10.3056.0_x64__qbz5n2kfra8p0\lib\concurrent\futures\thread.py", line 58, in run
    result = self.fn(*self.args, **self.kwargs)
  File "D:\Jafar\AAD\.env\lib\site-packages\asgiref\sync.py", line 538, in thread_handler
    return func(*args, **kwargs)
  File "D:\Jafar\AAD\.env\lib\site-packages\django\views\decorators\csrf.py", line 56, in wrapper_view
    return view_func(*args, **kwargs)
  File "D:\Jafar\AAD\.env\lib\site-packages\django\views\generic\base.py", line 104, in view
    return self.dispatch(request, *args, **kwargs)
  File "D:\Jafar\AAD\.env\lib\site-packages\rest_framework\views.py", line 509, in dispatch
    response = self.handle_exception(exc)
  File "D:\Jafar\AAD\.env\lib\site-packages\rest_framework\views.py", line 469, in handle_exception
    self.raise_uncaught_exception(exc)
  File "D:\Jafar\AAD\.env\lib\site-packages\rest_framework\views.py", line 480, in raise_uncaught_exception
    raise exc
  File "D:\Jafar\AAD\.env\lib\site-packages\rest_framework\views.py", line 506, in dispatch
    response = handler(request, *args, **kwargs)
  File "D:\Jafar\AAD\healthworker\views.py", line 106, in post
    serializer.save(location = location , familyId = familyId ,user = user )
  File "D:\Jafar\AAD\.env\lib\site-packages\rest_framework\serializers.py", line 212, in save
    self.instance = self.create(validated_data)
  File "D:\Jafar\AAD\healthworker\serializer.py", line 102, in create
    print(familyMembers_details.referels)
AttributeError: 'list' object has no attribute 'referels'
[35;1mHTTP POST /healthworker/api/PostSurveyForm 500 [0.18, 127.0.0.1:51045][0m
Internal Server Error: /healthworker/api/PostSurveyForm
Traceback (most recent call last):
  File "D:\Jafar\AAD\.env\lib\site-packages\asgiref\sync.py", line 534, in thread_handler
    raise exc_info[1]
  File "D:\Jafar\AAD\.env\lib\site-packages\django\core\handlers\exception.py", line 42, in inner
    response = await get_response(request)
  File "D:\Jafar\AAD\.env\lib\site-packages\django\core\handlers\base.py", line 253, in _get_response_async
    response = await wrapped_callback(
  File "D:\Jafar\AAD\.env\lib\site-packages\asgiref\sync.py", line 479, in __call__
    ret: _R = await loop.run_in_executor(
  File "C:\Program Files\WindowsApps\PythonSoftwareFoundation.Python.3.10_3.10.3056.0_x64__qbz5n2kfra8p0\lib\concurrent\futures\thread.py", line 58, in run
    result = self.fn(*self.args, **self.kwargs)
  File "D:\Jafar\AAD\.env\lib\site-packages\asgiref\sync.py", line 538, in thread_handler
    return func(*args, **kwargs)
  File "D:\Jafar\AAD\.env\lib\site-packages\django\views\decorators\csrf.py", line 56, in wrapper_view
    return view_func(*args, **kwargs)
  File "D:\Jafar\AAD\.env\lib\site-packages\django\views\generic\base.py", line 104, in view
    return self.dispatch(request, *args, **kwargs)
  File "D:\Jafar\AAD\.env\lib\site-packages\rest_framework\views.py", line 509, in dispatch
    response = self.handle_exception(exc)
  File "D:\Jafar\AAD\.env\lib\site-packages\rest_framework\views.py", line 469, in handle_exception
    self.raise_uncaught_exception(exc)
  File "D:\Jafar\AAD\.env\lib\site-packages\rest_framework\views.py", line 480, in raise_uncaught_exception
    raise exc
  File "D:\Jafar\AAD\.env\lib\site-packages\rest_framework\views.py", line 506, in dispatch
    response = handler(request, *args, **kwargs)
  File "D:\Jafar\AAD\healthworker\views.py", line 106, in post
    serializer.save(location = location , familyId = familyId ,user = user )
  File "D:\Jafar\AAD\.env\lib\site-packages\rest_framework\serializers.py", line 212, in save
    self.instance = self.create(validated_data)
  File "D:\Jafar\AAD\healthworker\serializer.py", line 102, in create
    print(familyMembers_details.get('referels'))
AttributeError: 'list' object has no attribute 'get'
[35;1mHTTP POST /healthworker/api/PostSurveyForm 500 [0.33, 127.0.0.1:51106][0m
Internal Server Error: /healthworker/api/PostSurveyForm
Traceback (most recent call last):
  File "D:\Jafar\AAD\.env\lib\site-packages\asgiref\sync.py", line 534, in thread_handler
    raise exc_info[1]
  File "D:\Jafar\AAD\.env\lib\site-packages\django\core\handlers\exception.py", line 42, in inner
    response = await get_response(request)
  File "D:\Jafar\AAD\.env\lib\site-packages\django\core\handlers\base.py", line 253, in _get_response_async
    response = await wrapped_callback(
  File "D:\Jafar\AAD\.env\lib\site-packages\asgiref\sync.py", line 479, in __call__
    ret: _R = await loop.run_in_executor(
  File "C:\Program Files\WindowsApps\PythonSoftwareFoundation.Python.3.10_3.10.3056.0_x64__qbz5n2kfra8p0\lib\concurrent\futures\thread.py", line 58, in run
    result = self.fn(*self.args, **self.kwargs)
  File "D:\Jafar\AAD\.env\lib\site-packages\asgiref\sync.py", line 538, in thread_handler
    return func(*args, **kwargs)
  File "D:\Jafar\AAD\.env\lib\site-packages\django\views\decorators\csrf.py", line 56, in wrapper_view
    return view_func(*args, **kwargs)
  File "D:\Jafar\AAD\.env\lib\site-packages\django\views\generic\base.py", line 104, in view
    return self.dispatch(request, *args, **kwargs)
  File "D:\Jafar\AAD\.env\lib\site-packages\rest_framework\views.py", line 509, in dispatch
    response = self.handle_exception(exc)
  File "D:\Jafar\AAD\.env\lib\site-packages\rest_framework\views.py", line 469, in handle_exception
    self.raise_uncaught_exception(exc)
  File "D:\Jafar\AAD\.env\lib\site-packages\rest_framework\views.py", line 480, in raise_uncaught_exception
    raise exc
  File "D:\Jafar\AAD\.env\lib\site-packages\rest_framework\views.py", line 506, in dispatch
    response = handler(request, *args, **kwargs)
  File "D:\Jafar\AAD\healthworker\views.py", line 106, in post
    serializer.save(location = location , familyId = familyId ,user = user )
  File "D:\Jafar\AAD\.env\lib\site-packages\rest_framework\serializers.py", line 212, in save
    self.instance = self.create(validated_data)
  File "D:\Jafar\AAD\healthworker\serializer.py", line 102, in create
    print(familyMembers_details['referels'])
TypeError: list indices must be integers or slices, not str
[35;1mHTTP POST /healthworker/api/PostSurveyForm 500 [0.26, 127.0.0.1:51163][0m
Internal Server Error: /healthworker/api/PostSurveyForm
Traceback (most recent call last):
  File "D:\Jafar\AAD\.env\lib\site-packages\asgiref\sync.py", line 534, in thread_handler
    raise exc_info[1]
  File "D:\Jafar\AAD\.env\lib\site-packages\django\core\handlers\exception.py", line 42, in inner
    response = await get_response(request)
  File "D:\Jafar\AAD\.env\lib\site-packages\django\core\handlers\base.py", line 253, in _get_response_async
    response = await wrapped_callback(
  File "D:\Jafar\AAD\.env\lib\site-packages\asgiref\sync.py", line 479, in __call__
    ret: _R = await loop.run_in_executor(
  File "C:\Program Files\WindowsApps\PythonSoftwareFoundation.Python.3.10_3.10.3056.0_x64__qbz5n2kfra8p0\lib\concurrent\futures\thread.py", line 58, in run
    result = self.fn(*self.args, **self.kwargs)
  File "D:\Jafar\AAD\.env\lib\site-packages\asgiref\sync.py", line 538, in thread_handler
    return func(*args, **kwargs)
  File "D:\Jafar\AAD\.env\lib\site-packages\django\views\decorators\csrf.py", line 56, in wrapper_view
    return view_func(*args, **kwargs)
  File "D:\Jafar\AAD\.env\lib\site-packages\django\views\generic\base.py", line 104, in view
    return self.dispatch(request, *args, **kwargs)
  File "D:\Jafar\AAD\.env\lib\site-packages\rest_framework\views.py", line 509, in dispatch
    response = self.handle_exception(exc)
  File "D:\Jafar\AAD\.env\lib\site-packages\rest_framework\views.py", line 469, in handle_exception
    self.raise_uncaught_exception(exc)
  File "D:\Jafar\AAD\.env\lib\site-packages\rest_framework\views.py", line 480, in raise_uncaught_exception
    raise exc
  File "D:\Jafar\AAD\.env\lib\site-packages\rest_framework\views.py", line 506, in dispatch
    response = handler(request, *args, **kwargs)
  File "D:\Jafar\AAD\healthworker\views.py", line 106, in post
    serializer.save(location = location , familyId = familyId ,user = user )
  File "D:\Jafar\AAD\.env\lib\site-packages\rest_framework\serializers.py", line 212, in save
    self.instance = self.create(validated_data)
  File "D:\Jafar\AAD\healthworker\serializer.py", line 102, in create
    print(familyMembers_details.referels)
AttributeError: 'list' object has no attribute 'referels'
[35;1mHTTP POST /healthworker/api/PostSurveyForm 500 [0.24, 127.0.0.1:51219][0m
Internal Server Error: /healthworker/api/PostSurveyForm
Traceback (most recent call last):
  File "D:\Jafar\AAD\.env\lib\site-packages\asgiref\sync.py", line 534, in thread_handler
    raise exc_info[1]
  File "D:\Jafar\AAD\.env\lib\site-packages\django\core\handlers\exception.py", line 42, in inner
    response = await get_response(request)
  File "D:\Jafar\AAD\.env\lib\site-packages\django\core\handlers\base.py", line 253, in _get_response_async
    response = await wrapped_callback(
  File "D:\Jafar\AAD\.env\lib\site-packages\asgiref\sync.py", line 479, in __call__
    ret: _R = await loop.run_in_executor(
  File "C:\Program Files\WindowsApps\PythonSoftwareFoundation.Python.3.10_3.10.3056.0_x64__qbz5n2kfra8p0\lib\concurrent\futures\thread.py", line 58, in run
    result = self.fn(*self.args, **self.kwargs)
  File "D:\Jafar\AAD\.env\lib\site-packages\asgiref\sync.py", line 538, in thread_handler
    return func(*args, **kwargs)
  File "D:\Jafar\AAD\.env\lib\site-packages\django\views\decorators\csrf.py", line 56, in wrapper_view
    return view_func(*args, **kwargs)
  File "D:\Jafar\AAD\.env\lib\site-packages\django\views\generic\base.py", line 104, in view
    return self.dispatch(request, *args, **kwargs)
  File "D:\Jafar\AAD\.env\lib\site-packages\rest_framework\views.py", line 509, in dispatch
    response = self.handle_exception(exc)
  File "D:\Jafar\AAD\.env\lib\site-packages\rest_framework\views.py", line 469, in handle_exception
    self.raise_uncaught_exception(exc)
  File "D:\Jafar\AAD\.env\lib\site-packages\rest_framework\views.py", line 480, in raise_uncaught_exception
    raise exc
  File "D:\Jafar\AAD\.env\lib\site-packages\rest_framework\views.py", line 506, in dispatch
    response = handler(request, *args, **kwargs)
  File "D:\Jafar\AAD\healthworker\views.py", line 106, in post
    serializer.save(location = location , familyId = familyId ,user = user )
  File "D:\Jafar\AAD\.env\lib\site-packages\rest_framework\serializers.py", line 212, in save
    self.instance = self.create(validated_data)
  File "D:\Jafar\AAD\healthworker\serializer.py", line 108, in create
    familyMembers.objects.create(familyHead = head, familySurveyor = head.user, memberId = member_id , **family)
  File "D:\Jafar\AAD\.env\lib\site-packages\django\db\models\manager.py", line 87, in manager_method
    return getattr(self.get_queryset(), name)(*args, **kwargs)
  File "D:\Jafar\AAD\.env\lib\site-packages\django\db\models\query.py", line 656, in create
    obj = self.model(**kwargs)
  File "D:\Jafar\AAD\.env\lib\site-packages\django\db\models\base.py", line 564, in __init__
    _setattr(self, prop, value)
  File "D:\Jafar\AAD\.env\lib\site-packages\django\db\models\fields\related_descriptors.py", line 626, in __set__
    raise TypeError(
TypeError: Direct assignment to the forward side of a many-to-many set is prohibited. Use referels.set() instead.
[35;1mHTTP POST /healthworker/api/PostSurveyForm 500 [0.66, 127.0.0.1:51247][0m
Bad Request: /healthworker/api/PostSurveyForm
[31;1mHTTP POST /healthworker/api/PostSurveyForm 400 [0.14, 127.0.0.1:51468][0m
Bad Request: /healthworker/api/PostSurveyForm
[31;1mHTTP POST /healthworker/api/PostSurveyForm 400 [0.18, 127.0.0.1:51468][0m
Internal Server Error: /healthworker/api/PostSurveyForm
Traceback (most recent call last):
  File "D:\Jafar\AAD\.env\lib\site-packages\asgiref\sync.py", line 534, in thread_handler
    raise exc_info[1]
  File "D:\Jafar\AAD\.env\lib\site-packages\django\core\handlers\exception.py", line 42, in inner
    response = await get_response(request)
  File "D:\Jafar\AAD\.env\lib\site-packages\django\core\handlers\base.py", line 253, in _get_response_async
    response = await wrapped_callback(
  File "D:\Jafar\AAD\.env\lib\site-packages\asgiref\sync.py", line 479, in __call__
    ret: _R = await loop.run_in_executor(
  File "C:\Program Files\WindowsApps\PythonSoftwareFoundation.Python.3.10_3.10.3056.0_x64__qbz5n2kfra8p0\lib\concurrent\futures\thread.py", line 58, in run
    result = self.fn(*self.args, **self.kwargs)
  File "D:\Jafar\AAD\.env\lib\site-packages\asgiref\sync.py", line 538, in thread_handler
    return func(*args, **kwargs)
  File "D:\Jafar\AAD\.env\lib\site-packages\django\views\decorators\csrf.py", line 56, in wrapper_view
    return view_func(*args, **kwargs)
  File "D:\Jafar\AAD\.env\lib\site-packages\django\views\generic\base.py", line 104, in view
    return self.dispatch(request, *args, **kwargs)
  File "D:\Jafar\AAD\.env\lib\site-packages\rest_framework\views.py", line 509, in dispatch
    response = self.handle_exception(exc)
  File "D:\Jafar\AAD\.env\lib\site-packages\rest_framework\views.py", line 469, in handle_exception
    self.raise_uncaught_exception(exc)
  File "D:\Jafar\AAD\.env\lib\site-packages\rest_framework\views.py", line 480, in raise_uncaught_exception
    raise exc
  File "D:\Jafar\AAD\.env\lib\site-packages\rest_framework\views.py", line 506, in dispatch
    response = handler(request, *args, **kwargs)
  File "D:\Jafar\AAD\healthworker\views.py", line 106, in post
    serializer.save(location = location , familyId = familyId ,user = user )
  File "D:\Jafar\AAD\.env\lib\site-packages\rest_framework\serializers.py", line 212, in save
    self.instance = self.create(validated_data)
  File "D:\Jafar\AAD\healthworker\serializer.py", line 102, in create
    for key , value in familyMembers_details:
ValueError: too many values to unpack (expected 2)
[35;1mHTTP POST /healthworker/api/PostSurveyForm 500 [0.25, 127.0.0.1:51468][0m
Internal Server Error: /healthworker/api/PostSurveyForm
Traceback (most recent call last):
  File "D:\Jafar\AAD\.env\lib\site-packages\asgiref\sync.py", line 534, in thread_handler
    raise exc_info[1]
  File "D:\Jafar\AAD\.env\lib\site-packages\django\core\handlers\exception.py", line 42, in inner
    response = await get_response(request)
  File "D:\Jafar\AAD\.env\lib\site-packages\django\core\handlers\base.py", line 253, in _get_response_async
    response = await wrapped_callback(
  File "D:\Jafar\AAD\.env\lib\site-packages\asgiref\sync.py", line 479, in __call__
    ret: _R = await loop.run_in_executor(
  File "C:\Program Files\WindowsApps\PythonSoftwareFoundation.Python.3.10_3.10.3056.0_x64__qbz5n2kfra8p0\lib\concurrent\futures\thread.py", line 58, in run
    result = self.fn(*self.args, **self.kwargs)
  File "D:\Jafar\AAD\.env\lib\site-packages\asgiref\sync.py", line 538, in thread_handler
    return func(*args, **kwargs)
  File "D:\Jafar\AAD\.env\lib\site-packages\django\views\decorators\csrf.py", line 56, in wrapper_view
    return view_func(*args, **kwargs)
  File "D:\Jafar\AAD\.env\lib\site-packages\django\views\generic\base.py", line 104, in view
    return self.dispatch(request, *args, **kwargs)
  File "D:\Jafar\AAD\.env\lib\site-packages\rest_framework\views.py", line 509, in dispatch
    response = self.handle_exception(exc)
  File "D:\Jafar\AAD\.env\lib\site-packages\rest_framework\views.py", line 469, in handle_exception
    self.raise_uncaught_exception(exc)
  File "D:\Jafar\AAD\.env\lib\site-packages\rest_framework\views.py", line 480, in raise_uncaught_exception
    raise exc
  File "D:\Jafar\AAD\.env\lib\site-packages\rest_framework\views.py", line 506, in dispatch
    response = handler(request, *args, **kwargs)
  File "D:\Jafar\AAD\healthworker\views.py", line 106, in post
    serializer.save(location = location , familyId = familyId ,user = user )
  File "D:\Jafar\AAD\.env\lib\site-packages\rest_framework\serializers.py", line 212, in save
    self.instance = self.create(validated_data)
  File "D:\Jafar\AAD\healthworker\serializer.py", line 102, in create
    for key , value in familyMembers_details:
ValueError: too many values to unpack (expected 2)
[35;1mHTTP POST /healthworker/api/PostSurveyForm 500 [0.21, 127.0.0.1:51507][0m
Internal Server Error: /healthworker/api/PostSurveyForm
Traceback (most recent call last):
  File "D:\Jafar\AAD\.env\lib\site-packages\asgiref\sync.py", line 534, in thread_handler
    raise exc_info[1]
  File "D:\Jafar\AAD\.env\lib\site-packages\django\core\handlers\exception.py", line 42, in inner
    response = await get_response(request)
  File "D:\Jafar\AAD\.env\lib\site-packages\django\core\handlers\base.py", line 253, in _get_response_async
    response = await wrapped_callback(
  File "D:\Jafar\AAD\.env\lib\site-packages\asgiref\sync.py", line 479, in __call__
    ret: _R = await loop.run_in_executor(
  File "C:\Program Files\WindowsApps\PythonSoftwareFoundation.Python.3.10_3.10.3056.0_x64__qbz5n2kfra8p0\lib\concurrent\futures\thread.py", line 58, in run
    result = self.fn(*self.args, **self.kwargs)
  File "D:\Jafar\AAD\.env\lib\site-packages\asgiref\sync.py", line 538, in thread_handler
    return func(*args, **kwargs)
  File "D:\Jafar\AAD\.env\lib\site-packages\django\views\decorators\csrf.py", line 56, in wrapper_view
    return view_func(*args, **kwargs)
  File "D:\Jafar\AAD\.env\lib\site-packages\django\views\generic\base.py", line 104, in view
    return self.dispatch(request, *args, **kwargs)
  File "D:\Jafar\AAD\.env\lib\site-packages\rest_framework\views.py", line 509, in dispatch
    response = self.handle_exception(exc)
  File "D:\Jafar\AAD\.env\lib\site-packages\rest_framework\views.py", line 469, in handle_exception
    self.raise_uncaught_exception(exc)
  File "D:\Jafar\AAD\.env\lib\site-packages\rest_framework\views.py", line 480, in raise_uncaught_exception
    raise exc
  File "D:\Jafar\AAD\.env\lib\site-packages\rest_framework\views.py", line 506, in dispatch
    response = handler(request, *args, **kwargs)
  File "D:\Jafar\AAD\healthworker\views.py", line 106, in post
    serializer.save(location = location , familyId = familyId ,user = user )
  File "D:\Jafar\AAD\.env\lib\site-packages\rest_framework\serializers.py", line 212, in save
    self.instance = self.create(validated_data)
  File "D:\Jafar\AAD\healthworker\serializer.py", line 102, in create
    for key, value in familyMembers_details:
ValueError: too many values to unpack (expected 2)
[35;1mHTTP POST /healthworker/api/PostSurveyForm 500 [0.22, 127.0.0.1:51579][0m
Unauthorized: /healthworker/api/PostSurveyForm
[31;1mHTTP POST /healthworker/api/PostSurveyForm 401 [0.07, 127.0.0.1:51737][0m
Unauthorized: /allauth/api/login
[31;1mHTTP POST /allauth/api/login 401 [0.84, 127.0.0.1:51737][0m
Unauthorized: /allauth/api/login
[31;1mHTTP POST /allauth/api/login 401 [1.10, 127.0.0.1:51737][0m
Internal Server Error: /healthworker/api/PostSurveyForm
Traceback (most recent call last):
  File "D:\Jafar\AAD\.env\lib\site-packages\asgiref\sync.py", line 534, in thread_handler
    raise exc_info[1]
  File "D:\Jafar\AAD\.env\lib\site-packages\django\core\handlers\exception.py", line 42, in inner
    response = await get_response(request)
  File "D:\Jafar\AAD\.env\lib\site-packages\django\core\handlers\base.py", line 253, in _get_response_async
    response = await wrapped_callback(
  File "D:\Jafar\AAD\.env\lib\site-packages\asgiref\sync.py", line 479, in __call__
    ret: _R = await loop.run_in_executor(
  File "C:\Program Files\WindowsApps\PythonSoftwareFoundation.Python.3.10_3.10.3056.0_x64__qbz5n2kfra8p0\lib\concurrent\futures\thread.py", line 58, in run
    result = self.fn(*self.args, **self.kwargs)
  File "D:\Jafar\AAD\.env\lib\site-packages\asgiref\sync.py", line 538, in thread_handler
    return func(*args, **kwargs)
  File "D:\Jafar\AAD\.env\lib\site-packages\django\views\decorators\csrf.py", line 56, in wrapper_view
    return view_func(*args, **kwargs)
  File "D:\Jafar\AAD\.env\lib\site-packages\django\views\generic\base.py", line 104, in view
    return self.dispatch(request, *args, **kwargs)
  File "D:\Jafar\AAD\.env\lib\site-packages\rest_framework\views.py", line 509, in dispatch
    response = self.handle_exception(exc)
  File "D:\Jafar\AAD\.env\lib\site-packages\rest_framework\views.py", line 469, in handle_exception
    self.raise_uncaught_exception(exc)
  File "D:\Jafar\AAD\.env\lib\site-packages\rest_framework\views.py", line 480, in raise_uncaught_exception
    raise exc
  File "D:\Jafar\AAD\.env\lib\site-packages\rest_framework\views.py", line 506, in dispatch
    response = handler(request, *args, **kwargs)
  File "D:\Jafar\AAD\healthworker\views.py", line 106, in post
    serializer.save(location = location , familyId = familyId ,user = user )
  File "D:\Jafar\AAD\.env\lib\site-packages\rest_framework\serializers.py", line 212, in save
    self.instance = self.create(validated_data)
  File "D:\Jafar\AAD\healthworker\serializer.py", line 102, in create
    print(familyMembers_details)
NameError: name 'fami' is not defined
[35;1mHTTP POST /healthworker/api/PostSurveyForm 500 [0.23, 127.0.0.1:51737][0m
Internal Server Error: /healthworker/api/PostSurveyForm
Traceback (most recent call last):
  File "D:\Jafar\AAD\.env\lib\site-packages\asgiref\sync.py", line 534, in thread_handler
    raise exc_info[1]
  File "D:\Jafar\AAD\.env\lib\site-packages\django\core\handlers\exception.py", line 42, in inner
    response = await get_response(request)
  File "D:\Jafar\AAD\.env\lib\site-packages\django\core\handlers\base.py", line 253, in _get_response_async
    response = await wrapped_callback(
  File "D:\Jafar\AAD\.env\lib\site-packages\asgiref\sync.py", line 479, in __call__
    ret: _R = await loop.run_in_executor(
  File "C:\Program Files\WindowsApps\PythonSoftwareFoundation.Python.3.10_3.10.3056.0_x64__qbz5n2kfra8p0\lib\concurrent\futures\thread.py", line 58, in run
    result = self.fn(*self.args, **self.kwargs)
  File "D:\Jafar\AAD\.env\lib\site-packages\asgiref\sync.py", line 538, in thread_handler
    return func(*args, **kwargs)
  File "D:\Jafar\AAD\.env\lib\site-packages\django\views\decorators\csrf.py", line 56, in wrapper_view
    return view_func(*args, **kwargs)
  File "D:\Jafar\AAD\.env\lib\site-packages\django\views\generic\base.py", line 104, in view
    return self.dispatch(request, *args, **kwargs)
  File "D:\Jafar\AAD\.env\lib\site-packages\rest_framework\views.py", line 509, in dispatch
    response = self.handle_exception(exc)
  File "D:\Jafar\AAD\.env\lib\site-packages\rest_framework\views.py", line 469, in handle_exception
    self.raise_uncaught_exception(exc)
  File "D:\Jafar\AAD\.env\lib\site-packages\rest_framework\views.py", line 480, in raise_uncaught_exception
    raise exc
  File "D:\Jafar\AAD\.env\lib\site-packages\rest_framework\views.py", line 506, in dispatch
    response = handler(request, *args, **kwargs)
  File "D:\Jafar\AAD\healthworker\views.py", line 106, in post
    serializer.save(location = location , familyId = familyId ,user = user )
  File "D:\Jafar\AAD\.env\lib\site-packages\rest_framework\serializers.py", line 212, in save
    self.instance = self.create(validated_data)
  File "D:\Jafar\AAD\healthworker\serializer.py", line 112, in create
    familyMembers.objects.create(familyHead = head, familySurveyor = head.user, memberId = member_id , **family)
  File "D:\Jafar\AAD\.env\lib\site-packages\django\db\models\manager.py", line 87, in manager_method
    return getattr(self.get_queryset(), name)(*args, **kwargs)
  File "D:\Jafar\AAD\.env\lib\site-packages\django\db\models\query.py", line 656, in create
    obj = self.model(**kwargs)
  File "D:\Jafar\AAD\.env\lib\site-packages\django\db\models\base.py", line 564, in __init__
    _setattr(self, prop, value)
  File "D:\Jafar\AAD\.env\lib\site-packages\django\db\models\fields\related_descriptors.py", line 626, in __set__
    raise TypeError(
TypeError: Direct assignment to the forward side of a many-to-many set is prohibited. Use referels.set() instead.
[35;1mHTTP POST /healthworker/api/PostSurveyForm 500 [0.69, 127.0.0.1:51775][0m
Unauthorized: /healthworker/api/PostSurveyForm
[31;1mHTTP POST /healthworker/api/PostSurveyForm 401 [0.09, 127.0.0.1:52023][0m
Bad Request: /healthworker/api/PostSurveyForm
[31;1mHTTP POST /healthworker/api/PostSurveyForm 400 [0.12, 127.0.0.1:52023][0m
Internal Server Error: /healthworker/api/PostSurveyForm
Traceback (most recent call last):
  File "D:\Jafar\AAD\.env\lib\site-packages\asgiref\sync.py", line 534, in thread_handler
    raise exc_info[1]
  File "D:\Jafar\AAD\.env\lib\site-packages\django\core\handlers\exception.py", line 42, in inner
    response = await get_response(request)
  File "D:\Jafar\AAD\.env\lib\site-packages\django\core\handlers\base.py", line 253, in _get_response_async
    response = await wrapped_callback(
  File "D:\Jafar\AAD\.env\lib\site-packages\asgiref\sync.py", line 479, in __call__
    ret: _R = await loop.run_in_executor(
  File "C:\Program Files\WindowsApps\PythonSoftwareFoundation.Python.3.10_3.10.3056.0_x64__qbz5n2kfra8p0\lib\concurrent\futures\thread.py", line 58, in run
    result = self.fn(*self.args, **self.kwargs)
  File "D:\Jafar\AAD\.env\lib\site-packages\asgiref\sync.py", line 538, in thread_handler
    return func(*args, **kwargs)
  File "D:\Jafar\AAD\.env\lib\site-packages\django\views\decorators\csrf.py", line 56, in wrapper_view
    return view_func(*args, **kwargs)
  File "D:\Jafar\AAD\.env\lib\site-packages\django\views\generic\base.py", line 104, in view
    return self.dispatch(request, *args, **kwargs)
  File "D:\Jafar\AAD\.env\lib\site-packages\rest_framework\views.py", line 509, in dispatch
    response = self.handle_exception(exc)
  File "D:\Jafar\AAD\.env\lib\site-packages\rest_framework\views.py", line 469, in handle_exception
    self.raise_uncaught_exception(exc)
  File "D:\Jafar\AAD\.env\lib\site-packages\rest_framework\views.py", line 480, in raise_uncaught_exception
    raise exc
  File "D:\Jafar\AAD\.env\lib\site-packages\rest_framework\views.py", line 506, in dispatch
    response = handler(request, *args, **kwargs)
  File "D:\Jafar\AAD\healthworker\views.py", line 106, in post
    serializer.save(location = location , familyId = familyId ,user = user )
  File "D:\Jafar\AAD\.env\lib\site-packages\rest_framework\serializers.py", line 212, in save
    self.instance = self.create(validated_data)
  File "D:\Jafar\AAD\healthworker\serializer.py", line 103, in create
    for key, value in familyMembers_details[0]:
ValueError: too many values to unpack (expected 2)
[35;1mHTTP POST /healthworker/api/PostSurveyForm 500 [0.14, 127.0.0.1:52023][0m
Internal Server Error: /healthworker/api/PostSurveyForm
Traceback (most recent call last):
  File "D:\Jafar\AAD\.env\lib\site-packages\asgiref\sync.py", line 534, in thread_handler
    raise exc_info[1]
  File "D:\Jafar\AAD\.env\lib\site-packages\django\core\handlers\exception.py", line 42, in inner
    response = await get_response(request)
  File "D:\Jafar\AAD\.env\lib\site-packages\django\core\handlers\base.py", line 253, in _get_response_async
    response = await wrapped_callback(
  File "D:\Jafar\AAD\.env\lib\site-packages\asgiref\sync.py", line 479, in __call__
    ret: _R = await loop.run_in_executor(
  File "C:\Program Files\WindowsApps\PythonSoftwareFoundation.Python.3.10_3.10.3056.0_x64__qbz5n2kfra8p0\lib\concurrent\futures\thread.py", line 58, in run
    result = self.fn(*self.args, **self.kwargs)
  File "D:\Jafar\AAD\.env\lib\site-packages\asgiref\sync.py", line 538, in thread_handler
    return func(*args, **kwargs)
  File "D:\Jafar\AAD\.env\lib\site-packages\django\views\decorators\csrf.py", line 56, in wrapper_view
    return view_func(*args, **kwargs)
  File "D:\Jafar\AAD\.env\lib\site-packages\django\views\generic\base.py", line 104, in view
    return self.dispatch(request, *args, **kwargs)
  File "D:\Jafar\AAD\.env\lib\site-packages\rest_framework\views.py", line 509, in dispatch
    response = self.handle_exception(exc)
  File "D:\Jafar\AAD\.env\lib\site-packages\rest_framework\views.py", line 469, in handle_exception
    self.raise_uncaught_exception(exc)
  File "D:\Jafar\AAD\.env\lib\site-packages\rest_framework\views.py", line 480, in raise_uncaught_exception
    raise exc
  File "D:\Jafar\AAD\.env\lib\site-packages\rest_framework\views.py", line 506, in dispatch
    response = handler(request, *args, **kwargs)
  File "D:\Jafar\AAD\healthworker\views.py", line 106, in post
    serializer.save(location = location , familyId = familyId ,user = user )
  File "D:\Jafar\AAD\.env\lib\site-packages\rest_framework\serializers.py", line 212, in save
    self.instance = self.create(validated_data)
  File "D:\Jafar\AAD\healthworker\serializer.py", line 103, in create
    for key, value in familyMembers_details[0]:
ValueError: too many values to unpack (expected 2)
[35;1mHTTP POST /healthworker/api/PostSurveyForm 500 [0.22, 127.0.0.1:52023][0m
Internal Server Error: /healthworker/api/PostSurveyForm
Traceback (most recent call last):
  File "D:\Jafar\AAD\.env\lib\site-packages\asgiref\sync.py", line 534, in thread_handler
    raise exc_info[1]
  File "D:\Jafar\AAD\.env\lib\site-packages\django\core\handlers\exception.py", line 42, in inner
    response = await get_response(request)
  File "D:\Jafar\AAD\.env\lib\site-packages\django\core\handlers\base.py", line 253, in _get_response_async
    response = await wrapped_callback(
  File "D:\Jafar\AAD\.env\lib\site-packages\asgiref\sync.py", line 479, in __call__
    ret: _R = await loop.run_in_executor(
  File "C:\Program Files\WindowsApps\PythonSoftwareFoundation.Python.3.10_3.10.3056.0_x64__qbz5n2kfra8p0\lib\concurrent\futures\thread.py", line 58, in run
    result = self.fn(*self.args, **self.kwargs)
  File "D:\Jafar\AAD\.env\lib\site-packages\asgiref\sync.py", line 538, in thread_handler
    return func(*args, **kwargs)
  File "D:\Jafar\AAD\.env\lib\site-packages\django\views\decorators\csrf.py", line 56, in wrapper_view
    return view_func(*args, **kwargs)
  File "D:\Jafar\AAD\.env\lib\site-packages\django\views\generic\base.py", line 104, in view
    return self.dispatch(request, *args, **kwargs)
  File "D:\Jafar\AAD\.env\lib\site-packages\rest_framework\views.py", line 509, in dispatch
    response = self.handle_exception(exc)
  File "D:\Jafar\AAD\.env\lib\site-packages\rest_framework\views.py", line 469, in handle_exception
    self.raise_uncaught_exception(exc)
  File "D:\Jafar\AAD\.env\lib\site-packages\rest_framework\views.py", line 480, in raise_uncaught_exception
    raise exc
  File "D:\Jafar\AAD\.env\lib\site-packages\rest_framework\views.py", line 506, in dispatch
    response = handler(request, *args, **kwargs)
  File "D:\Jafar\AAD\healthworker\views.py", line 106, in post
    serializer.save(location = location , familyId = familyId ,user = user )
  File "D:\Jafar\AAD\.env\lib\site-packages\rest_framework\serializers.py", line 212, in save
    self.instance = self.create(validated_data)
  File "D:\Jafar\AAD\healthworker\serializer.py", line 103, in create
    for key, value in familyMembers_details[0]:
ValueError: too many values to unpack (expected 2)
[35;1mHTTP POST /healthworker/api/PostSurveyForm 500 [0.17, 127.0.0.1:52270][0m
Internal Server Error: /healthworker/api/PostSurveyForm
Traceback (most recent call last):
  File "D:\Jafar\AAD\.env\lib\site-packages\asgiref\sync.py", line 534, in thread_handler
    raise exc_info[1]
  File "D:\Jafar\AAD\.env\lib\site-packages\django\core\handlers\exception.py", line 42, in inner
    response = await get_response(request)
  File "D:\Jafar\AAD\.env\lib\site-packages\django\core\handlers\base.py", line 253, in _get_response_async
    response = await wrapped_callback(
  File "D:\Jafar\AAD\.env\lib\site-packages\asgiref\sync.py", line 479, in __call__
    ret: _R = await loop.run_in_executor(
  File "C:\Program Files\WindowsApps\PythonSoftwareFoundation.Python.3.10_3.10.3056.0_x64__qbz5n2kfra8p0\lib\concurrent\futures\thread.py", line 58, in run
    result = self.fn(*self.args, **self.kwargs)
  File "D:\Jafar\AAD\.env\lib\site-packages\asgiref\sync.py", line 538, in thread_handler
    return func(*args, **kwargs)
  File "D:\Jafar\AAD\.env\lib\site-packages\django\views\decorators\csrf.py", line 56, in wrapper_view
    return view_func(*args, **kwargs)
  File "D:\Jafar\AAD\.env\lib\site-packages\django\views\generic\base.py", line 104, in view
    return self.dispatch(request, *args, **kwargs)
  File "D:\Jafar\AAD\.env\lib\site-packages\rest_framework\views.py", line 509, in dispatch
    response = self.handle_exception(exc)
  File "D:\Jafar\AAD\.env\lib\site-packages\rest_framework\views.py", line 469, in handle_exception
    self.raise_uncaught_exception(exc)
  File "D:\Jafar\AAD\.env\lib\site-packages\rest_framework\views.py", line 480, in raise_uncaught_exception
    raise exc
  File "D:\Jafar\AAD\.env\lib\site-packages\rest_framework\views.py", line 506, in dispatch
    response = handler(request, *args, **kwargs)
  File "D:\Jafar\AAD\healthworker\views.py", line 106, in post
    serializer.save(location = location , familyId = familyId ,user = user )
  File "D:\Jafar\AAD\.env\lib\site-packages\rest_framework\serializers.py", line 212, in save
    self.instance = self.create(validated_data)
  File "D:\Jafar\AAD\healthworker\serializer.py", line 103, in create
    for key, value in familyMembers_details[0]:
ValueError: too many values to unpack (expected 2)
[35;1mHTTP POST /healthworker/api/PostSurveyForm 500 [0.20, 127.0.0.1:52328][0m
Internal Server Error: /healthworker/api/PostSurveyForm
Traceback (most recent call last):
  File "D:\Jafar\AAD\.env\lib\site-packages\asgiref\sync.py", line 534, in thread_handler
    raise exc_info[1]
  File "D:\Jafar\AAD\.env\lib\site-packages\django\core\handlers\exception.py", line 42, in inner
    response = await get_response(request)
  File "D:\Jafar\AAD\.env\lib\site-packages\django\core\handlers\base.py", line 253, in _get_response_async
    response = await wrapped_callback(
  File "D:\Jafar\AAD\.env\lib\site-packages\asgiref\sync.py", line 479, in __call__
    ret: _R = await loop.run_in_executor(
  File "C:\Program Files\WindowsApps\PythonSoftwareFoundation.Python.3.10_3.10.3056.0_x64__qbz5n2kfra8p0\lib\concurrent\futures\thread.py", line 58, in run
    result = self.fn(*self.args, **self.kwargs)
  File "D:\Jafar\AAD\.env\lib\site-packages\asgiref\sync.py", line 538, in thread_handler
    return func(*args, **kwargs)
  File "D:\Jafar\AAD\.env\lib\site-packages\django\views\decorators\csrf.py", line 56, in wrapper_view
    return view_func(*args, **kwargs)
  File "D:\Jafar\AAD\.env\lib\site-packages\django\views\generic\base.py", line 104, in view
    return self.dispatch(request, *args, **kwargs)
  File "D:\Jafar\AAD\.env\lib\site-packages\rest_framework\views.py", line 509, in dispatch
    response = self.handle_exception(exc)
  File "D:\Jafar\AAD\.env\lib\site-packages\rest_framework\views.py", line 469, in handle_exception
    self.raise_uncaught_exception(exc)
  File "D:\Jafar\AAD\.env\lib\site-packages\rest_framework\views.py", line 480, in raise_uncaught_exception
    raise exc
  File "D:\Jafar\AAD\.env\lib\site-packages\rest_framework\views.py", line 506, in dispatch
    response = handler(request, *args, **kwargs)
  File "D:\Jafar\AAD\healthworker\views.py", line 106, in post
    serializer.save(location = location , familyId = familyId ,user = user )
  File "D:\Jafar\AAD\.env\lib\site-packages\rest_framework\serializers.py", line 212, in save
    self.instance = self.create(validated_data)
  File "D:\Jafar\AAD\healthworker\serializer.py", line 111, in create
    familyMembers.objects.create(familyHead = head, familySurveyor = head.user, memberId = member_id , **family)
  File "D:\Jafar\AAD\.env\lib\site-packages\django\db\models\manager.py", line 87, in manager_method
    return getattr(self.get_queryset(), name)(*args, **kwargs)
  File "D:\Jafar\AAD\.env\lib\site-packages\django\db\models\query.py", line 656, in create
    obj = self.model(**kwargs)
  File "D:\Jafar\AAD\.env\lib\site-packages\django\db\models\base.py", line 564, in __init__
    _setattr(self, prop, value)
  File "D:\Jafar\AAD\.env\lib\site-packages\django\db\models\fields\related_descriptors.py", line 626, in __set__
    raise TypeError(
TypeError: Direct assignment to the forward side of a many-to-many set is prohibited. Use referels.set() instead.
[35;1mHTTP POST /healthworker/api/PostSurveyForm 500 [1.38, 127.0.0.1:52531][0m
Bad Request: /healthworker/api/PostSurveyForm
[31;1mHTTP POST /healthworker/api/PostSurveyForm 400 [0.14, 127.0.0.1:52633][0m
Internal Server Error: /healthworker/api/PostSurveyForm
Traceback (most recent call last):
  File "D:\Jafar\AAD\.env\lib\site-packages\asgiref\sync.py", line 534, in thread_handler
    raise exc_info[1]
  File "D:\Jafar\AAD\.env\lib\site-packages\django\core\handlers\exception.py", line 42, in inner
    response = await get_response(request)
  File "D:\Jafar\AAD\.env\lib\site-packages\django\core\handlers\base.py", line 253, in _get_response_async
    response = await wrapped_callback(
  File "D:\Jafar\AAD\.env\lib\site-packages\asgiref\sync.py", line 479, in __call__
    ret: _R = await loop.run_in_executor(
  File "C:\Program Files\WindowsApps\PythonSoftwareFoundation.Python.3.10_3.10.3056.0_x64__qbz5n2kfra8p0\lib\concurrent\futures\thread.py", line 58, in run
    result = self.fn(*self.args, **self.kwargs)
  File "D:\Jafar\AAD\.env\lib\site-packages\asgiref\sync.py", line 538, in thread_handler
    return func(*args, **kwargs)
  File "D:\Jafar\AAD\.env\lib\site-packages\django\views\decorators\csrf.py", line 56, in wrapper_view
    return view_func(*args, **kwargs)
  File "D:\Jafar\AAD\.env\lib\site-packages\django\views\generic\base.py", line 104, in view
    return self.dispatch(request, *args, **kwargs)
  File "D:\Jafar\AAD\.env\lib\site-packages\rest_framework\views.py", line 509, in dispatch
    response = self.handle_exception(exc)
  File "D:\Jafar\AAD\.env\lib\site-packages\rest_framework\views.py", line 469, in handle_exception
    self.raise_uncaught_exception(exc)
  File "D:\Jafar\AAD\.env\lib\site-packages\rest_framework\views.py", line 480, in raise_uncaught_exception
    raise exc
  File "D:\Jafar\AAD\.env\lib\site-packages\rest_framework\views.py", line 506, in dispatch
    response = handler(request, *args, **kwargs)
  File "D:\Jafar\AAD\healthworker\views.py", line 106, in post
    serializer.save(location = location , familyId = familyId ,user = user )
  File "D:\Jafar\AAD\.env\lib\site-packages\rest_framework\serializers.py", line 212, in save
    self.instance = self.create(validated_data)
  File "D:\Jafar\AAD\healthworker\serializer.py", line 105, in create
    print(ref.referels)
AttributeError: 'str' object has no attribute 'referels'
[35;1mHTTP POST /healthworker/api/PostSurveyForm 500 [0.19, 127.0.0.1:52633][0m
Internal Server Error: /healthworker/api/PostSurveyForm
Traceback (most recent call last):
  File "D:\Jafar\AAD\.env\lib\site-packages\asgiref\sync.py", line 534, in thread_handler
    raise exc_info[1]
  File "D:\Jafar\AAD\.env\lib\site-packages\django\core\handlers\exception.py", line 42, in inner
    response = await get_response(request)
  File "D:\Jafar\AAD\.env\lib\site-packages\django\core\handlers\base.py", line 253, in _get_response_async
    response = await wrapped_callback(
  File "D:\Jafar\AAD\.env\lib\site-packages\asgiref\sync.py", line 479, in __call__
    ret: _R = await loop.run_in_executor(
  File "C:\Program Files\WindowsApps\PythonSoftwareFoundation.Python.3.10_3.10.3056.0_x64__qbz5n2kfra8p0\lib\concurrent\futures\thread.py", line 58, in run
    result = self.fn(*self.args, **self.kwargs)
  File "D:\Jafar\AAD\.env\lib\site-packages\asgiref\sync.py", line 538, in thread_handler
    return func(*args, **kwargs)
  File "D:\Jafar\AAD\.env\lib\site-packages\django\views\decorators\csrf.py", line 56, in wrapper_view
    return view_func(*args, **kwargs)
  File "D:\Jafar\AAD\.env\lib\site-packages\django\views\generic\base.py", line 104, in view
    return self.dispatch(request, *args, **kwargs)
  File "D:\Jafar\AAD\.env\lib\site-packages\rest_framework\views.py", line 509, in dispatch
    response = self.handle_exception(exc)
  File "D:\Jafar\AAD\.env\lib\site-packages\rest_framework\views.py", line 469, in handle_exception
    self.raise_uncaught_exception(exc)
  File "D:\Jafar\AAD\.env\lib\site-packages\rest_framework\views.py", line 480, in raise_uncaught_exception
    raise exc
  File "D:\Jafar\AAD\.env\lib\site-packages\rest_framework\views.py", line 506, in dispatch
    response = handler(request, *args, **kwargs)
  File "D:\Jafar\AAD\healthworker\views.py", line 106, in post
    serializer.save(location = location , familyId = familyId ,user = user )
  File "D:\Jafar\AAD\.env\lib\site-packages\rest_framework\serializers.py", line 212, in save
    self.instance = self.create(validated_data)
  File "D:\Jafar\AAD\healthworker\serializer.py", line 112, in create
    familyMembers.objects.create(familyHead = head, familySurveyor = head.user, memberId = member_id , **family)
  File "D:\Jafar\AAD\.env\lib\site-packages\django\db\models\manager.py", line 87, in manager_method
    return getattr(self.get_queryset(), name)(*args, **kwargs)
  File "D:\Jafar\AAD\.env\lib\site-packages\django\db\models\query.py", line 656, in create
    obj = self.model(**kwargs)
  File "D:\Jafar\AAD\.env\lib\site-packages\django\db\models\base.py", line 564, in __init__
    _setattr(self, prop, value)
  File "D:\Jafar\AAD\.env\lib\site-packages\django\db\models\fields\related_descriptors.py", line 626, in __set__
    raise TypeError(
TypeError: Direct assignment to the forward side of a many-to-many set is prohibited. Use referels.set() instead.
[35;1mHTTP POST /healthworker/api/PostSurveyForm 500 [0.52, 127.0.0.1:52679][0m
Bad Request: /healthworker/api/PostSurveyForm
[31;1mHTTP POST /healthworker/api/PostSurveyForm 400 [0.13, 127.0.0.1:52719][0m
Internal Server Error: /healthworker/api/PostSurveyForm
Traceback (most recent call last):
  File "D:\Jafar\AAD\.env\lib\site-packages\asgiref\sync.py", line 534, in thread_handler
    raise exc_info[1]
  File "D:\Jafar\AAD\.env\lib\site-packages\django\core\handlers\exception.py", line 42, in inner
    response = await get_response(request)
  File "D:\Jafar\AAD\.env\lib\site-packages\django\core\handlers\base.py", line 253, in _get_response_async
    response = await wrapped_callback(
  File "D:\Jafar\AAD\.env\lib\site-packages\asgiref\sync.py", line 479, in __call__
    ret: _R = await loop.run_in_executor(
  File "C:\Program Files\WindowsApps\PythonSoftwareFoundation.Python.3.10_3.10.3056.0_x64__qbz5n2kfra8p0\lib\concurrent\futures\thread.py", line 58, in run
    result = self.fn(*self.args, **self.kwargs)
  File "D:\Jafar\AAD\.env\lib\site-packages\asgiref\sync.py", line 538, in thread_handler
    return func(*args, **kwargs)
  File "D:\Jafar\AAD\.env\lib\site-packages\django\views\decorators\csrf.py", line 56, in wrapper_view
    return view_func(*args, **kwargs)
  File "D:\Jafar\AAD\.env\lib\site-packages\django\views\generic\base.py", line 104, in view
    return self.dispatch(request, *args, **kwargs)
  File "D:\Jafar\AAD\.env\lib\site-packages\rest_framework\views.py", line 509, in dispatch
    response = self.handle_exception(exc)
  File "D:\Jafar\AAD\.env\lib\site-packages\rest_framework\views.py", line 469, in handle_exception
    self.raise_uncaught_exception(exc)
  File "D:\Jafar\AAD\.env\lib\site-packages\rest_framework\views.py", line 480, in raise_uncaught_exception
    raise exc
  File "D:\Jafar\AAD\.env\lib\site-packages\rest_framework\views.py", line 506, in dispatch
    response = handler(request, *args, **kwargs)
  File "D:\Jafar\AAD\healthworker\views.py", line 106, in post
    serializer.save(location = location , familyId = familyId ,user = user )
  File "D:\Jafar\AAD\.env\lib\site-packages\rest_framework\serializers.py", line 212, in save
    self.instance = self.create(validated_data)
  File "D:\Jafar\AAD\healthworker\serializer.py", line 105, in create
    print(ref['referels'])
TypeError: string indices must be integers
[35;1mHTTP POST /healthworker/api/PostSurveyForm 500 [0.15, 127.0.0.1:52719][0m
Internal Server Error: /healthworker/api/PostSurveyForm
Traceback (most recent call last):
  File "D:\Jafar\AAD\.env\lib\site-packages\asgiref\sync.py", line 534, in thread_handler
    raise exc_info[1]
  File "D:\Jafar\AAD\.env\lib\site-packages\django\core\handlers\exception.py", line 42, in inner
    response = await get_response(request)
  File "D:\Jafar\AAD\.env\lib\site-packages\django\core\handlers\base.py", line 253, in _get_response_async
    response = await wrapped_callback(
  File "D:\Jafar\AAD\.env\lib\site-packages\asgiref\sync.py", line 479, in __call__
    ret: _R = await loop.run_in_executor(
  File "C:\Program Files\WindowsApps\PythonSoftwareFoundation.Python.3.10_3.10.3056.0_x64__qbz5n2kfra8p0\lib\concurrent\futures\thread.py", line 58, in run
    result = self.fn(*self.args, **self.kwargs)
  File "D:\Jafar\AAD\.env\lib\site-packages\asgiref\sync.py", line 538, in thread_handler
    return func(*args, **kwargs)
  File "D:\Jafar\AAD\.env\lib\site-packages\django\views\decorators\csrf.py", line 56, in wrapper_view
    return view_func(*args, **kwargs)
  File "D:\Jafar\AAD\.env\lib\site-packages\django\views\generic\base.py", line 104, in view
    return self.dispatch(request, *args, **kwargs)
  File "D:\Jafar\AAD\.env\lib\site-packages\rest_framework\views.py", line 509, in dispatch
    response = self.handle_exception(exc)
  File "D:\Jafar\AAD\.env\lib\site-packages\rest_framework\views.py", line 469, in handle_exception
    self.raise_uncaught_exception(exc)
  File "D:\Jafar\AAD\.env\lib\site-packages\rest_framework\views.py", line 480, in raise_uncaught_exception
    raise exc
  File "D:\Jafar\AAD\.env\lib\site-packages\rest_framework\views.py", line 506, in dispatch
    response = handler(request, *args, **kwargs)
  File "D:\Jafar\AAD\healthworker\views.py", line 106, in post
    serializer.save(location = location , familyId = familyId ,user = user )
  File "D:\Jafar\AAD\.env\lib\site-packages\rest_framework\serializers.py", line 212, in save
    self.instance = self.create(validated_data)
  File "D:\Jafar\AAD\healthworker\serializer.py", line 105, in create
    print(ref.referels)
AttributeError: 'str' object has no attribute 'referels'
[35;1mHTTP POST /healthworker/api/PostSurveyForm 500 [0.21, 127.0.0.1:52768][0m
Internal Server Error: /healthworker/api/PostSurveyForm
Traceback (most recent call last):
  File "D:\Jafar\AAD\.env\lib\site-packages\asgiref\sync.py", line 534, in thread_handler
    raise exc_info[1]
  File "D:\Jafar\AAD\.env\lib\site-packages\django\core\handlers\exception.py", line 42, in inner
    response = await get_response(request)
  File "D:\Jafar\AAD\.env\lib\site-packages\django\core\handlers\base.py", line 253, in _get_response_async
    response = await wrapped_callback(
  File "D:\Jafar\AAD\.env\lib\site-packages\asgiref\sync.py", line 479, in __call__
    ret: _R = await loop.run_in_executor(
  File "C:\Program Files\WindowsApps\PythonSoftwareFoundation.Python.3.10_3.10.3056.0_x64__qbz5n2kfra8p0\lib\concurrent\futures\thread.py", line 58, in run
    result = self.fn(*self.args, **self.kwargs)
  File "D:\Jafar\AAD\.env\lib\site-packages\asgiref\sync.py", line 538, in thread_handler
    return func(*args, **kwargs)
  File "D:\Jafar\AAD\.env\lib\site-packages\django\views\decorators\csrf.py", line 56, in wrapper_view
    return view_func(*args, **kwargs)
  File "D:\Jafar\AAD\.env\lib\site-packages\django\views\generic\base.py", line 104, in view
    return self.dispatch(request, *args, **kwargs)
  File "D:\Jafar\AAD\.env\lib\site-packages\rest_framework\views.py", line 509, in dispatch
    response = self.handle_exception(exc)
  File "D:\Jafar\AAD\.env\lib\site-packages\rest_framework\views.py", line 469, in handle_exception
    self.raise_uncaught_exception(exc)
  File "D:\Jafar\AAD\.env\lib\site-packages\rest_framework\views.py", line 480, in raise_uncaught_exception
    raise exc
  File "D:\Jafar\AAD\.env\lib\site-packages\rest_framework\views.py", line 506, in dispatch
    response = handler(request, *args, **kwargs)
  File "D:\Jafar\AAD\healthworker\views.py", line 106, in post
    serializer.save(location = location , familyId = familyId ,user = user )
  File "D:\Jafar\AAD\.env\lib\site-packages\rest_framework\serializers.py", line 212, in save
    self.instance = self.create(validated_data)
  File "D:\Jafar\AAD\healthworker\serializer.py", line 112, in create
    familyMembers.objects.create(familyHead = head, familySurveyor = head.user, memberId = member_id , **family)
  File "D:\Jafar\AAD\.env\lib\site-packages\django\db\models\manager.py", line 87, in manager_method
    return getattr(self.get_queryset(), name)(*args, **kwargs)
  File "D:\Jafar\AAD\.env\lib\site-packages\django\db\models\query.py", line 656, in create
    obj = self.model(**kwargs)
  File "D:\Jafar\AAD\.env\lib\site-packages\django\db\models\base.py", line 564, in __init__
    _setattr(self, prop, value)
  File "D:\Jafar\AAD\.env\lib\site-packages\django\db\models\fields\related_descriptors.py", line 626, in __set__
    raise TypeError(
TypeError: Direct assignment to the forward side of a many-to-many set is prohibited. Use referels.set() instead.
[35;1mHTTP POST /healthworker/api/PostSurveyForm 500 [0.69, 127.0.0.1:53164][0m
Unauthorized: /healthworker/api/PostSurveyForm
[31;1mHTTP POST /healthworker/api/PostSurveyForm 401 [0.11, 127.0.0.1:53260][0m
Bad Request: /healthworker/api/PostSurveyForm
[31;1mHTTP POST /healthworker/api/PostSurveyForm 400 [0.20, 127.0.0.1:53318][0m
Bad Request: /healthworker/api/PostSurveyForm
[31;1mHTTP POST /healthworker/api/PostSurveyForm 400 [0.16, 127.0.0.1:53318][0m
Internal Server Error: /healthworker/api/PostSurveyForm
Traceback (most recent call last):
  File "D:\Jafar\AAD\.env\lib\site-packages\asgiref\sync.py", line 534, in thread_handler
    raise exc_info[1]
  File "D:\Jafar\AAD\.env\lib\site-packages\django\core\handlers\exception.py", line 42, in inner
    response = await get_response(request)
  File "D:\Jafar\AAD\.env\lib\site-packages\django\core\handlers\base.py", line 253, in _get_response_async
    response = await wrapped_callback(
  File "D:\Jafar\AAD\.env\lib\site-packages\asgiref\sync.py", line 479, in __call__
    ret: _R = await loop.run_in_executor(
  File "C:\Program Files\WindowsApps\PythonSoftwareFoundation.Python.3.10_3.10.3056.0_x64__qbz5n2kfra8p0\lib\concurrent\futures\thread.py", line 58, in run
    result = self.fn(*self.args, **self.kwargs)
  File "D:\Jafar\AAD\.env\lib\site-packages\asgiref\sync.py", line 538, in thread_handler
    return func(*args, **kwargs)
  File "D:\Jafar\AAD\.env\lib\site-packages\django\views\decorators\csrf.py", line 56, in wrapper_view
    return view_func(*args, **kwargs)
  File "D:\Jafar\AAD\.env\lib\site-packages\django\views\generic\base.py", line 104, in view
    return self.dispatch(request, *args, **kwargs)
  File "D:\Jafar\AAD\.env\lib\site-packages\rest_framework\views.py", line 509, in dispatch
    response = self.handle_exception(exc)
  File "D:\Jafar\AAD\.env\lib\site-packages\rest_framework\views.py", line 469, in handle_exception
    self.raise_uncaught_exception(exc)
  File "D:\Jafar\AAD\.env\lib\site-packages\rest_framework\views.py", line 480, in raise_uncaught_exception
    raise exc
  File "D:\Jafar\AAD\.env\lib\site-packages\rest_framework\views.py", line 506, in dispatch
    response = handler(request, *args, **kwargs)
  File "D:\Jafar\AAD\healthworker\views.py", line 106, in post
    serializer.save(location = location , familyId = familyId ,user = user )
  File "D:\Jafar\AAD\.env\lib\site-packages\rest_framework\serializers.py", line 212, in save
    self.instance = self.create(validated_data)
  File "D:\Jafar\AAD\healthworker\serializer.py", line 113, in create
    familyMembers.objects.create(familyHead = head, familySurveyor = head.user, memberId = member_id , **family)
  File "D:\Jafar\AAD\.env\lib\site-packages\django\db\models\manager.py", line 87, in manager_method
    return getattr(self.get_queryset(), name)(*args, **kwargs)
  File "D:\Jafar\AAD\.env\lib\site-packages\django\db\models\query.py", line 656, in create
    obj = self.model(**kwargs)
  File "D:\Jafar\AAD\.env\lib\site-packages\django\db\models\base.py", line 564, in __init__
    _setattr(self, prop, value)
  File "D:\Jafar\AAD\.env\lib\site-packages\django\db\models\fields\related_descriptors.py", line 626, in __set__
    raise TypeError(
TypeError: Direct assignment to the forward side of a many-to-many set is prohibited. Use referels.set() instead.
[35;1mHTTP POST /healthworker/api/PostSurveyForm 500 [1.17, 127.0.0.1:53318][0m
Internal Server Error: /healthworker/api/PostSurveyForm
Traceback (most recent call last):
  File "D:\Jafar\AAD\.env\lib\site-packages\asgiref\sync.py", line 534, in thread_handler
    raise exc_info[1]
  File "D:\Jafar\AAD\.env\lib\site-packages\django\core\handlers\exception.py", line 42, in inner
    response = await get_response(request)
  File "D:\Jafar\AAD\.env\lib\site-packages\django\core\handlers\base.py", line 253, in _get_response_async
    response = await wrapped_callback(
  File "D:\Jafar\AAD\.env\lib\site-packages\asgiref\sync.py", line 479, in __call__
    ret: _R = await loop.run_in_executor(
  File "C:\Program Files\WindowsApps\PythonSoftwareFoundation.Python.3.10_3.10.3056.0_x64__qbz5n2kfra8p0\lib\concurrent\futures\thread.py", line 58, in run
    result = self.fn(*self.args, **self.kwargs)
  File "D:\Jafar\AAD\.env\lib\site-packages\asgiref\sync.py", line 538, in thread_handler
    return func(*args, **kwargs)
  File "D:\Jafar\AAD\.env\lib\site-packages\django\views\decorators\csrf.py", line 56, in wrapper_view
    return view_func(*args, **kwargs)
  File "D:\Jafar\AAD\.env\lib\site-packages\django\views\generic\base.py", line 104, in view
    return self.dispatch(request, *args, **kwargs)
  File "D:\Jafar\AAD\.env\lib\site-packages\rest_framework\views.py", line 509, in dispatch
    response = self.handle_exception(exc)
  File "D:\Jafar\AAD\.env\lib\site-packages\rest_framework\views.py", line 469, in handle_exception
    self.raise_uncaught_exception(exc)
  File "D:\Jafar\AAD\.env\lib\site-packages\rest_framework\views.py", line 480, in raise_uncaught_exception
    raise exc
  File "D:\Jafar\AAD\.env\lib\site-packages\rest_framework\views.py", line 506, in dispatch
    response = handler(request, *args, **kwargs)
  File "D:\Jafar\AAD\healthworker\views.py", line 106, in post
    serializer.save(location = location , familyId = familyId ,user = user )
  File "D:\Jafar\AAD\.env\lib\site-packages\rest_framework\serializers.py", line 212, in save
    self.instance = self.create(validated_data)
  File "D:\Jafar\AAD\healthworker\serializer.py", line 113, in create
    familyMembers.objects.create(familyHead = head, familySurveyor = head.user, memberId = member_id , **family)
  File "D:\Jafar\AAD\.env\lib\site-packages\django\db\models\manager.py", line 87, in manager_method
    return getattr(self.get_queryset(), name)(*args, **kwargs)
  File "D:\Jafar\AAD\.env\lib\site-packages\django\db\models\query.py", line 656, in create
    obj = self.model(**kwargs)
  File "D:\Jafar\AAD\.env\lib\site-packages\django\db\models\base.py", line 564, in __init__
    _setattr(self, prop, value)
  File "D:\Jafar\AAD\.env\lib\site-packages\django\db\models\fields\related_descriptors.py", line 626, in __set__
    raise TypeError(
TypeError: Direct assignment to the forward side of a many-to-many set is prohibited. Use referels.set() instead.
[35;1mHTTP POST /healthworker/api/PostSurveyForm 500 [0.95, 127.0.0.1:53318][0m
Bad Request: /healthworker/api/PostSurveyForm
[31;1mHTTP POST /healthworker/api/PostSurveyForm 400 [0.16, 127.0.0.1:53411][0m
Internal Server Error: /healthworker/api/PostSurveyForm
Traceback (most recent call last):
  File "D:\Jafar\AAD\.env\lib\site-packages\asgiref\sync.py", line 534, in thread_handler
    raise exc_info[1]
  File "D:\Jafar\AAD\.env\lib\site-packages\django\core\handlers\exception.py", line 42, in inner
    response = await get_response(request)
  File "D:\Jafar\AAD\.env\lib\site-packages\django\core\handlers\base.py", line 253, in _get_response_async
    response = await wrapped_callback(
  File "D:\Jafar\AAD\.env\lib\site-packages\asgiref\sync.py", line 479, in __call__
    ret: _R = await loop.run_in_executor(
  File "C:\Program Files\WindowsApps\PythonSoftwareFoundation.Python.3.10_3.10.3056.0_x64__qbz5n2kfra8p0\lib\concurrent\futures\thread.py", line 58, in run
    result = self.fn(*self.args, **self.kwargs)
  File "D:\Jafar\AAD\.env\lib\site-packages\asgiref\sync.py", line 538, in thread_handler
    return func(*args, **kwargs)
  File "D:\Jafar\AAD\.env\lib\site-packages\django\views\decorators\csrf.py", line 56, in wrapper_view
    return view_func(*args, **kwargs)
  File "D:\Jafar\AAD\.env\lib\site-packages\django\views\generic\base.py", line 104, in view
    return self.dispatch(request, *args, **kwargs)
  File "D:\Jafar\AAD\.env\lib\site-packages\rest_framework\views.py", line 509, in dispatch
    response = self.handle_exception(exc)
  File "D:\Jafar\AAD\.env\lib\site-packages\rest_framework\views.py", line 469, in handle_exception
    self.raise_uncaught_exception(exc)
  File "D:\Jafar\AAD\.env\lib\site-packages\rest_framework\views.py", line 480, in raise_uncaught_exception
    raise exc
  File "D:\Jafar\AAD\.env\lib\site-packages\rest_framework\views.py", line 506, in dispatch
    response = handler(request, *args, **kwargs)
  File "D:\Jafar\AAD\healthworker\views.py", line 106, in post
    serializer.save(location = location , familyId = familyId ,user = user )
  File "D:\Jafar\AAD\.env\lib\site-packages\rest_framework\serializers.py", line 212, in save
    self.instance = self.create(validated_data)
  File "D:\Jafar\AAD\healthworker\serializer.py", line 113, in create
    familyMembers.objects.create(familyHead = head, familySurveyor = head.user, memberId = member_id , **family)
  File "D:\Jafar\AAD\.env\lib\site-packages\django\db\models\manager.py", line 87, in manager_method
    return getattr(self.get_queryset(), name)(*args, **kwargs)
  File "D:\Jafar\AAD\.env\lib\site-packages\django\db\models\query.py", line 656, in create
    obj = self.model(**kwargs)
  File "D:\Jafar\AAD\.env\lib\site-packages\django\db\models\base.py", line 564, in __init__
    _setattr(self, prop, value)
  File "D:\Jafar\AAD\.env\lib\site-packages\django\db\models\fields\related_descriptors.py", line 626, in __set__
    raise TypeError(
TypeError: Direct assignment to the forward side of a many-to-many set is prohibited. Use referels.set() instead.
[35;1mHTTP POST /healthworker/api/PostSurveyForm 500 [1.18, 127.0.0.1:53411][0m
Bad Request: /healthworker/api/PostSurveyForm
[31;1mHTTP POST /healthworker/api/PostSurveyForm 400 [0.23, 127.0.0.1:53501][0m
Internal Server Error: /healthworker/api/PostSurveyForm
Traceback (most recent call last):
  File "D:\Jafar\AAD\.env\lib\site-packages\asgiref\sync.py", line 534, in thread_handler
    raise exc_info[1]
  File "D:\Jafar\AAD\.env\lib\site-packages\django\core\handlers\exception.py", line 42, in inner
    response = await get_response(request)
  File "D:\Jafar\AAD\.env\lib\site-packages\django\core\handlers\base.py", line 253, in _get_response_async
    response = await wrapped_callback(
  File "D:\Jafar\AAD\.env\lib\site-packages\asgiref\sync.py", line 479, in __call__
    ret: _R = await loop.run_in_executor(
  File "C:\Program Files\WindowsApps\PythonSoftwareFoundation.Python.3.10_3.10.3056.0_x64__qbz5n2kfra8p0\lib\concurrent\futures\thread.py", line 58, in run
    result = self.fn(*self.args, **self.kwargs)
  File "D:\Jafar\AAD\.env\lib\site-packages\asgiref\sync.py", line 538, in thread_handler
    return func(*args, **kwargs)
  File "D:\Jafar\AAD\.env\lib\site-packages\django\views\decorators\csrf.py", line 56, in wrapper_view
    return view_func(*args, **kwargs)
  File "D:\Jafar\AAD\.env\lib\site-packages\django\views\generic\base.py", line 104, in view
    return self.dispatch(request, *args, **kwargs)
  File "D:\Jafar\AAD\.env\lib\site-packages\rest_framework\views.py", line 509, in dispatch
    response = self.handle_exception(exc)
  File "D:\Jafar\AAD\.env\lib\site-packages\rest_framework\views.py", line 469, in handle_exception
    self.raise_uncaught_exception(exc)
  File "D:\Jafar\AAD\.env\lib\site-packages\rest_framework\views.py", line 480, in raise_uncaught_exception
    raise exc
  File "D:\Jafar\AAD\.env\lib\site-packages\rest_framework\views.py", line 506, in dispatch
    response = handler(request, *args, **kwargs)
  File "D:\Jafar\AAD\healthworker\views.py", line 106, in post
    serializer.save(location = location , familyId = familyId ,user = user )
  File "D:\Jafar\AAD\.env\lib\site-packages\rest_framework\serializers.py", line 212, in save
    self.instance = self.create(validated_data)
  File "D:\Jafar\AAD\healthworker\serializer.py", line 113, in create
    familyMembers.objects.create(familyHead = head, familySurveyor = head.user, memberId = member_id , **family)
  File "D:\Jafar\AAD\.env\lib\site-packages\django\db\models\manager.py", line 87, in manager_method
    return getattr(self.get_queryset(), name)(*args, **kwargs)
  File "D:\Jafar\AAD\.env\lib\site-packages\django\db\models\query.py", line 656, in create
    obj = self.model(**kwargs)
  File "D:\Jafar\AAD\.env\lib\site-packages\django\db\models\base.py", line 564, in __init__
    _setattr(self, prop, value)
  File "D:\Jafar\AAD\.env\lib\site-packages\django\db\models\fields\related_descriptors.py", line 626, in __set__
    raise TypeError(
TypeError: Direct assignment to the forward side of a many-to-many set is prohibited. Use referels.set() instead.
[35;1mHTTP POST /healthworker/api/PostSurveyForm 500 [0.82, 127.0.0.1:53501][0m
Internal Server Error: /healthworker/api/PostSurveyForm
Traceback (most recent call last):
  File "D:\Jafar\AAD\.env\lib\site-packages\asgiref\sync.py", line 534, in thread_handler
    raise exc_info[1]
  File "D:\Jafar\AAD\.env\lib\site-packages\django\core\handlers\exception.py", line 42, in inner
    response = await get_response(request)
  File "D:\Jafar\AAD\.env\lib\site-packages\django\core\handlers\base.py", line 253, in _get_response_async
    response = await wrapped_callback(
  File "D:\Jafar\AAD\.env\lib\site-packages\asgiref\sync.py", line 479, in __call__
    ret: _R = await loop.run_in_executor(
  File "C:\Program Files\WindowsApps\PythonSoftwareFoundation.Python.3.10_3.10.3056.0_x64__qbz5n2kfra8p0\lib\concurrent\futures\thread.py", line 58, in run
    result = self.fn(*self.args, **self.kwargs)
  File "D:\Jafar\AAD\.env\lib\site-packages\asgiref\sync.py", line 538, in thread_handler
    return func(*args, **kwargs)
  File "D:\Jafar\AAD\.env\lib\site-packages\django\views\decorators\csrf.py", line 56, in wrapper_view
    return view_func(*args, **kwargs)
  File "D:\Jafar\AAD\.env\lib\site-packages\django\views\generic\base.py", line 104, in view
    return self.dispatch(request, *args, **kwargs)
  File "D:\Jafar\AAD\.env\lib\site-packages\rest_framework\views.py", line 509, in dispatch
    response = self.handle_exception(exc)
  File "D:\Jafar\AAD\.env\lib\site-packages\rest_framework\views.py", line 469, in handle_exception
    self.raise_uncaught_exception(exc)
  File "D:\Jafar\AAD\.env\lib\site-packages\rest_framework\views.py", line 480, in raise_uncaught_exception
    raise exc
  File "D:\Jafar\AAD\.env\lib\site-packages\rest_framework\views.py", line 506, in dispatch
    response = handler(request, *args, **kwargs)
  File "D:\Jafar\AAD\healthworker\views.py", line 106, in post
    serializer.save(location = location , familyId = familyId ,user = user )
  File "D:\Jafar\AAD\.env\lib\site-packages\rest_framework\serializers.py", line 212, in save
    self.instance = self.create(validated_data)
  File "D:\Jafar\AAD\healthworker\serializer.py", line 113, in create
    familyMembers.objects.create(familyHead = head, familySurveyor = head.user, memberId = member_id , **family)
  File "D:\Jafar\AAD\.env\lib\site-packages\django\db\models\manager.py", line 87, in manager_method
    return getattr(self.get_queryset(), name)(*args, **kwargs)
  File "D:\Jafar\AAD\.env\lib\site-packages\django\db\models\query.py", line 656, in create
    obj = self.model(**kwargs)
  File "D:\Jafar\AAD\.env\lib\site-packages\django\db\models\base.py", line 564, in __init__
    _setattr(self, prop, value)
  File "D:\Jafar\AAD\.env\lib\site-packages\django\db\models\fields\related_descriptors.py", line 626, in __set__
    raise TypeError(
TypeError: Direct assignment to the forward side of a many-to-many set is prohibited. Use referels.set() instead.
[35;1mHTTP POST /healthworker/api/PostSurveyForm 500 [0.60, 127.0.0.1:53604][0m
Bad Request: /healthworker/api/PostSurveyForm
[31;1mHTTP POST /healthworker/api/PostSurveyForm 400 [0.18, 127.0.0.1:53685][0m
Internal Server Error: /healthworker/api/PostSurveyForm
Traceback (most recent call last):
  File "D:\Jafar\AAD\.env\lib\site-packages\asgiref\sync.py", line 534, in thread_handler
    raise exc_info[1]
  File "D:\Jafar\AAD\.env\lib\site-packages\django\core\handlers\exception.py", line 42, in inner
    response = await get_response(request)
  File "D:\Jafar\AAD\.env\lib\site-packages\django\core\handlers\base.py", line 253, in _get_response_async
    response = await wrapped_callback(
  File "D:\Jafar\AAD\.env\lib\site-packages\asgiref\sync.py", line 479, in __call__
    ret: _R = await loop.run_in_executor(
  File "C:\Program Files\WindowsApps\PythonSoftwareFoundation.Python.3.10_3.10.3056.0_x64__qbz5n2kfra8p0\lib\concurrent\futures\thread.py", line 58, in run
    result = self.fn(*self.args, **self.kwargs)
  File "D:\Jafar\AAD\.env\lib\site-packages\asgiref\sync.py", line 538, in thread_handler
    return func(*args, **kwargs)
  File "D:\Jafar\AAD\.env\lib\site-packages\django\views\decorators\csrf.py", line 56, in wrapper_view
    return view_func(*args, **kwargs)
  File "D:\Jafar\AAD\.env\lib\site-packages\django\views\generic\base.py", line 104, in view
    return self.dispatch(request, *args, **kwargs)
  File "D:\Jafar\AAD\.env\lib\site-packages\rest_framework\views.py", line 509, in dispatch
    response = self.handle_exception(exc)
  File "D:\Jafar\AAD\.env\lib\site-packages\rest_framework\views.py", line 469, in handle_exception
    self.raise_uncaught_exception(exc)
  File "D:\Jafar\AAD\.env\lib\site-packages\rest_framework\views.py", line 480, in raise_uncaught_exception
    raise exc
  File "D:\Jafar\AAD\.env\lib\site-packages\rest_framework\views.py", line 506, in dispatch
    response = handler(request, *args, **kwargs)
  File "D:\Jafar\AAD\healthworker\views.py", line 106, in post
    serializer.save(location = location , familyId = familyId ,user = user )
  File "D:\Jafar\AAD\.env\lib\site-packages\rest_framework\serializers.py", line 212, in save
    self.instance = self.create(validated_data)
  File "D:\Jafar\AAD\healthworker\serializer.py", line 114, in create
    familyMembers.objects.create(familyHead = head, familySurveyor = head.user, memberId = member_id , **family)
  File "D:\Jafar\AAD\.env\lib\site-packages\django\db\models\manager.py", line 87, in manager_method
    return getattr(self.get_queryset(), name)(*args, **kwargs)
  File "D:\Jafar\AAD\.env\lib\site-packages\django\db\models\query.py", line 656, in create
    obj = self.model(**kwargs)
  File "D:\Jafar\AAD\.env\lib\site-packages\django\db\models\base.py", line 564, in __init__
    _setattr(self, prop, value)
  File "D:\Jafar\AAD\.env\lib\site-packages\django\db\models\fields\related_descriptors.py", line 626, in __set__
    raise TypeError(
TypeError: Direct assignment to the forward side of a many-to-many set is prohibited. Use referels.set() instead.
[35;1mHTTP POST /healthworker/api/PostSurveyForm 500 [1.22, 127.0.0.1:53685][0m
Bad Request: /healthworker/api/PostSurveyForm
[31;1mHTTP POST /healthworker/api/PostSurveyForm 400 [0.21, 127.0.0.1:53811][0m
Internal Server Error: /healthworker/api/PostSurveyForm
Traceback (most recent call last):
  File "D:\Jafar\AAD\.env\lib\site-packages\asgiref\sync.py", line 534, in thread_handler
    raise exc_info[1]
  File "D:\Jafar\AAD\.env\lib\site-packages\django\core\handlers\exception.py", line 42, in inner
    response = await get_response(request)
  File "D:\Jafar\AAD\.env\lib\site-packages\django\core\handlers\base.py", line 253, in _get_response_async
    response = await wrapped_callback(
  File "D:\Jafar\AAD\.env\lib\site-packages\asgiref\sync.py", line 479, in __call__
    ret: _R = await loop.run_in_executor(
  File "C:\Program Files\WindowsApps\PythonSoftwareFoundation.Python.3.10_3.10.3056.0_x64__qbz5n2kfra8p0\lib\concurrent\futures\thread.py", line 58, in run
    result = self.fn(*self.args, **self.kwargs)
  File "D:\Jafar\AAD\.env\lib\site-packages\asgiref\sync.py", line 538, in thread_handler
    return func(*args, **kwargs)
  File "D:\Jafar\AAD\.env\lib\site-packages\django\views\decorators\csrf.py", line 56, in wrapper_view
    return view_func(*args, **kwargs)
  File "D:\Jafar\AAD\.env\lib\site-packages\django\views\generic\base.py", line 104, in view
    return self.dispatch(request, *args, **kwargs)
  File "D:\Jafar\AAD\.env\lib\site-packages\rest_framework\views.py", line 509, in dispatch
    response = self.handle_exception(exc)
  File "D:\Jafar\AAD\.env\lib\site-packages\rest_framework\views.py", line 469, in handle_exception
    self.raise_uncaught_exception(exc)
  File "D:\Jafar\AAD\.env\lib\site-packages\rest_framework\views.py", line 480, in raise_uncaught_exception
    raise exc
  File "D:\Jafar\AAD\.env\lib\site-packages\rest_framework\views.py", line 506, in dispatch
    response = handler(request, *args, **kwargs)
  File "D:\Jafar\AAD\healthworker\views.py", line 106, in post
    serializer.save(location = location , familyId = familyId ,user = user )
  File "D:\Jafar\AAD\.env\lib\site-packages\rest_framework\serializers.py", line 212, in save
    self.instance = self.create(validated_data)
  File "D:\Jafar\AAD\healthworker\serializer.py", line 114, in create
    instance = familyMembers.objects.create(familyHead = head, familySurveyor = head.user, memberId = member_id , **family)
  File "D:\Jafar\AAD\.env\lib\site-packages\django\db\models\manager.py", line 87, in manager_method
    return getattr(self.get_queryset(), name)(*args, **kwargs)
  File "D:\Jafar\AAD\.env\lib\site-packages\django\db\models\query.py", line 656, in create
    obj = self.model(**kwargs)
  File "D:\Jafar\AAD\.env\lib\site-packages\django\db\models\base.py", line 564, in __init__
    _setattr(self, prop, value)
  File "D:\Jafar\AAD\.env\lib\site-packages\django\db\models\fields\related_descriptors.py", line 626, in __set__
    raise TypeError(
TypeError: Direct assignment to the forward side of a many-to-many set is prohibited. Use referels.set() instead.
[35;1mHTTP POST /healthworker/api/PostSurveyForm 500 [0.61, 127.0.0.1:53811][0m
Bad Request: /healthworker/api/PostSurveyForm
[31;1mHTTP POST /healthworker/api/PostSurveyForm 400 [0.19, 127.0.0.1:54018][0m
Internal Server Error: /healthworker/api/PostSurveyForm
Traceback (most recent call last):
  File "D:\Jafar\AAD\.env\lib\site-packages\asgiref\sync.py", line 534, in thread_handler
    raise exc_info[1]
  File "D:\Jafar\AAD\.env\lib\site-packages\django\core\handlers\exception.py", line 42, in inner
    response = await get_response(request)
  File "D:\Jafar\AAD\.env\lib\site-packages\django\core\handlers\base.py", line 253, in _get_response_async
    response = await wrapped_callback(
  File "D:\Jafar\AAD\.env\lib\site-packages\asgiref\sync.py", line 479, in __call__
    ret: _R = await loop.run_in_executor(
  File "C:\Program Files\WindowsApps\PythonSoftwareFoundation.Python.3.10_3.10.3056.0_x64__qbz5n2kfra8p0\lib\concurrent\futures\thread.py", line 58, in run
    result = self.fn(*self.args, **self.kwargs)
  File "D:\Jafar\AAD\.env\lib\site-packages\asgiref\sync.py", line 538, in thread_handler
    return func(*args, **kwargs)
  File "D:\Jafar\AAD\.env\lib\site-packages\django\views\decorators\csrf.py", line 56, in wrapper_view
    return view_func(*args, **kwargs)
  File "D:\Jafar\AAD\.env\lib\site-packages\django\views\generic\base.py", line 104, in view
    return self.dispatch(request, *args, **kwargs)
  File "D:\Jafar\AAD\.env\lib\site-packages\rest_framework\views.py", line 509, in dispatch
    response = self.handle_exception(exc)
  File "D:\Jafar\AAD\.env\lib\site-packages\rest_framework\views.py", line 469, in handle_exception
    self.raise_uncaught_exception(exc)
  File "D:\Jafar\AAD\.env\lib\site-packages\rest_framework\views.py", line 480, in raise_uncaught_exception
    raise exc
  File "D:\Jafar\AAD\.env\lib\site-packages\rest_framework\views.py", line 506, in dispatch
    response = handler(request, *args, **kwargs)
  File "D:\Jafar\AAD\healthworker\views.py", line 106, in post
    serializer.save(location = location , familyId = familyId ,user = user )
  File "D:\Jafar\AAD\.env\lib\site-packages\rest_framework\serializers.py", line 212, in save
    self.instance = self.create(validated_data)
  File "D:\Jafar\AAD\healthworker\serializer.py", line 114, in create
    instance = familyMembers.objects.create(familyHead = head, familySurveyor = head.user, memberId = member_id , **family)
  File "D:\Jafar\AAD\.env\lib\site-packages\django\db\models\manager.py", line 87, in manager_method
    return getattr(self.get_queryset(), name)(*args, **kwargs)
  File "D:\Jafar\AAD\.env\lib\site-packages\django\db\models\query.py", line 656, in create
    obj = self.model(**kwargs)
  File "D:\Jafar\AAD\.env\lib\site-packages\django\db\models\base.py", line 564, in __init__
    _setattr(self, prop, value)
  File "D:\Jafar\AAD\.env\lib\site-packages\django\db\models\fields\related_descriptors.py", line 626, in __set__
    raise TypeError(
TypeError: Direct assignment to the forward side of a many-to-many set is prohibited. Use referels.set() instead.
[35;1mHTTP POST /healthworker/api/PostSurveyForm 500 [1.08, 127.0.0.1:54018][0m
Bad Request: /healthworker/api/PostSurveyForm
[31;1mHTTP POST /healthworker/api/PostSurveyForm 400 [0.19, 127.0.0.1:54128][0m
Internal Server Error: /healthworker/api/PostSurveyForm
Traceback (most recent call last):
  File "D:\Jafar\AAD\.env\lib\site-packages\asgiref\sync.py", line 534, in thread_handler
    raise exc_info[1]
  File "D:\Jafar\AAD\.env\lib\site-packages\django\core\handlers\exception.py", line 42, in inner
    response = await get_response(request)
  File "D:\Jafar\AAD\.env\lib\site-packages\django\core\handlers\base.py", line 253, in _get_response_async
    response = await wrapped_callback(
  File "D:\Jafar\AAD\.env\lib\site-packages\asgiref\sync.py", line 479, in __call__
    ret: _R = await loop.run_in_executor(
  File "C:\Program Files\WindowsApps\PythonSoftwareFoundation.Python.3.10_3.10.3056.0_x64__qbz5n2kfra8p0\lib\concurrent\futures\thread.py", line 58, in run
    result = self.fn(*self.args, **self.kwargs)
  File "D:\Jafar\AAD\.env\lib\site-packages\asgiref\sync.py", line 538, in thread_handler
    return func(*args, **kwargs)
  File "D:\Jafar\AAD\.env\lib\site-packages\django\views\decorators\csrf.py", line 56, in wrapper_view
    return view_func(*args, **kwargs)
  File "D:\Jafar\AAD\.env\lib\site-packages\django\views\generic\base.py", line 104, in view
    return self.dispatch(request, *args, **kwargs)
  File "D:\Jafar\AAD\.env\lib\site-packages\rest_framework\views.py", line 509, in dispatch
    response = self.handle_exception(exc)
  File "D:\Jafar\AAD\.env\lib\site-packages\rest_framework\views.py", line 469, in handle_exception
    self.raise_uncaught_exception(exc)
  File "D:\Jafar\AAD\.env\lib\site-packages\rest_framework\views.py", line 480, in raise_uncaught_exception
    raise exc
  File "D:\Jafar\AAD\.env\lib\site-packages\rest_framework\views.py", line 506, in dispatch
    response = handler(request, *args, **kwargs)
  File "D:\Jafar\AAD\healthworker\views.py", line 106, in post
    serializer.save(location = location , familyId = familyId ,user = user )
  File "D:\Jafar\AAD\.env\lib\site-packages\rest_framework\serializers.py", line 212, in save
    self.instance = self.create(validated_data)
  File "D:\Jafar\AAD\healthworker\serializer.py", line 114, in create
    instance = familyMembers.objects.create(familyHead = head, familySurveyor = head.user, memberId = member_id , **family)
  File "D:\Jafar\AAD\.env\lib\site-packages\django\db\models\manager.py", line 87, in manager_method
    return getattr(self.get_queryset(), name)(*args, **kwargs)
  File "D:\Jafar\AAD\.env\lib\site-packages\django\db\models\query.py", line 656, in create
    obj = self.model(**kwargs)
  File "D:\Jafar\AAD\.env\lib\site-packages\django\db\models\base.py", line 564, in __init__
    _setattr(self, prop, value)
  File "D:\Jafar\AAD\.env\lib\site-packages\django\db\models\fields\related_descriptors.py", line 626, in __set__
    raise TypeError(
TypeError: Direct assignment to the forward side of a many-to-many set is prohibited. Use referels.set() instead.
[35;1mHTTP POST /healthworker/api/PostSurveyForm 500 [0.64, 127.0.0.1:54128][0m
Bad Request: /healthworker/api/PostSurveyForm
[31;1mHTTP POST /healthworker/api/PostSurveyForm 400 [0.15, 127.0.0.1:54292][0m
Internal Server Error: /healthworker/api/PostSurveyForm
Traceback (most recent call last):
  File "D:\Jafar\AAD\.env\lib\site-packages\asgiref\sync.py", line 534, in thread_handler
    raise exc_info[1]
  File "D:\Jafar\AAD\.env\lib\site-packages\django\core\handlers\exception.py", line 42, in inner
    response = await get_response(request)
  File "D:\Jafar\AAD\.env\lib\site-packages\django\core\handlers\base.py", line 253, in _get_response_async
    response = await wrapped_callback(
  File "D:\Jafar\AAD\.env\lib\site-packages\asgiref\sync.py", line 479, in __call__
    ret: _R = await loop.run_in_executor(
  File "C:\Program Files\WindowsApps\PythonSoftwareFoundation.Python.3.10_3.10.3056.0_x64__qbz5n2kfra8p0\lib\concurrent\futures\thread.py", line 58, in run
    result = self.fn(*self.args, **self.kwargs)
  File "D:\Jafar\AAD\.env\lib\site-packages\asgiref\sync.py", line 538, in thread_handler
    return func(*args, **kwargs)
  File "D:\Jafar\AAD\.env\lib\site-packages\django\views\decorators\csrf.py", line 56, in wrapper_view
    return view_func(*args, **kwargs)
  File "D:\Jafar\AAD\.env\lib\site-packages\django\views\generic\base.py", line 104, in view
    return self.dispatch(request, *args, **kwargs)
  File "D:\Jafar\AAD\.env\lib\site-packages\rest_framework\views.py", line 509, in dispatch
    response = self.handle_exception(exc)
  File "D:\Jafar\AAD\.env\lib\site-packages\rest_framework\views.py", line 469, in handle_exception
    self.raise_uncaught_exception(exc)
  File "D:\Jafar\AAD\.env\lib\site-packages\rest_framework\views.py", line 480, in raise_uncaught_exception
    raise exc
  File "D:\Jafar\AAD\.env\lib\site-packages\rest_framework\views.py", line 506, in dispatch
    response = handler(request, *args, **kwargs)
  File "D:\Jafar\AAD\healthworker\views.py", line 106, in post
    serializer.save(location = location , familyId = familyId ,user = user )
  File "D:\Jafar\AAD\.env\lib\site-packages\rest_framework\serializers.py", line 212, in save
    self.instance = self.create(validated_data)
  File "D:\Jafar\AAD\healthworker\serializer.py", line 114, in create
    instance = familyMembers.objects.create(familyHead = head, familySurveyor = head.user, memberId = member_id , **family)
  File "D:\Jafar\AAD\.env\lib\site-packages\django\db\models\manager.py", line 87, in manager_method
    return getattr(self.get_queryset(), name)(*args, **kwargs)
  File "D:\Jafar\AAD\.env\lib\site-packages\django\db\models\query.py", line 656, in create
    obj = self.model(**kwargs)
  File "D:\Jafar\AAD\.env\lib\site-packages\django\db\models\base.py", line 564, in __init__
    _setattr(self, prop, value)
  File "D:\Jafar\AAD\.env\lib\site-packages\django\db\models\fields\related_descriptors.py", line 626, in __set__
    raise TypeError(
TypeError: Direct assignment to the forward side of a many-to-many set is prohibited. Use referels.set() instead.
[35;1mHTTP POST /healthworker/api/PostSurveyForm 500 [0.68, 127.0.0.1:54292][0m
Internal Server Error: /healthworker/api/PostSurveyForm
Traceback (most recent call last):
  File "D:\Jafar\AAD\.env\lib\site-packages\asgiref\sync.py", line 534, in thread_handler
    raise exc_info[1]
  File "D:\Jafar\AAD\.env\lib\site-packages\django\core\handlers\exception.py", line 42, in inner
    response = await get_response(request)
  File "D:\Jafar\AAD\.env\lib\site-packages\django\core\handlers\base.py", line 253, in _get_response_async
    response = await wrapped_callback(
  File "D:\Jafar\AAD\.env\lib\site-packages\asgiref\sync.py", line 479, in __call__
    ret: _R = await loop.run_in_executor(
  File "C:\Program Files\WindowsApps\PythonSoftwareFoundation.Python.3.10_3.10.3056.0_x64__qbz5n2kfra8p0\lib\concurrent\futures\thread.py", line 58, in run
    result = self.fn(*self.args, **self.kwargs)
  File "D:\Jafar\AAD\.env\lib\site-packages\asgiref\sync.py", line 538, in thread_handler
    return func(*args, **kwargs)
  File "D:\Jafar\AAD\.env\lib\site-packages\django\views\decorators\csrf.py", line 56, in wrapper_view
    return view_func(*args, **kwargs)
  File "D:\Jafar\AAD\.env\lib\site-packages\django\views\generic\base.py", line 104, in view
    return self.dispatch(request, *args, **kwargs)
  File "D:\Jafar\AAD\.env\lib\site-packages\rest_framework\views.py", line 509, in dispatch
    response = self.handle_exception(exc)
  File "D:\Jafar\AAD\.env\lib\site-packages\rest_framework\views.py", line 469, in handle_exception
    self.raise_uncaught_exception(exc)
  File "D:\Jafar\AAD\.env\lib\site-packages\rest_framework\views.py", line 480, in raise_uncaught_exception
    raise exc
  File "D:\Jafar\AAD\.env\lib\site-packages\rest_framework\views.py", line 506, in dispatch
    response = handler(request, *args, **kwargs)
  File "D:\Jafar\AAD\healthworker\views.py", line 106, in post
    serializer.save(location = location , familyId = familyId ,user = user )
  File "D:\Jafar\AAD\.env\lib\site-packages\rest_framework\serializers.py", line 212, in save
    self.instance = self.create(validated_data)
  File "D:\Jafar\AAD\healthworker\serializer.py", line 118, in create
    instance.referels.add(*family['referels'])
KeyError: 'referels'
[35;1mHTTP POST /healthworker/api/PostSurveyForm 500 [0.50, 127.0.0.1:54530][0m
Internal Server Error: /adminportal/api/GetuserListAPI/healthworker
Traceback (most recent call last):
  File "D:\Jafar\AAD\.env\lib\site-packages\asgiref\sync.py", line 534, in thread_handler
    raise exc_info[1]
  File "D:\Jafar\AAD\.env\lib\site-packages\django\core\handlers\exception.py", line 42, in inner
    response = await get_response(request)
  File "D:\Jafar\AAD\.env\lib\site-packages\django\core\handlers\base.py", line 284, in _get_response_async
    response = await sync_to_async(
  File "D:\Jafar\AAD\.env\lib\site-packages\asgiref\sync.py", line 479, in __call__
    ret: _R = await loop.run_in_executor(
  File "C:\Program Files\WindowsApps\PythonSoftwareFoundation.Python.3.10_3.10.3056.0_x64__qbz5n2kfra8p0\lib\concurrent\futures\thread.py", line 58, in run
    result = self.fn(*self.args, **self.kwargs)
  File "D:\Jafar\AAD\.env\lib\site-packages\asgiref\sync.py", line 538, in thread_handler
    return func(*args, **kwargs)
  File "D:\Jafar\AAD\.env\lib\site-packages\django\template\response.py", line 114, in render
    self.content = self.rendered_content
  File "D:\Jafar\AAD\.env\lib\site-packages\rest_framework\response.py", line 70, in rendered_content
    ret = renderer.render(self.data, accepted_media_type, context)
  File "D:\Jafar\AAD\.env\lib\site-packages\rest_framework\renderers.py", line 99, in render
    ret = json.dumps(
  File "D:\Jafar\AAD\.env\lib\site-packages\rest_framework\utils\json.py", line 25, in dumps
    return json.dumps(*args, **kwargs)
  File "C:\Program Files\WindowsApps\PythonSoftwareFoundation.Python.3.10_3.10.3056.0_x64__qbz5n2kfra8p0\lib\json\__init__.py", line 238, in dumps
    **kw).encode(obj)
  File "C:\Program Files\WindowsApps\PythonSoftwareFoundation.Python.3.10_3.10.3056.0_x64__qbz5n2kfra8p0\lib\json\encoder.py", line 199, in encode
    chunks = self.iterencode(o, _one_shot=True)
  File "C:\Program Files\WindowsApps\PythonSoftwareFoundation.Python.3.10_3.10.3056.0_x64__qbz5n2kfra8p0\lib\json\encoder.py", line 257, in iterencode
    return _iterencode(o, 0)
  File "D:\Jafar\AAD\.env\lib\site-packages\rest_framework\utils\encoders.py", line 67, in default
    return super().default(obj)
  File "C:\Program Files\WindowsApps\PythonSoftwareFoundation.Python.3.10_3.10.3056.0_x64__qbz5n2kfra8p0\lib\json\encoder.py", line 179, in default
    raise TypeError(f'Object of type {o.__class__.__name__} '
TypeError: Object of type ward is not JSON serializable
[35;1mHTTP GET /adminportal/api/GetuserListAPI/healthworker?limit=50 500 [1.00, 127.0.0.1:57545][0m
Internal Server Error: /adminportal/api/GetuserListAPI/healthworker
Traceback (most recent call last):
  File "D:\Jafar\AAD\.env\lib\site-packages\asgiref\sync.py", line 534, in thread_handler
    raise exc_info[1]
  File "D:\Jafar\AAD\.env\lib\site-packages\django\core\handlers\exception.py", line 42, in inner
    response = await get_response(request)
  File "D:\Jafar\AAD\.env\lib\site-packages\django\core\handlers\base.py", line 284, in _get_response_async
    response = await sync_to_async(
  File "D:\Jafar\AAD\.env\lib\site-packages\asgiref\sync.py", line 479, in __call__
    ret: _R = await loop.run_in_executor(
  File "C:\Program Files\WindowsApps\PythonSoftwareFoundation.Python.3.10_3.10.3056.0_x64__qbz5n2kfra8p0\lib\concurrent\futures\thread.py", line 58, in run
    result = self.fn(*self.args, **self.kwargs)
  File "D:\Jafar\AAD\.env\lib\site-packages\asgiref\sync.py", line 538, in thread_handler
    return func(*args, **kwargs)
  File "D:\Jafar\AAD\.env\lib\site-packages\django\template\response.py", line 114, in render
    self.content = self.rendered_content
  File "D:\Jafar\AAD\.env\lib\site-packages\rest_framework\response.py", line 70, in rendered_content
    ret = renderer.render(self.data, accepted_media_type, context)
  File "D:\Jafar\AAD\.env\lib\site-packages\rest_framework\renderers.py", line 99, in render
    ret = json.dumps(
  File "D:\Jafar\AAD\.env\lib\site-packages\rest_framework\utils\json.py", line 25, in dumps
    return json.dumps(*args, **kwargs)
  File "C:\Program Files\WindowsApps\PythonSoftwareFoundation.Python.3.10_3.10.3056.0_x64__qbz5n2kfra8p0\lib\json\__init__.py", line 238, in dumps
    **kw).encode(obj)
  File "C:\Program Files\WindowsApps\PythonSoftwareFoundation.Python.3.10_3.10.3056.0_x64__qbz5n2kfra8p0\lib\json\encoder.py", line 199, in encode
    chunks = self.iterencode(o, _one_shot=True)
  File "C:\Program Files\WindowsApps\PythonSoftwareFoundation.Python.3.10_3.10.3056.0_x64__qbz5n2kfra8p0\lib\json\encoder.py", line 257, in iterencode
    return _iterencode(o, 0)
  File "D:\Jafar\AAD\.env\lib\site-packages\rest_framework\utils\encoders.py", line 67, in default
    return super().default(obj)
  File "C:\Program Files\WindowsApps\PythonSoftwareFoundation.Python.3.10_3.10.3056.0_x64__qbz5n2kfra8p0\lib\json\encoder.py", line 179, in default
    raise TypeError(f'Object of type {o.__class__.__name__} '
TypeError: Object of type ward is not JSON serializable
[35;1mHTTP GET /adminportal/api/GetuserListAPI/healthworker?limit=50 500 [0.75, 127.0.0.1:57617][0m
Internal Server Error: /adminportal/api/GetuserListAPI/mo
Traceback (most recent call last):
  File "D:\Jafar\AAD\.env\lib\site-packages\asgiref\sync.py", line 534, in thread_handler
    raise exc_info[1]
  File "D:\Jafar\AAD\.env\lib\site-packages\django\core\handlers\exception.py", line 42, in inner
    response = await get_response(request)
  File "D:\Jafar\AAD\.env\lib\site-packages\django\core\handlers\base.py", line 253, in _get_response_async
    response = await wrapped_callback(
  File "D:\Jafar\AAD\.env\lib\site-packages\asgiref\sync.py", line 479, in __call__
    ret: _R = await loop.run_in_executor(
  File "C:\Program Files\WindowsApps\PythonSoftwareFoundation.Python.3.10_3.10.3056.0_x64__qbz5n2kfra8p0\lib\concurrent\futures\thread.py", line 58, in run
    result = self.fn(*self.args, **self.kwargs)
  File "D:\Jafar\AAD\.env\lib\site-packages\asgiref\sync.py", line 538, in thread_handler
    return func(*args, **kwargs)
  File "D:\Jafar\AAD\.env\lib\site-packages\django\views\decorators\csrf.py", line 56, in wrapper_view
    return view_func(*args, **kwargs)
  File "D:\Jafar\AAD\.env\lib\site-packages\django\views\generic\base.py", line 104, in view
    return self.dispatch(request, *args, **kwargs)
  File "D:\Jafar\AAD\.env\lib\site-packages\rest_framework\views.py", line 509, in dispatch
    response = self.handle_exception(exc)
  File "D:\Jafar\AAD\.env\lib\site-packages\rest_framework\views.py", line 469, in handle_exception
    self.raise_uncaught_exception(exc)
  File "D:\Jafar\AAD\.env\lib\site-packages\rest_framework\views.py", line 480, in raise_uncaught_exception
    raise exc
  File "D:\Jafar\AAD\.env\lib\site-packages\rest_framework\views.py", line 506, in dispatch
    response = handler(request, *args, **kwargs)
  File "D:\Jafar\AAD\adminportal\views.py", line 183, in get
    'data': serializer.data})
  File "D:\Jafar\AAD\.env\lib\site-packages\rest_framework\serializers.py", line 768, in data
    ret = super().data
  File "D:\Jafar\AAD\.env\lib\site-packages\rest_framework\serializers.py", line 253, in data
    self._data = self.to_representation(self.instance)
  File "D:\Jafar\AAD\.env\lib\site-packages\rest_framework\serializers.py", line 686, in to_representation
    return [
  File "D:\Jafar\AAD\.env\lib\site-packages\rest_framework\serializers.py", line 687, in <listcomp>
    self.child.to_representation(item) for item in iterable
  File "D:\Jafar\AAD\.env\lib\site-packages\rest_framework\serializers.py", line 507, in to_representation
    for field in fields:
  File "D:\Jafar\AAD\.env\lib\site-packages\rest_framework\serializers.py", line 368, in _readable_fields
    for field in self.fields.values():
  File "D:\Jafar\AAD\.env\lib\site-packages\django\utils\functional.py", line 57, in __get__
    res = instance.__dict__[self.name] = self.func(instance)
  File "D:\Jafar\AAD\.env\lib\site-packages\rest_framework\serializers.py", line 356, in fields
    for key, value in self.get_fields().items():
  File "D:\Jafar\AAD\.env\lib\site-packages\rest_framework\serializers.py", line 1052, in get_fields
    field_names = self.get_field_names(declared_fields, info)
  File "D:\Jafar\AAD\.env\lib\site-packages\rest_framework\serializers.py", line 1148, in get_field_names
    assert field_name in fields, (
AssertionError: The field 'dispensary_id' was declared on serializer CustomUserSerializer, but has not been included in the 'fields' option.
[35;1mHTTP GET /adminportal/api/GetuserListAPI/mo?limit=50 500 [0.21, 127.0.0.1:57791][0m
