view's UpdateUserDetails raised exception during schema generation; use `getattr(self, 'swagger_fake_view', False)` to detect and short-circuit this
Traceback (most recent call last):
  File "D:\ArograD\venv\lib\site-packages\drf_yasg\inspectors\base.py", line 42, in call_view_method
    return view_method()
  File "D:\ArograD\venv\lib\site-packages\rest_framework\generics.py", line 63, in get_queryset
    assert self.queryset is not None, (
AssertionError: 'UpdateUserDetails' should either include a `queryset` attribute, or override the `get_queryset()` method.
Unauthorized: /allauth/api/GetSectionListAPI
HTTP GET /allauth/api/GetSectionListAPI 401 [0.01, 127.0.0.1:53449]
view's UpdateUserDetails raised exception during schema generation; use `getattr(self, 'swagger_fake_view', False)` to detect and short-circuit this
Traceback (most recent call last):
  File "D:\ArograD\venv\lib\site-packages\drf_yasg\inspectors\base.py", line 42, in call_view_method
    return view_method()
  File "D:\ArograD\venv\lib\site-packages\rest_framework\generics.py", line 63, in get_queryset
    assert self.queryset is not None, (
AssertionError: 'UpdateUserDetails' should either include a `queryset` attribute, or override the `get_queryset()` method.
Unauthorized: /allauth/api/GetSectionListAPI
HTTP GET /allauth/api/GetSectionListAPI 401 [0.01, 127.0.0.1:53875]
view's UpdateUserDetails raised exception during schema generation; use `getattr(self, 'swagger_fake_view', False)` to detect and short-circuit this
Traceback (most recent call last):
  File "D:\ArograD\venv\lib\site-packages\drf_yasg\inspectors\base.py", line 42, in call_view_method
    return view_method()
  File "D:\ArograD\venv\lib\site-packages\rest_framework\generics.py", line 63, in get_queryset
    assert self.queryset is not None, (
AssertionError: 'UpdateUserDetails' should either include a `queryset` attribute, or override the `get_queryset()` method.
view's UpdateUserDetails raised exception during schema generation; use `getattr(self, 'swagger_fake_view', False)` to detect and short-circuit this
Traceback (most recent call last):
  File "D:\ArograD\venv\lib\site-packages\drf_yasg\inspectors\base.py", line 42, in call_view_method
    return view_method()
  File "D:\ArograD\venv\lib\site-packages\rest_framework\generics.py", line 63, in get_queryset
    assert self.queryset is not None, (
AssertionError: 'UpdateUserDetails' should either include a `queryset` attribute, or override the `get_queryset()` method.
view's UpdateUserDetails raised exception during schema generation; use `getattr(self, 'swagger_fake_view', False)` to detect and short-circuit this
Traceback (most recent call last):
  File "D:\ArograD\venv\lib\site-packages\drf_yasg\inspectors\base.py", line 42, in call_view_method
    return view_method()
  File "D:\ArograD\venv\lib\site-packages\rest_framework\generics.py", line 63, in get_queryset
    assert self.queryset is not None, (
AssertionError: 'UpdateUserDetails' should either include a `queryset` attribute, or override the `get_queryset()` method.
Unauthorized: /allauth/api/GetSectionListAPI
HTTP GET /allauth/api/GetSectionListAPI 401 [0.01, 127.0.0.1:55450]
view's UpdateUserDetails raised exception during schema generation; use `getattr(self, 'swagger_fake_view', False)` to detect and short-circuit this
Traceback (most recent call last):
  File "D:\Jafar\AAD\.env\lib\site-packages\drf_yasg\inspectors\base.py", line 42, in call_view_method
    return view_method()
  File "D:\Jafar\AAD\.env\lib\site-packages\rest_framework\generics.py", line 63, in get_queryset
    assert self.queryset is not None, (
AssertionError: 'UpdateUserDetails' should either include a `queryset` attribute, or override the `get_queryset()` method.
Internal Server Error: /swagger/
Traceback (most recent call last):
  File "D:\Jafar\AAD\.env\lib\site-packages\asgiref\sync.py", line 534, in thread_handler
    raise exc_info[1]
  File "D:\Jafar\AAD\.env\lib\site-packages\django\core\handlers\exception.py", line 42, in inner
    response = await get_response(request)
  File "D:\Jafar\AAD\.env\lib\site-packages\django\core\handlers\base.py", line 253, in _get_response_async
    response = await wrapped_callback(
  File "D:\Jafar\AAD\.env\lib\site-packages\asgiref\sync.py", line 479, in __call__
    ret: _R = await loop.run_in_executor(
  File "C:\Program Files\WindowsApps\PythonSoftwareFoundation.Python.3.10_3.10.3056.0_x64__qbz5n2kfra8p0\lib\concurrent\futures\thread.py", line 58, in run
    result = self.fn(*self.args, **self.kwargs)
  File "D:\Jafar\AAD\.env\lib\site-packages\asgiref\sync.py", line 538, in thread_handler
    return func(*args, **kwargs)
  File "D:\Jafar\AAD\.env\lib\site-packages\django\views\decorators\csrf.py", line 56, in wrapper_view
    return view_func(*args, **kwargs)
  File "D:\Jafar\AAD\.env\lib\site-packages\django\views\generic\base.py", line 104, in view
    return self.dispatch(request, *args, **kwargs)
  File "D:\Jafar\AAD\.env\lib\site-packages\rest_framework\views.py", line 509, in dispatch
    response = self.handle_exception(exc)
  File "D:\Jafar\AAD\.env\lib\site-packages\rest_framework\views.py", line 469, in handle_exception
    self.raise_uncaught_exception(exc)
  File "D:\Jafar\AAD\.env\lib\site-packages\rest_framework\views.py", line 480, in raise_uncaught_exception
    raise exc
  File "D:\Jafar\AAD\.env\lib\site-packages\rest_framework\views.py", line 506, in dispatch
    response = handler(request, *args, **kwargs)
  File "D:\Jafar\AAD\.env\lib\site-packages\drf_yasg\views.py", line 96, in get
    schema = generator.get_schema(request, self.public)
  File "D:\Jafar\AAD\.env\lib\site-packages\drf_yasg\generators.py", line 276, in get_schema
    paths, prefix = self.get_paths(endpoints, components, request, public)
  File "D:\Jafar\AAD\.env\lib\site-packages\drf_yasg\generators.py", line 482, in get_paths
    operation = self.get_operation(view, path, prefix, method, components, request)
  File "D:\Jafar\AAD\.env\lib\site-packages\drf_yasg\generators.py", line 524, in get_operation
    operation = view_inspector.get_operation(operation_keys)
  File "D:\Jafar\AAD\.env\lib\site-packages\drf_yasg\inspectors\view.py", line 33, in get_operation
    query = self.get_query_parameters()
  File "D:\Jafar\AAD\.env\lib\site-packages\drf_yasg\inspectors\view.py", line 293, in get_query_parameters
    natural_parameters = self.get_filter_parameters() + self.get_pagination_parameters()
  File "D:\Jafar\AAD\.env\lib\site-packages\drf_yasg\inspectors\base.py", line 409, in get_filter_parameters
    fields += self.probe_inspectors(self.filter_inspectors, 'get_filter_parameters', filter_backend()) or []
  File "D:\Jafar\AAD\.env\lib\site-packages\drf_yasg\inspectors\base.py", line 110, in probe_inspectors
    result = method(obj, **kwargs)
  File "D:\Jafar\AAD\.env\lib\site-packages\drf_yasg\inspectors\query.py", line 42, in get_filter_parameters
    return list(map(self.param_to_schema, filter_backend.get_schema_operation_parameters(self.view)))
  File "D:\Jafar\AAD\.env\lib\site-packages\django_filters\rest_framework\backends.py", line 146, in get_schema_operation_parameters
    filterset_class = self.get_filterset_class(view, queryset)
  File "D:\Jafar\AAD\.env\lib\site-packages\django_filters\rest_framework\backends.py", line 51, in get_filterset_class
    class AutoFilterSet(self.filterset_base):
  File "D:\Jafar\AAD\.env\lib\site-packages\django_filters\filterset.py", line 62, in __new__
    new_class.base_filters = new_class.get_filters()
  File "D:\Jafar\AAD\.env\lib\site-packages\django_filters\filterset.py", line 349, in get_filters
    raise TypeError(
TypeError: 'Meta.fields' must not contain non-model field names: h, e, a, l, t, P, o, s, _, i, d
[35;1mHTTP GET /swagger/?format=openapi 500 [0.24, 127.0.0.1:55722][0m
view's UpdateUserDetails raised exception during schema generation; use `getattr(self, 'swagger_fake_view', False)` to detect and short-circuit this
Traceback (most recent call last):
  File "D:\Jafar\AAD\.env\lib\site-packages\drf_yasg\inspectors\base.py", line 42, in call_view_method
    return view_method()
  File "D:\Jafar\AAD\.env\lib\site-packages\rest_framework\generics.py", line 63, in get_queryset
    assert self.queryset is not None, (
AssertionError: 'UpdateUserDetails' should either include a `queryset` attribute, or override the `get_queryset()` method.
Internal Server Error: /swagger/
Traceback (most recent call last):
  File "D:\Jafar\AAD\.env\lib\site-packages\asgiref\sync.py", line 534, in thread_handler
    raise exc_info[1]
  File "D:\Jafar\AAD\.env\lib\site-packages\django\core\handlers\exception.py", line 42, in inner
    response = await get_response(request)
  File "D:\Jafar\AAD\.env\lib\site-packages\django\core\handlers\base.py", line 253, in _get_response_async
    response = await wrapped_callback(
  File "D:\Jafar\AAD\.env\lib\site-packages\asgiref\sync.py", line 479, in __call__
    ret: _R = await loop.run_in_executor(
  File "C:\Program Files\WindowsApps\PythonSoftwareFoundation.Python.3.10_3.10.3056.0_x64__qbz5n2kfra8p0\lib\concurrent\futures\thread.py", line 58, in run
    result = self.fn(*self.args, **self.kwargs)
  File "D:\Jafar\AAD\.env\lib\site-packages\asgiref\sync.py", line 538, in thread_handler
    return func(*args, **kwargs)
  File "D:\Jafar\AAD\.env\lib\site-packages\django\views\decorators\csrf.py", line 56, in wrapper_view
    return view_func(*args, **kwargs)
  File "D:\Jafar\AAD\.env\lib\site-packages\django\views\generic\base.py", line 104, in view
    return self.dispatch(request, *args, **kwargs)
  File "D:\Jafar\AAD\.env\lib\site-packages\rest_framework\views.py", line 509, in dispatch
    response = self.handle_exception(exc)
  File "D:\Jafar\AAD\.env\lib\site-packages\rest_framework\views.py", line 469, in handle_exception
    self.raise_uncaught_exception(exc)
  File "D:\Jafar\AAD\.env\lib\site-packages\rest_framework\views.py", line 480, in raise_uncaught_exception
    raise exc
  File "D:\Jafar\AAD\.env\lib\site-packages\rest_framework\views.py", line 506, in dispatch
    response = handler(request, *args, **kwargs)
  File "D:\Jafar\AAD\.env\lib\site-packages\drf_yasg\views.py", line 96, in get
    schema = generator.get_schema(request, self.public)
  File "D:\Jafar\AAD\.env\lib\site-packages\drf_yasg\generators.py", line 276, in get_schema
    paths, prefix = self.get_paths(endpoints, components, request, public)
  File "D:\Jafar\AAD\.env\lib\site-packages\drf_yasg\generators.py", line 482, in get_paths
    operation = self.get_operation(view, path, prefix, method, components, request)
  File "D:\Jafar\AAD\.env\lib\site-packages\drf_yasg\generators.py", line 524, in get_operation
    operation = view_inspector.get_operation(operation_keys)
  File "D:\Jafar\AAD\.env\lib\site-packages\drf_yasg\inspectors\view.py", line 33, in get_operation
    query = self.get_query_parameters()
  File "D:\Jafar\AAD\.env\lib\site-packages\drf_yasg\inspectors\view.py", line 293, in get_query_parameters
    natural_parameters = self.get_filter_parameters() + self.get_pagination_parameters()
  File "D:\Jafar\AAD\.env\lib\site-packages\drf_yasg\inspectors\base.py", line 409, in get_filter_parameters
    fields += self.probe_inspectors(self.filter_inspectors, 'get_filter_parameters', filter_backend()) or []
  File "D:\Jafar\AAD\.env\lib\site-packages\drf_yasg\inspectors\base.py", line 110, in probe_inspectors
    result = method(obj, **kwargs)
  File "D:\Jafar\AAD\.env\lib\site-packages\drf_yasg\inspectors\query.py", line 42, in get_filter_parameters
    return list(map(self.param_to_schema, filter_backend.get_schema_operation_parameters(self.view)))
  File "D:\Jafar\AAD\.env\lib\site-packages\django_filters\rest_framework\backends.py", line 146, in get_schema_operation_parameters
    filterset_class = self.get_filterset_class(view, queryset)
  File "D:\Jafar\AAD\.env\lib\site-packages\django_filters\rest_framework\backends.py", line 51, in get_filterset_class
    class AutoFilterSet(self.filterset_base):
  File "D:\Jafar\AAD\.env\lib\site-packages\django_filters\filterset.py", line 62, in __new__
    new_class.base_filters = new_class.get_filters()
  File "D:\Jafar\AAD\.env\lib\site-packages\django_filters\filterset.py", line 349, in get_filters
    raise TypeError(
TypeError: 'Meta.fields' must not contain non-model field names: h, e, a, l, t, P, o, s, _, i, d
[35;1mHTTP GET /swagger/?format=openapi 500 [0.12, 127.0.0.1:56049][0m
view's UpdateUserDetails raised exception during schema generation; use `getattr(self, 'swagger_fake_view', False)` to detect and short-circuit this
Traceback (most recent call last):
  File "D:\Jafar\AAD\.env\lib\site-packages\drf_yasg\inspectors\base.py", line 42, in call_view_method
    return view_method()
  File "D:\Jafar\AAD\.env\lib\site-packages\rest_framework\generics.py", line 63, in get_queryset
    assert self.queryset is not None, (
AssertionError: 'UpdateUserDetails' should either include a `queryset` attribute, or override the `get_queryset()` method.
Internal Server Error: /swagger/
Traceback (most recent call last):
  File "D:\Jafar\AAD\.env\lib\site-packages\asgiref\sync.py", line 534, in thread_handler
    raise exc_info[1]
  File "D:\Jafar\AAD\.env\lib\site-packages\django\core\handlers\exception.py", line 42, in inner
    response = await get_response(request)
  File "D:\Jafar\AAD\.env\lib\site-packages\django\core\handlers\base.py", line 253, in _get_response_async
    response = await wrapped_callback(
  File "D:\Jafar\AAD\.env\lib\site-packages\asgiref\sync.py", line 479, in __call__
    ret: _R = await loop.run_in_executor(
  File "C:\Program Files\WindowsApps\PythonSoftwareFoundation.Python.3.10_3.10.3056.0_x64__qbz5n2kfra8p0\lib\concurrent\futures\thread.py", line 58, in run
    result = self.fn(*self.args, **self.kwargs)
  File "D:\Jafar\AAD\.env\lib\site-packages\asgiref\sync.py", line 538, in thread_handler
    return func(*args, **kwargs)
  File "D:\Jafar\AAD\.env\lib\site-packages\django\views\decorators\csrf.py", line 56, in wrapper_view
    return view_func(*args, **kwargs)
  File "D:\Jafar\AAD\.env\lib\site-packages\django\views\generic\base.py", line 104, in view
    return self.dispatch(request, *args, **kwargs)
  File "D:\Jafar\AAD\.env\lib\site-packages\rest_framework\views.py", line 509, in dispatch
    response = self.handle_exception(exc)
  File "D:\Jafar\AAD\.env\lib\site-packages\rest_framework\views.py", line 469, in handle_exception
    self.raise_uncaught_exception(exc)
  File "D:\Jafar\AAD\.env\lib\site-packages\rest_framework\views.py", line 480, in raise_uncaught_exception
    raise exc
  File "D:\Jafar\AAD\.env\lib\site-packages\rest_framework\views.py", line 506, in dispatch
    response = handler(request, *args, **kwargs)
  File "D:\Jafar\AAD\.env\lib\site-packages\drf_yasg\views.py", line 96, in get
    schema = generator.get_schema(request, self.public)
  File "D:\Jafar\AAD\.env\lib\site-packages\drf_yasg\generators.py", line 276, in get_schema
    paths, prefix = self.get_paths(endpoints, components, request, public)
  File "D:\Jafar\AAD\.env\lib\site-packages\drf_yasg\generators.py", line 482, in get_paths
    operation = self.get_operation(view, path, prefix, method, components, request)
  File "D:\Jafar\AAD\.env\lib\site-packages\drf_yasg\generators.py", line 524, in get_operation
    operation = view_inspector.get_operation(operation_keys)
  File "D:\Jafar\AAD\.env\lib\site-packages\drf_yasg\inspectors\view.py", line 33, in get_operation
    query = self.get_query_parameters()
  File "D:\Jafar\AAD\.env\lib\site-packages\drf_yasg\inspectors\view.py", line 293, in get_query_parameters
    natural_parameters = self.get_filter_parameters() + self.get_pagination_parameters()
  File "D:\Jafar\AAD\.env\lib\site-packages\drf_yasg\inspectors\base.py", line 409, in get_filter_parameters
    fields += self.probe_inspectors(self.filter_inspectors, 'get_filter_parameters', filter_backend()) or []
  File "D:\Jafar\AAD\.env\lib\site-packages\drf_yasg\inspectors\base.py", line 110, in probe_inspectors
    result = method(obj, **kwargs)
  File "D:\Jafar\AAD\.env\lib\site-packages\drf_yasg\inspectors\query.py", line 42, in get_filter_parameters
    return list(map(self.param_to_schema, filter_backend.get_schema_operation_parameters(self.view)))
  File "D:\Jafar\AAD\.env\lib\site-packages\django_filters\rest_framework\backends.py", line 146, in get_schema_operation_parameters
    filterset_class = self.get_filterset_class(view, queryset)
  File "D:\Jafar\AAD\.env\lib\site-packages\django_filters\rest_framework\backends.py", line 51, in get_filterset_class
    class AutoFilterSet(self.filterset_base):
  File "D:\Jafar\AAD\.env\lib\site-packages\django_filters\filterset.py", line 62, in __new__
    new_class.base_filters = new_class.get_filters()
  File "D:\Jafar\AAD\.env\lib\site-packages\django_filters\filterset.py", line 349, in get_filters
    raise TypeError(
TypeError: 'Meta.fields' must not contain non-model field names: h, e, a, l, t, P, o, s, _, i, d
[35;1mHTTP GET /swagger/?format=openapi 500 [0.30, 127.0.0.1:56049][0m
view's UpdateUserDetails raised exception during schema generation; use `getattr(self, 'swagger_fake_view', False)` to detect and short-circuit this
Traceback (most recent call last):
  File "D:\Jafar\AAD\.env\lib\site-packages\drf_yasg\inspectors\base.py", line 42, in call_view_method
    return view_method()
  File "D:\Jafar\AAD\.env\lib\site-packages\rest_framework\generics.py", line 63, in get_queryset
    assert self.queryset is not None, (
AssertionError: 'UpdateUserDetails' should either include a `queryset` attribute, or override the `get_queryset()` method.
view's UpdateUserDetails raised exception during schema generation; use `getattr(self, 'swagger_fake_view', False)` to detect and short-circuit this
Traceback (most recent call last):
  File "D:\Jafar\AAD\.env\lib\site-packages\drf_yasg\inspectors\base.py", line 42, in call_view_method
    return view_method()
  File "D:\Jafar\AAD\.env\lib\site-packages\rest_framework\generics.py", line 63, in get_queryset
    assert self.queryset is not None, (
AssertionError: 'UpdateUserDetails' should either include a `queryset` attribute, or override the `get_queryset()` method.
Internal Server Error: /swagger/
Traceback (most recent call last):
  File "D:\Jafar\AAD\.env\lib\site-packages\asgiref\sync.py", line 534, in thread_handler
    raise exc_info[1]
  File "D:\Jafar\AAD\.env\lib\site-packages\django\core\handlers\exception.py", line 42, in inner
    response = await get_response(request)
  File "D:\Jafar\AAD\.env\lib\site-packages\django\core\handlers\base.py", line 253, in _get_response_async
    response = await wrapped_callback(
  File "D:\Jafar\AAD\.env\lib\site-packages\asgiref\sync.py", line 479, in __call__
    ret: _R = await loop.run_in_executor(
  File "C:\Program Files\WindowsApps\PythonSoftwareFoundation.Python.3.10_3.10.3056.0_x64__qbz5n2kfra8p0\lib\concurrent\futures\thread.py", line 58, in run
    result = self.fn(*self.args, **self.kwargs)
  File "D:\Jafar\AAD\.env\lib\site-packages\asgiref\sync.py", line 538, in thread_handler
    return func(*args, **kwargs)
  File "D:\Jafar\AAD\.env\lib\site-packages\django\views\decorators\csrf.py", line 56, in wrapper_view
    return view_func(*args, **kwargs)
  File "D:\Jafar\AAD\.env\lib\site-packages\django\views\generic\base.py", line 104, in view
    return self.dispatch(request, *args, **kwargs)
  File "D:\Jafar\AAD\.env\lib\site-packages\rest_framework\views.py", line 509, in dispatch
    response = self.handle_exception(exc)
  File "D:\Jafar\AAD\.env\lib\site-packages\rest_framework\views.py", line 469, in handle_exception
    self.raise_uncaught_exception(exc)
  File "D:\Jafar\AAD\.env\lib\site-packages\rest_framework\views.py", line 480, in raise_uncaught_exception
    raise exc
  File "D:\Jafar\AAD\.env\lib\site-packages\rest_framework\views.py", line 506, in dispatch
    response = handler(request, *args, **kwargs)
  File "D:\Jafar\AAD\.env\lib\site-packages\drf_yasg\views.py", line 96, in get
    schema = generator.get_schema(request, self.public)
  File "D:\Jafar\AAD\.env\lib\site-packages\drf_yasg\generators.py", line 276, in get_schema
    paths, prefix = self.get_paths(endpoints, components, request, public)
  File "D:\Jafar\AAD\.env\lib\site-packages\drf_yasg\generators.py", line 482, in get_paths
    operation = self.get_operation(view, path, prefix, method, components, request)
  File "D:\Jafar\AAD\.env\lib\site-packages\drf_yasg\generators.py", line 524, in get_operation
    operation = view_inspector.get_operation(operation_keys)
  File "D:\Jafar\AAD\.env\lib\site-packages\drf_yasg\inspectors\view.py", line 33, in get_operation
    query = self.get_query_parameters()
  File "D:\Jafar\AAD\.env\lib\site-packages\drf_yasg\inspectors\view.py", line 293, in get_query_parameters
    natural_parameters = self.get_filter_parameters() + self.get_pagination_parameters()
  File "D:\Jafar\AAD\.env\lib\site-packages\drf_yasg\inspectors\base.py", line 409, in get_filter_parameters
    fields += self.probe_inspectors(self.filter_inspectors, 'get_filter_parameters', filter_backend()) or []
  File "D:\Jafar\AAD\.env\lib\site-packages\drf_yasg\inspectors\base.py", line 110, in probe_inspectors
    result = method(obj, **kwargs)
  File "D:\Jafar\AAD\.env\lib\site-packages\drf_yasg\inspectors\query.py", line 42, in get_filter_parameters
    return list(map(self.param_to_schema, filter_backend.get_schema_operation_parameters(self.view)))
  File "D:\Jafar\AAD\.env\lib\site-packages\django_filters\rest_framework\backends.py", line 146, in get_schema_operation_parameters
    filterset_class = self.get_filterset_class(view, queryset)
  File "D:\Jafar\AAD\.env\lib\site-packages\django_filters\rest_framework\backends.py", line 51, in get_filterset_class
    class AutoFilterSet(self.filterset_base):
  File "D:\Jafar\AAD\.env\lib\site-packages\django_filters\filterset.py", line 62, in __new__
    new_class.base_filters = new_class.get_filters()
  File "D:\Jafar\AAD\.env\lib\site-packages\django_filters\filterset.py", line 349, in get_filters
    raise TypeError(
TypeError: 'Meta.fields' must not contain non-model field names: h, e, a, l, t, P, o, s, _, i, d
[35;1mHTTP GET /swagger/?format=openapi 500 [0.20, 127.0.0.1:56209][0m
view's UpdateUserDetails raised exception during schema generation; use `getattr(self, 'swagger_fake_view', False)` to detect and short-circuit this
Traceback (most recent call last):
  File "D:\Jafar\AAD\.env\lib\site-packages\drf_yasg\inspectors\base.py", line 42, in call_view_method
    return view_method()
  File "D:\Jafar\AAD\.env\lib\site-packages\rest_framework\generics.py", line 63, in get_queryset
    assert self.queryset is not None, (
AssertionError: 'UpdateUserDetails' should either include a `queryset` attribute, or override the `get_queryset()` method.
view's UpdateUserDetails raised exception during schema generation; use `getattr(self, 'swagger_fake_view', False)` to detect and short-circuit this
Traceback (most recent call last):
  File "D:\Jafar\AAD\.env\lib\site-packages\drf_yasg\inspectors\base.py", line 42, in call_view_method
    return view_method()
  File "D:\Jafar\AAD\.env\lib\site-packages\rest_framework\generics.py", line 63, in get_queryset
    assert self.queryset is not None, (
AssertionError: 'UpdateUserDetails' should either include a `queryset` attribute, or override the `get_queryset()` method.
view's UpdateUserDetails raised exception during schema generation; use `getattr(self, 'swagger_fake_view', False)` to detect and short-circuit this
Traceback (most recent call last):
  File "D:\Jafar\AAD\.env\lib\site-packages\drf_yasg\inspectors\base.py", line 42, in call_view_method
    return view_method()
  File "D:\Jafar\AAD\.env\lib\site-packages\rest_framework\generics.py", line 63, in get_queryset
    assert self.queryset is not None, (
AssertionError: 'UpdateUserDetails' should either include a `queryset` attribute, or override the `get_queryset()` method.
Forbidden: /allauth/api/GetSectionListAPI/4
[31;1mHTTP GET /allauth/api/GetSectionListAPI/4 403 [0.11, 127.0.0.1:56345][0m
Bad Request: /allauth/api/login
[31;1mHTTP POST /allauth/api/login 400 [0.64, 127.0.0.1:56345][0m
view's UpdateUserDetails raised exception during schema generation; use `getattr(self, 'swagger_fake_view', False)` to detect and short-circuit this
Traceback (most recent call last):
  File "D:\Jafar\AAD\.env\lib\site-packages\drf_yasg\inspectors\base.py", line 42, in call_view_method
    return view_method()
  File "D:\Jafar\AAD\.env\lib\site-packages\rest_framework\generics.py", line 63, in get_queryset
    assert self.queryset is not None, (
AssertionError: 'UpdateUserDetails' should either include a `queryset` attribute, or override the `get_queryset()` method.
view's UpdateUserDetails raised exception during schema generation; use `getattr(self, 'swagger_fake_view', False)` to detect and short-circuit this
Traceback (most recent call last):
  File "D:\Jafar\AAD\.env\lib\site-packages\drf_yasg\inspectors\base.py", line 42, in call_view_method
    return view_method()
  File "D:\Jafar\AAD\.env\lib\site-packages\rest_framework\generics.py", line 63, in get_queryset
    assert self.queryset is not None, (
AssertionError: 'UpdateUserDetails' should either include a `queryset` attribute, or override the `get_queryset()` method.
view's UpdateUserDetails raised exception during schema generation; use `getattr(self, 'swagger_fake_view', False)` to detect and short-circuit this
Traceback (most recent call last):
  File "D:\Jafar\AAD\.env\lib\site-packages\drf_yasg\inspectors\base.py", line 42, in call_view_method
    return view_method()
  File "D:\Jafar\AAD\.env\lib\site-packages\rest_framework\generics.py", line 63, in get_queryset
    assert self.queryset is not None, (
AssertionError: 'UpdateUserDetails' should either include a `queryset` attribute, or override the `get_queryset()` method.
view's UpdateUserDetails raised exception during schema generation; use `getattr(self, 'swagger_fake_view', False)` to detect and short-circuit this
Traceback (most recent call last):
  File "D:\Jafar\AAD\.env\lib\site-packages\drf_yasg\inspectors\base.py", line 42, in call_view_method
    return view_method()
  File "D:\Jafar\AAD\.env\lib\site-packages\rest_framework\generics.py", line 63, in get_queryset
    assert self.queryset is not None, (
AssertionError: 'UpdateUserDetails' should either include a `queryset` attribute, or override the `get_queryset()` method.
view's DownloadHealthpostwiseUserList raised exception during schema generation; use `getattr(self, 'swagger_fake_view', False)` to detect and short-circuit this
Traceback (most recent call last):
  File "D:\Jafar\AAD\.env\lib\site-packages\drf_yasg\inspectors\base.py", line 42, in call_view_method
    return view_method()
  File "D:\Jafar\AAD\.env\lib\site-packages\rest_framework\generics.py", line 108, in get_serializer
    serializer_class = self.get_serializer_class()
  File "D:\Jafar\AAD\.env\lib\site-packages\rest_framework\generics.py", line 122, in get_serializer_class
    assert self.serializer_class is not None, (
AssertionError: 'DownloadHealthpostwiseUserList' should either include a `serializer_class` attribute, or override the `get_serializer_class()` method.
Internal Server Error: /adminportal/api/DownloadHealthpostwiseUserList/5
Traceback (most recent call last):
  File "D:\Jafar\AAD\.env\lib\site-packages\asgiref\sync.py", line 534, in thread_handler
    raise exc_info[1]
  File "D:\Jafar\AAD\.env\lib\site-packages\django\core\handlers\exception.py", line 42, in inner
    response = await get_response(request)
  File "D:\Jafar\AAD\.env\lib\site-packages\django\core\handlers\base.py", line 253, in _get_response_async
    response = await wrapped_callback(
  File "D:\Jafar\AAD\.env\lib\site-packages\asgiref\sync.py", line 479, in __call__
    ret: _R = await loop.run_in_executor(
  File "C:\Program Files\WindowsApps\PythonSoftwareFoundation.Python.3.10_3.10.3056.0_x64__qbz5n2kfra8p0\lib\concurrent\futures\thread.py", line 58, in run
    result = self.fn(*self.args, **self.kwargs)
  File "D:\Jafar\AAD\.env\lib\site-packages\asgiref\sync.py", line 538, in thread_handler
    return func(*args, **kwargs)
  File "D:\Jafar\AAD\.env\lib\site-packages\django\views\decorators\csrf.py", line 56, in wrapper_view
    return view_func(*args, **kwargs)
  File "D:\Jafar\AAD\.env\lib\site-packages\django\views\generic\base.py", line 104, in view
    return self.dispatch(request, *args, **kwargs)
  File "D:\Jafar\AAD\.env\lib\site-packages\rest_framework\views.py", line 511, in dispatch
    self.response = self.finalize_response(request, response, *args, **kwargs)
  File "D:\Jafar\AAD\.env\lib\site-packages\rest_framework\views.py", line 423, in finalize_response
    assert isinstance(response, HttpResponseBase), (
AssertionError: Expected a `Response`, `HttpResponse` or `HttpStreamingResponse` to be returned from the view, but received a `<class 'NoneType'>`
[35;1mHTTP GET /adminportal/api/DownloadHealthpostwiseUserList/5 500 [0.21, 127.0.0.1:58566][0m
Internal Server Error: /adminportal/api/DownloadHealthpostwiseUserList/5
Traceback (most recent call last):
  File "D:\Jafar\AAD\.env\lib\site-packages\asgiref\sync.py", line 534, in thread_handler
    raise exc_info[1]
  File "D:\Jafar\AAD\.env\lib\site-packages\django\core\handlers\exception.py", line 42, in inner
    response = await get_response(request)
  File "D:\Jafar\AAD\.env\lib\site-packages\django\core\handlers\base.py", line 253, in _get_response_async
    response = await wrapped_callback(
  File "D:\Jafar\AAD\.env\lib\site-packages\asgiref\sync.py", line 479, in __call__
    ret: _R = await loop.run_in_executor(
  File "C:\Program Files\WindowsApps\PythonSoftwareFoundation.Python.3.10_3.10.3056.0_x64__qbz5n2kfra8p0\lib\concurrent\futures\thread.py", line 58, in run
    result = self.fn(*self.args, **self.kwargs)
  File "D:\Jafar\AAD\.env\lib\site-packages\asgiref\sync.py", line 538, in thread_handler
    return func(*args, **kwargs)
  File "D:\Jafar\AAD\.env\lib\site-packages\django\views\decorators\csrf.py", line 56, in wrapper_view
    return view_func(*args, **kwargs)
  File "D:\Jafar\AAD\.env\lib\site-packages\django\views\generic\base.py", line 104, in view
    return self.dispatch(request, *args, **kwargs)
  File "D:\Jafar\AAD\.env\lib\site-packages\rest_framework\views.py", line 509, in dispatch
    response = self.handle_exception(exc)
  File "D:\Jafar\AAD\.env\lib\site-packages\rest_framework\views.py", line 469, in handle_exception
    self.raise_uncaught_exception(exc)
  File "D:\Jafar\AAD\.env\lib\site-packages\rest_framework\views.py", line 480, in raise_uncaught_exception
    raise exc
  File "D:\Jafar\AAD\.env\lib\site-packages\rest_framework\views.py", line 506, in dispatch
    response = handler(request, *args, **kwargs)
  File "D:\Jafar\AAD\adminportal\views.py", line 204, in get
    i.ASHA_CHV.name , i.aadharCard , i.abhaId
AttributeError: 'NoneType' object has no attribute 'name'
[35;1mHTTP GET /adminportal/api/DownloadHealthpostwiseUserList/5 500 [0.22, 127.0.0.1:59083][0m
Internal Server Error: /adminportal/api/DownloadHealthpostwiseUserList/5
Traceback (most recent call last):
  File "D:\Jafar\AAD\.env\lib\site-packages\asgiref\sync.py", line 534, in thread_handler
    raise exc_info[1]
  File "D:\Jafar\AAD\.env\lib\site-packages\django\core\handlers\exception.py", line 42, in inner
    response = await get_response(request)
  File "D:\Jafar\AAD\.env\lib\site-packages\django\core\handlers\base.py", line 253, in _get_response_async
    response = await wrapped_callback(
  File "D:\Jafar\AAD\.env\lib\site-packages\asgiref\sync.py", line 479, in __call__
    ret: _R = await loop.run_in_executor(
  File "C:\Program Files\WindowsApps\PythonSoftwareFoundation.Python.3.10_3.10.3056.0_x64__qbz5n2kfra8p0\lib\concurrent\futures\thread.py", line 58, in run
    result = self.fn(*self.args, **self.kwargs)
  File "D:\Jafar\AAD\.env\lib\site-packages\asgiref\sync.py", line 538, in thread_handler
    return func(*args, **kwargs)
  File "D:\Jafar\AAD\.env\lib\site-packages\django\views\decorators\csrf.py", line 56, in wrapper_view
    return view_func(*args, **kwargs)
  File "D:\Jafar\AAD\.env\lib\site-packages\django\views\generic\base.py", line 104, in view
    return self.dispatch(request, *args, **kwargs)
  File "D:\Jafar\AAD\.env\lib\site-packages\rest_framework\views.py", line 509, in dispatch
    response = self.handle_exception(exc)
  File "D:\Jafar\AAD\.env\lib\site-packages\rest_framework\views.py", line 469, in handle_exception
    self.raise_uncaught_exception(exc)
  File "D:\Jafar\AAD\.env\lib\site-packages\rest_framework\views.py", line 480, in raise_uncaught_exception
    raise exc
  File "D:\Jafar\AAD\.env\lib\site-packages\rest_framework\views.py", line 506, in dispatch
    response = handler(request, *args, **kwargs)
  File "D:\Jafar\AAD\adminportal\views.py", line 204, in get
    i.ASHA_CHV.username , i.aadharCard , i.abhaId
AttributeError: 'NoneType' object has no attribute 'username'
[35;1mHTTP GET /adminportal/api/DownloadHealthpostwiseUserList/5 500 [0.17, 127.0.0.1:59138][0m
Internal Server Error: /adminportal/api/DownloadHealthpostwiseUserList/5
Traceback (most recent call last):
  File "D:\Jafar\AAD\.env\lib\site-packages\asgiref\sync.py", line 534, in thread_handler
    raise exc_info[1]
  File "D:\Jafar\AAD\.env\lib\site-packages\django\core\handlers\exception.py", line 42, in inner
    response = await get_response(request)
  File "D:\Jafar\AAD\.env\lib\site-packages\django\core\handlers\base.py", line 253, in _get_response_async
    response = await wrapped_callback(
  File "D:\Jafar\AAD\.env\lib\site-packages\asgiref\sync.py", line 479, in __call__
    ret: _R = await loop.run_in_executor(
  File "C:\Program Files\WindowsApps\PythonSoftwareFoundation.Python.3.10_3.10.3056.0_x64__qbz5n2kfra8p0\lib\concurrent\futures\thread.py", line 58, in run
    result = self.fn(*self.args, **self.kwargs)
  File "D:\Jafar\AAD\.env\lib\site-packages\asgiref\sync.py", line 538, in thread_handler
    return func(*args, **kwargs)
  File "D:\Jafar\AAD\.env\lib\site-packages\django\views\decorators\csrf.py", line 56, in wrapper_view
    return view_func(*args, **kwargs)
  File "D:\Jafar\AAD\.env\lib\site-packages\django\views\generic\base.py", line 104, in view
    return self.dispatch(request, *args, **kwargs)
  File "D:\Jafar\AAD\.env\lib\site-packages\rest_framework\views.py", line 509, in dispatch
    response = self.handle_exception(exc)
  File "D:\Jafar\AAD\.env\lib\site-packages\rest_framework\views.py", line 469, in handle_exception
    self.raise_uncaught_exception(exc)
  File "D:\Jafar\AAD\.env\lib\site-packages\rest_framework\views.py", line 480, in raise_uncaught_exception
    raise exc
  File "D:\Jafar\AAD\.env\lib\site-packages\rest_framework\views.py", line 506, in dispatch
    response = handler(request, *args, **kwargs)
  File "D:\Jafar\AAD\adminportal\views.py", line 210, in get
    ws.append(row)
  File "D:\Jafar\AAD\.env\lib\site-packages\openpyxl\worksheet\worksheet.py", line 670, in append
    cell = Cell(self, row=row_idx, column=col_idx, value=content)
  File "D:\Jafar\AAD\.env\lib\site-packages\openpyxl\cell\cell.py", line 119, in __init__
    self.value = value
  File "D:\Jafar\AAD\.env\lib\site-packages\openpyxl\cell\cell.py", line 218, in value
    self._bind_value(value)
  File "D:\Jafar\AAD\.env\lib\site-packages\openpyxl\cell\cell.py", line 187, in _bind_value
    raise ValueError("Cannot convert {0!r} to Excel".format(value))
ValueError: Cannot convert <area: area object (1079)> to Excel
[35;1mHTTP GET /adminportal/api/DownloadHealthpostwiseUserList/5 500 [0.34, 127.0.0.1:59164][0m
Internal Server Error: /adminportal/api/DownloadHealthpostwiseUserList/5
Traceback (most recent call last):
  File "D:\Jafar\AAD\.env\lib\site-packages\asgiref\sync.py", line 534, in thread_handler
    raise exc_info[1]
  File "D:\Jafar\AAD\.env\lib\site-packages\django\core\handlers\exception.py", line 42, in inner
    response = await get_response(request)
  File "D:\Jafar\AAD\.env\lib\site-packages\django\core\handlers\base.py", line 253, in _get_response_async
    response = await wrapped_callback(
  File "D:\Jafar\AAD\.env\lib\site-packages\asgiref\sync.py", line 479, in __call__
    ret: _R = await loop.run_in_executor(
  File "C:\Program Files\WindowsApps\PythonSoftwareFoundation.Python.3.10_3.10.3056.0_x64__qbz5n2kfra8p0\lib\concurrent\futures\thread.py", line 58, in run
    result = self.fn(*self.args, **self.kwargs)
  File "D:\Jafar\AAD\.env\lib\site-packages\asgiref\sync.py", line 538, in thread_handler
    return func(*args, **kwargs)
  File "D:\Jafar\AAD\.env\lib\site-packages\django\views\decorators\csrf.py", line 56, in wrapper_view
    return view_func(*args, **kwargs)
  File "D:\Jafar\AAD\.env\lib\site-packages\django\views\generic\base.py", line 104, in view
    return self.dispatch(request, *args, **kwargs)
  File "D:\Jafar\AAD\.env\lib\site-packages\rest_framework\views.py", line 509, in dispatch
    response = self.handle_exception(exc)
  File "D:\Jafar\AAD\.env\lib\site-packages\rest_framework\views.py", line 469, in handle_exception
    self.raise_uncaught_exception(exc)
  File "D:\Jafar\AAD\.env\lib\site-packages\rest_framework\views.py", line 480, in raise_uncaught_exception
    raise exc
  File "D:\Jafar\AAD\.env\lib\site-packages\rest_framework\views.py", line 506, in dispatch
    response = handler(request, *args, **kwargs)
  File "D:\Jafar\AAD\adminportal\views.py", line 203, in get
    i.name , i.memberId , i.mobileNo, i.area.areas, i.age , i.familyHead.name , i.familySurveyor.name ,
AttributeError: 'NoneType' object has no attribute 'areas'
[35;1mHTTP GET /adminportal/api/DownloadHealthpostwiseUserList/5 500 [0.24, 127.0.0.1:59182][0m
view's UpdateUserDetails raised exception during schema generation; use `getattr(self, 'swagger_fake_view', False)` to detect and short-circuit this
Traceback (most recent call last):
  File "D:\Jafar\AAD\.env\lib\site-packages\drf_yasg\inspectors\base.py", line 42, in call_view_method
    return view_method()
  File "D:\Jafar\AAD\.env\lib\site-packages\rest_framework\generics.py", line 63, in get_queryset
    assert self.queryset is not None, (
AssertionError: 'UpdateUserDetails' should either include a `queryset` attribute, or override the `get_queryset()` method.
view's DownloadHealthpostwiseUserList raised exception during schema generation; use `getattr(self, 'swagger_fake_view', False)` to detect and short-circuit this
Traceback (most recent call last):
  File "D:\Jafar\AAD\.env\lib\site-packages\drf_yasg\inspectors\base.py", line 42, in call_view_method
    return view_method()
  File "D:\Jafar\AAD\.env\lib\site-packages\rest_framework\generics.py", line 108, in get_serializer
    serializer_class = self.get_serializer_class()
  File "D:\Jafar\AAD\.env\lib\site-packages\rest_framework\generics.py", line 122, in get_serializer_class
    assert self.serializer_class is not None, (
AssertionError: 'DownloadHealthpostwiseUserList' should either include a `serializer_class` attribute, or override the `get_serializer_class()` method.
view's UpdateUserDetails raised exception during schema generation; use `getattr(self, 'swagger_fake_view', False)` to detect and short-circuit this
Traceback (most recent call last):
  File "D:\Jafar\AAD\.env\lib\site-packages\drf_yasg\inspectors\base.py", line 42, in call_view_method
    return view_method()
  File "D:\Jafar\AAD\.env\lib\site-packages\rest_framework\generics.py", line 63, in get_queryset
    assert self.queryset is not None, (
AssertionError: 'UpdateUserDetails' should either include a `queryset` attribute, or override the `get_queryset()` method.
view's DownloadHealthpostwiseUserList raised exception during schema generation; use `getattr(self, 'swagger_fake_view', False)` to detect and short-circuit this
Traceback (most recent call last):
  File "D:\Jafar\AAD\.env\lib\site-packages\drf_yasg\inspectors\base.py", line 42, in call_view_method
    return view_method()
  File "D:\Jafar\AAD\.env\lib\site-packages\rest_framework\generics.py", line 108, in get_serializer
    serializer_class = self.get_serializer_class()
  File "D:\Jafar\AAD\.env\lib\site-packages\rest_framework\generics.py", line 122, in get_serializer_class
    assert self.serializer_class is not None, (
AssertionError: 'DownloadHealthpostwiseUserList' should either include a `serializer_class` attribute, or override the `get_serializer_class()` method.
Internal Server Error: /adminportal/api/DownloadHealthpostwiseUserList/6
Traceback (most recent call last):
  File "D:\Jafar\AAD\.env\lib\site-packages\asgiref\sync.py", line 534, in thread_handler
    raise exc_info[1]
  File "D:\Jafar\AAD\.env\lib\site-packages\django\core\handlers\exception.py", line 42, in inner
    response = await get_response(request)
  File "D:\Jafar\AAD\.env\lib\site-packages\django\core\handlers\base.py", line 253, in _get_response_async
    response = await wrapped_callback(
  File "D:\Jafar\AAD\.env\lib\site-packages\asgiref\sync.py", line 479, in __call__
    ret: _R = await loop.run_in_executor(
  File "C:\Program Files\WindowsApps\PythonSoftwareFoundation.Python.3.10_3.10.3056.0_x64__qbz5n2kfra8p0\lib\concurrent\futures\thread.py", line 58, in run
    result = self.fn(*self.args, **self.kwargs)
  File "D:\Jafar\AAD\.env\lib\site-packages\asgiref\sync.py", line 538, in thread_handler
    return func(*args, **kwargs)
  File "D:\Jafar\AAD\.env\lib\site-packages\django\views\decorators\csrf.py", line 56, in wrapper_view
    return view_func(*args, **kwargs)
  File "D:\Jafar\AAD\.env\lib\site-packages\django\views\generic\base.py", line 104, in view
    return self.dispatch(request, *args, **kwargs)
  File "D:\Jafar\AAD\.env\lib\site-packages\rest_framework\views.py", line 509, in dispatch
    response = self.handle_exception(exc)
  File "D:\Jafar\AAD\.env\lib\site-packages\rest_framework\views.py", line 469, in handle_exception
    self.raise_uncaught_exception(exc)
  File "D:\Jafar\AAD\.env\lib\site-packages\rest_framework\views.py", line 480, in raise_uncaught_exception
    raise exc
  File "D:\Jafar\AAD\.env\lib\site-packages\rest_framework\views.py", line 506, in dispatch
    response = handler(request, *args, **kwargs)
  File "D:\Jafar\AAD\adminportal\views.py", line 210, in get
    ws.append(row)
  File "D:\Jafar\AAD\.env\lib\site-packages\openpyxl\worksheet\worksheet.py", line 670, in append
    cell = Cell(self, row=row_idx, column=col_idx, value=content)
  File "D:\Jafar\AAD\.env\lib\site-packages\openpyxl\cell\cell.py", line 119, in __init__
    self.value = value
  File "D:\Jafar\AAD\.env\lib\site-packages\openpyxl\cell\cell.py", line 218, in value
    self._bind_value(value)
  File "D:\Jafar\AAD\.env\lib\site-packages\openpyxl\cell\cell.py", line 187, in _bind_value
    raise ValueError("Cannot convert {0!r} to Excel".format(value))
ValueError: Cannot convert <CustomUser: 8655146219> to Excel
[35;1mHTTP GET /adminportal/api/DownloadHealthpostwiseUserList/6 500 [0.23, 127.0.0.1:59906][0m
view's UpdateUserDetails raised exception during schema generation; use `getattr(self, 'swagger_fake_view', False)` to detect and short-circuit this
Traceback (most recent call last):
  File "D:\Jafar\AAD\.env\lib\site-packages\drf_yasg\inspectors\base.py", line 42, in call_view_method
    return view_method()
  File "D:\Jafar\AAD\.env\lib\site-packages\rest_framework\generics.py", line 63, in get_queryset
    assert self.queryset is not None, (
AssertionError: 'UpdateUserDetails' should either include a `queryset` attribute, or override the `get_queryset()` method.
view's DownloadHealthpostwiseUserList raised exception during schema generation; use `getattr(self, 'swagger_fake_view', False)` to detect and short-circuit this
Traceback (most recent call last):
  File "D:\Jafar\AAD\.env\lib\site-packages\drf_yasg\inspectors\base.py", line 42, in call_view_method
    return view_method()
  File "D:\Jafar\AAD\.env\lib\site-packages\rest_framework\generics.py", line 108, in get_serializer
    serializer_class = self.get_serializer_class()
  File "D:\Jafar\AAD\.env\lib\site-packages\rest_framework\generics.py", line 122, in get_serializer_class
    assert self.serializer_class is not None, (
AssertionError: 'DownloadHealthpostwiseUserList' should either include a `serializer_class` attribute, or override the `get_serializer_class()` method.
view's DownloadWardtwiseUserList raised exception during schema generation; use `getattr(self, 'swagger_fake_view', False)` to detect and short-circuit this
Traceback (most recent call last):
  File "D:\Jafar\AAD\.env\lib\site-packages\drf_yasg\inspectors\base.py", line 42, in call_view_method
    return view_method()
  File "D:\Jafar\AAD\.env\lib\site-packages\rest_framework\generics.py", line 108, in get_serializer
    serializer_class = self.get_serializer_class()
  File "D:\Jafar\AAD\.env\lib\site-packages\rest_framework\generics.py", line 122, in get_serializer_class
    assert self.serializer_class is not None, (
AssertionError: 'DownloadWardtwiseUserList' should either include a `serializer_class` attribute, or override the `get_serializer_class()` method.
Unauthorized: /adminportal/api/DownloadWardtwiseUserList/10
[31;1mHTTP GET /adminportal/api/DownloadWardtwiseUserList/10 401 [0.01, 127.0.0.1:61807][0m
view's UpdateUserDetails raised exception during schema generation; use `getattr(self, 'swagger_fake_view', False)` to detect and short-circuit this
Traceback (most recent call last):
  File "D:\Jafar\AAD\.env\lib\site-packages\drf_yasg\inspectors\base.py", line 42, in call_view_method
    return view_method()
  File "D:\Jafar\AAD\.env\lib\site-packages\rest_framework\generics.py", line 63, in get_queryset
    assert self.queryset is not None, (
AssertionError: 'UpdateUserDetails' should either include a `queryset` attribute, or override the `get_queryset()` method.
view's DownloadDispensarywiseUserList raised exception during schema generation; use `getattr(self, 'swagger_fake_view', False)` to detect and short-circuit this
Traceback (most recent call last):
  File "D:\Jafar\AAD\.env\lib\site-packages\drf_yasg\inspectors\base.py", line 42, in call_view_method
    return view_method()
  File "D:\Jafar\AAD\.env\lib\site-packages\rest_framework\generics.py", line 108, in get_serializer
    serializer_class = self.get_serializer_class()
  File "D:\Jafar\AAD\.env\lib\site-packages\rest_framework\generics.py", line 122, in get_serializer_class
    assert self.serializer_class is not None, (
AssertionError: 'DownloadDispensarywiseUserList' should either include a `serializer_class` attribute, or override the `get_serializer_class()` method.
view's DownloadHealthpostwiseUserList raised exception during schema generation; use `getattr(self, 'swagger_fake_view', False)` to detect and short-circuit this
Traceback (most recent call last):
  File "D:\Jafar\AAD\.env\lib\site-packages\drf_yasg\inspectors\base.py", line 42, in call_view_method
    return view_method()
  File "D:\Jafar\AAD\.env\lib\site-packages\rest_framework\generics.py", line 108, in get_serializer
    serializer_class = self.get_serializer_class()
  File "D:\Jafar\AAD\.env\lib\site-packages\rest_framework\generics.py", line 122, in get_serializer_class
    assert self.serializer_class is not None, (
AssertionError: 'DownloadHealthpostwiseUserList' should either include a `serializer_class` attribute, or override the `get_serializer_class()` method.
view's DownloadWardwiseUserList raised exception during schema generation; use `getattr(self, 'swagger_fake_view', False)` to detect and short-circuit this
Traceback (most recent call last):
  File "D:\Jafar\AAD\.env\lib\site-packages\drf_yasg\inspectors\base.py", line 42, in call_view_method
    return view_method()
  File "D:\Jafar\AAD\.env\lib\site-packages\rest_framework\generics.py", line 108, in get_serializer
    serializer_class = self.get_serializer_class()
  File "D:\Jafar\AAD\.env\lib\site-packages\rest_framework\generics.py", line 122, in get_serializer_class
    assert self.serializer_class is not None, (
AssertionError: 'DownloadWardwiseUserList' should either include a `serializer_class` attribute, or override the `get_serializer_class()` method.
Internal Server Error: /adminportal/api/DownloadDispensarywiseUserList/4
Traceback (most recent call last):
  File "D:\Jafar\AAD\.env\lib\site-packages\asgiref\sync.py", line 534, in thread_handler
    raise exc_info[1]
  File "D:\Jafar\AAD\.env\lib\site-packages\django\core\handlers\exception.py", line 42, in inner
    response = await get_response(request)
  File "D:\Jafar\AAD\.env\lib\site-packages\django\core\handlers\base.py", line 253, in _get_response_async
    response = await wrapped_callback(
  File "D:\Jafar\AAD\.env\lib\site-packages\asgiref\sync.py", line 479, in __call__
    ret: _R = await loop.run_in_executor(
  File "C:\Program Files\WindowsApps\PythonSoftwareFoundation.Python.3.10_3.10.3056.0_x64__qbz5n2kfra8p0\lib\concurrent\futures\thread.py", line 58, in run
    result = self.fn(*self.args, **self.kwargs)
  File "D:\Jafar\AAD\.env\lib\site-packages\asgiref\sync.py", line 538, in thread_handler
    return func(*args, **kwargs)
  File "D:\Jafar\AAD\.env\lib\site-packages\django\views\decorators\csrf.py", line 56, in wrapper_view
    return view_func(*args, **kwargs)
  File "D:\Jafar\AAD\.env\lib\site-packages\django\views\generic\base.py", line 104, in view
    return self.dispatch(request, *args, **kwargs)
  File "D:\Jafar\AAD\.env\lib\site-packages\rest_framework\views.py", line 509, in dispatch
    response = self.handle_exception(exc)
  File "D:\Jafar\AAD\.env\lib\site-packages\rest_framework\views.py", line 469, in handle_exception
    self.raise_uncaught_exception(exc)
  File "D:\Jafar\AAD\.env\lib\site-packages\rest_framework\views.py", line 480, in raise_uncaught_exception
    raise exc
  File "D:\Jafar\AAD\.env\lib\site-packages\rest_framework\views.py", line 506, in dispatch
    response = handler(request, *args, **kwargs)
  File "D:\Jafar\AAD\adminportal\views.py", line 269, in get
    filename = f"{dispensary_name}"
UnboundLocalError: local variable 'dispensary_name' referenced before assignment
[35;1mHTTP GET /adminportal/api/DownloadDispensarywiseUserList/4 500 [0.11, 127.0.0.1:62767][0m
view's UpdateUserDetails raised exception during schema generation; use `getattr(self, 'swagger_fake_view', False)` to detect and short-circuit this
Traceback (most recent call last):
  File "D:\Jafar\AAD\.env\lib\site-packages\drf_yasg\inspectors\base.py", line 42, in call_view_method
    return view_method()
  File "D:\Jafar\AAD\.env\lib\site-packages\rest_framework\generics.py", line 63, in get_queryset
    assert self.queryset is not None, (
AssertionError: 'UpdateUserDetails' should either include a `queryset` attribute, or override the `get_queryset()` method.
view's DownloadDispensarywiseUserList raised exception during schema generation; use `getattr(self, 'swagger_fake_view', False)` to detect and short-circuit this
Traceback (most recent call last):
  File "D:\Jafar\AAD\.env\lib\site-packages\drf_yasg\inspectors\base.py", line 42, in call_view_method
    return view_method()
  File "D:\Jafar\AAD\.env\lib\site-packages\rest_framework\generics.py", line 108, in get_serializer
    serializer_class = self.get_serializer_class()
  File "D:\Jafar\AAD\.env\lib\site-packages\rest_framework\generics.py", line 122, in get_serializer_class
    assert self.serializer_class is not None, (
AssertionError: 'DownloadDispensarywiseUserList' should either include a `serializer_class` attribute, or override the `get_serializer_class()` method.
view's DownloadHealthpostwiseUserList raised exception during schema generation; use `getattr(self, 'swagger_fake_view', False)` to detect and short-circuit this
Traceback (most recent call last):
  File "D:\Jafar\AAD\.env\lib\site-packages\drf_yasg\inspectors\base.py", line 42, in call_view_method
    return view_method()
  File "D:\Jafar\AAD\.env\lib\site-packages\rest_framework\generics.py", line 108, in get_serializer
    serializer_class = self.get_serializer_class()
  File "D:\Jafar\AAD\.env\lib\site-packages\rest_framework\generics.py", line 122, in get_serializer_class
    assert self.serializer_class is not None, (
AssertionError: 'DownloadHealthpostwiseUserList' should either include a `serializer_class` attribute, or override the `get_serializer_class()` method.
view's DownloadWardwiseUserList raised exception during schema generation; use `getattr(self, 'swagger_fake_view', False)` to detect and short-circuit this
Traceback (most recent call last):
  File "D:\Jafar\AAD\.env\lib\site-packages\drf_yasg\inspectors\base.py", line 42, in call_view_method
    return view_method()
  File "D:\Jafar\AAD\.env\lib\site-packages\rest_framework\generics.py", line 108, in get_serializer
    serializer_class = self.get_serializer_class()
  File "D:\Jafar\AAD\.env\lib\site-packages\rest_framework\generics.py", line 122, in get_serializer_class
    assert self.serializer_class is not None, (
AssertionError: 'DownloadWardwiseUserList' should either include a `serializer_class` attribute, or override the `get_serializer_class()` method.
Unauthorized: /healthworker/api/GetSurveyorDashboard
[31;1mHTTP GET /healthworker/api/GetSurveyorDashboard 401 [0.01, 127.0.0.1:52391][0m
Internal Server Error: /healthworker/api/GetSurveyorDashboard
Traceback (most recent call last):
  File "D:\Jafar\AAD\.env\lib\site-packages\django\db\models\fields\__init__.py", line 2053, in get_prep_value
    return int(value)
  File "D:\Jafar\AAD\.env\lib\site-packages\django\contrib\auth\models.py", line 437, in __int__
    raise TypeError(
TypeError: Cannot cast AnonymousUser to int. Are you trying to use it in place of User?

The above exception was the direct cause of the following exception:

Traceback (most recent call last):
  File "D:\Jafar\AAD\.env\lib\site-packages\asgiref\sync.py", line 534, in thread_handler
    raise exc_info[1]
  File "D:\Jafar\AAD\.env\lib\site-packages\django\core\handlers\exception.py", line 42, in inner
    response = await get_response(request)
  File "D:\Jafar\AAD\.env\lib\site-packages\django\core\handlers\base.py", line 253, in _get_response_async
    response = await wrapped_callback(
  File "D:\Jafar\AAD\.env\lib\site-packages\asgiref\sync.py", line 479, in __call__
    ret: _R = await loop.run_in_executor(
  File "C:\Program Files\WindowsApps\PythonSoftwareFoundation.Python.3.10_3.10.3056.0_x64__qbz5n2kfra8p0\lib\concurrent\futures\thread.py", line 58, in run
    result = self.fn(*self.args, **self.kwargs)
  File "D:\Jafar\AAD\.env\lib\site-packages\asgiref\sync.py", line 538, in thread_handler
    return func(*args, **kwargs)
  File "D:\Jafar\AAD\.env\lib\site-packages\django\views\decorators\csrf.py", line 56, in wrapper_view
    return view_func(*args, **kwargs)
  File "D:\Jafar\AAD\.env\lib\site-packages\django\views\generic\base.py", line 104, in view
    return self.dispatch(request, *args, **kwargs)
  File "D:\Jafar\AAD\.env\lib\site-packages\rest_framework\views.py", line 509, in dispatch
    response = self.handle_exception(exc)
  File "D:\Jafar\AAD\.env\lib\site-packages\rest_framework\views.py", line 469, in handle_exception
    self.raise_uncaught_exception(exc)
  File "D:\Jafar\AAD\.env\lib\site-packages\rest_framework\views.py", line 480, in raise_uncaught_exception
    raise exc
  File "D:\Jafar\AAD\.env\lib\site-packages\rest_framework\views.py", line 506, in dispatch
    response = handler(request, *args, **kwargs)
  File "D:\Jafar\AAD\healthworker\views.py", line 238, in get
    total_citizen_count = self.get_queryset().filter(familySurveyor = request.user).count()
  File "D:\Jafar\AAD\.env\lib\site-packages\django\db\models\query.py", line 1436, in filter
    return self._filter_or_exclude(False, args, kwargs)
  File "D:\Jafar\AAD\.env\lib\site-packages\django\db\models\query.py", line 1454, in _filter_or_exclude
    clone._filter_or_exclude_inplace(negate, args, kwargs)
  File "D:\Jafar\AAD\.env\lib\site-packages\django\db\models\query.py", line 1461, in _filter_or_exclude_inplace
    self._query.add_q(Q(*args, **kwargs))
  File "D:\Jafar\AAD\.env\lib\site-packages\django\db\models\sql\query.py", line 1545, in add_q
    clause, _ = self._add_q(q_object, self.used_aliases)
  File "D:\Jafar\AAD\.env\lib\site-packages\django\db\models\sql\query.py", line 1576, in _add_q
    child_clause, needed_inner = self.build_filter(
  File "D:\Jafar\AAD\.env\lib\site-packages\django\db\models\sql\query.py", line 1491, in build_filter
    condition = self.build_lookup(lookups, col, value)
  File "D:\Jafar\AAD\.env\lib\site-packages\django\db\models\sql\query.py", line 1318, in build_lookup
    lookup = lookup_class(lhs, rhs)
  File "D:\Jafar\AAD\.env\lib\site-packages\django\db\models\lookups.py", line 27, in __init__
    self.rhs = self.get_prep_lookup()
  File "D:\Jafar\AAD\.env\lib\site-packages\django\db\models\fields\related_lookups.py", line 166, in get_prep_lookup
    self.rhs = target_field.get_prep_value(self.rhs)
  File "D:\Jafar\AAD\.env\lib\site-packages\django\db\models\fields\__init__.py", line 2055, in get_prep_value
    raise e.__class__(
TypeError: Field 'id' expected a number but got <django.contrib.auth.models.AnonymousUser object at 0x0000013671BDAA10>.
[35;1mHTTP GET /healthworker/api/GetSurveyorDashboard 500 [0.17, 127.0.0.1:52402][0m
Not Found: /favicon.ico
[33mHTTP GET /favicon.ico 404 [0.02, 127.0.0.1:59171][0m
Not Found: /
[33mHTTP GET / 404 [0.11, 127.0.0.1:61348][0m
Not Found: /favicon.ico
[33mHTTP GET /favicon.ico 404 [0.04, 127.0.0.1:61348][0m
view's UpdateUserDetails raised exception during schema generation; use `getattr(self, 'swagger_fake_view', False)` to detect and short-circuit this
Traceback (most recent call last):
  File "D:\Jafar\AAD\.env\lib\site-packages\drf_yasg\inspectors\base.py", line 42, in call_view_method
    return view_method()
  File "D:\Jafar\AAD\.env\lib\site-packages\rest_framework\generics.py", line 63, in get_queryset
    assert self.queryset is not None, (
AssertionError: 'UpdateUserDetails' should either include a `queryset` attribute, or override the `get_queryset()` method.
view's DownloadDispensarywiseUserList raised exception during schema generation; use `getattr(self, 'swagger_fake_view', False)` to detect and short-circuit this
Traceback (most recent call last):
  File "D:\Jafar\AAD\.env\lib\site-packages\drf_yasg\inspectors\base.py", line 42, in call_view_method
    return view_method()
  File "D:\Jafar\AAD\.env\lib\site-packages\rest_framework\generics.py", line 108, in get_serializer
    serializer_class = self.get_serializer_class()
  File "D:\Jafar\AAD\.env\lib\site-packages\rest_framework\generics.py", line 122, in get_serializer_class
    assert self.serializer_class is not None, (
AssertionError: 'DownloadDispensarywiseUserList' should either include a `serializer_class` attribute, or override the `get_serializer_class()` method.
view's DownloadHealthpostwiseUserList raised exception during schema generation; use `getattr(self, 'swagger_fake_view', False)` to detect and short-circuit this
Traceback (most recent call last):
  File "D:\Jafar\AAD\.env\lib\site-packages\drf_yasg\inspectors\base.py", line 42, in call_view_method
    return view_method()
  File "D:\Jafar\AAD\.env\lib\site-packages\rest_framework\generics.py", line 108, in get_serializer
    serializer_class = self.get_serializer_class()
  File "D:\Jafar\AAD\.env\lib\site-packages\rest_framework\generics.py", line 122, in get_serializer_class
    assert self.serializer_class is not None, (
AssertionError: 'DownloadHealthpostwiseUserList' should either include a `serializer_class` attribute, or override the `get_serializer_class()` method.
view's DownloadWardwiseUserList raised exception during schema generation; use `getattr(self, 'swagger_fake_view', False)` to detect and short-circuit this
Traceback (most recent call last):
  File "D:\Jafar\AAD\.env\lib\site-packages\drf_yasg\inspectors\base.py", line 42, in call_view_method
    return view_method()
  File "D:\Jafar\AAD\.env\lib\site-packages\rest_framework\generics.py", line 108, in get_serializer
    serializer_class = self.get_serializer_class()
  File "D:\Jafar\AAD\.env\lib\site-packages\rest_framework\generics.py", line 122, in get_serializer_class
    assert self.serializer_class is not None, (
AssertionError: 'DownloadWardwiseUserList' should either include a `serializer_class` attribute, or override the `get_serializer_class()` method.
view's MOHDashboardView raised exception during schema generation; use `getattr(self, 'swagger_fake_view', False)` to detect and short-circuit this
Traceback (most recent call last):
  File "D:\Jafar\AAD\.env\lib\site-packages\drf_yasg\inspectors\base.py", line 42, in call_view_method
    return view_method()
  File "D:\Jafar\AAD\.env\lib\site-packages\rest_framework\generics.py", line 108, in get_serializer
    serializer_class = self.get_serializer_class()
  File "D:\Jafar\AAD\.env\lib\site-packages\rest_framework\generics.py", line 122, in get_serializer_class
    assert self.serializer_class is not None, (
AssertionError: 'MOHDashboardView' should either include a `serializer_class` attribute, or override the `get_serializer_class()` method.
view's UpdateUserDetails raised exception during schema generation; use `getattr(self, 'swagger_fake_view', False)` to detect and short-circuit this
Traceback (most recent call last):
  File "D:\Jafar\AAD\.env\lib\site-packages\drf_yasg\inspectors\base.py", line 42, in call_view_method
    return view_method()
  File "D:\Jafar\AAD\.env\lib\site-packages\rest_framework\generics.py", line 63, in get_queryset
    assert self.queryset is not None, (
AssertionError: 'UpdateUserDetails' should either include a `queryset` attribute, or override the `get_queryset()` method.
view's DownloadDispensarywiseUserList raised exception during schema generation; use `getattr(self, 'swagger_fake_view', False)` to detect and short-circuit this
Traceback (most recent call last):
  File "D:\Jafar\AAD\.env\lib\site-packages\drf_yasg\inspectors\base.py", line 42, in call_view_method
    return view_method()
  File "D:\Jafar\AAD\.env\lib\site-packages\rest_framework\generics.py", line 108, in get_serializer
    serializer_class = self.get_serializer_class()
  File "D:\Jafar\AAD\.env\lib\site-packages\rest_framework\generics.py", line 122, in get_serializer_class
    assert self.serializer_class is not None, (
AssertionError: 'DownloadDispensarywiseUserList' should either include a `serializer_class` attribute, or override the `get_serializer_class()` method.
view's DownloadHealthpostwiseUserList raised exception during schema generation; use `getattr(self, 'swagger_fake_view', False)` to detect and short-circuit this
Traceback (most recent call last):
  File "D:\Jafar\AAD\.env\lib\site-packages\drf_yasg\inspectors\base.py", line 42, in call_view_method
    return view_method()
  File "D:\Jafar\AAD\.env\lib\site-packages\rest_framework\generics.py", line 108, in get_serializer
    serializer_class = self.get_serializer_class()
  File "D:\Jafar\AAD\.env\lib\site-packages\rest_framework\generics.py", line 122, in get_serializer_class
    assert self.serializer_class is not None, (
AssertionError: 'DownloadHealthpostwiseUserList' should either include a `serializer_class` attribute, or override the `get_serializer_class()` method.
view's DownloadWardwiseUserList raised exception during schema generation; use `getattr(self, 'swagger_fake_view', False)` to detect and short-circuit this
Traceback (most recent call last):
  File "D:\Jafar\AAD\.env\lib\site-packages\drf_yasg\inspectors\base.py", line 42, in call_view_method
    return view_method()
  File "D:\Jafar\AAD\.env\lib\site-packages\rest_framework\generics.py", line 108, in get_serializer
    serializer_class = self.get_serializer_class()
  File "D:\Jafar\AAD\.env\lib\site-packages\rest_framework\generics.py", line 122, in get_serializer_class
    assert self.serializer_class is not None, (
AssertionError: 'DownloadWardwiseUserList' should either include a `serializer_class` attribute, or override the `get_serializer_class()` method.
view's MOHDashboardView raised exception during schema generation; use `getattr(self, 'swagger_fake_view', False)` to detect and short-circuit this
Traceback (most recent call last):
  File "D:\Jafar\AAD\.env\lib\site-packages\drf_yasg\inspectors\base.py", line 42, in call_view_method
    return view_method()
  File "D:\Jafar\AAD\.env\lib\site-packages\rest_framework\generics.py", line 108, in get_serializer
    serializer_class = self.get_serializer_class()
  File "D:\Jafar\AAD\.env\lib\site-packages\rest_framework\generics.py", line 122, in get_serializer_class
    assert self.serializer_class is not None, (
AssertionError: 'MOHDashboardView' should either include a `serializer_class` attribute, or override the `get_serializer_class()` method.
Internal Server Error: /allauth/api/login
Traceback (most recent call last):
  File "D:\Jafar\AAD\.env\lib\site-packages\asgiref\sync.py", line 534, in thread_handler
    raise exc_info[1]
  File "D:\Jafar\AAD\.env\lib\site-packages\django\core\handlers\exception.py", line 42, in inner
    response = await get_response(request)
  File "D:\Jafar\AAD\.env\lib\site-packages\django\core\handlers\base.py", line 253, in _get_response_async
    response = await wrapped_callback(
  File "D:\Jafar\AAD\.env\lib\site-packages\asgiref\sync.py", line 479, in __call__
    ret: _R = await loop.run_in_executor(
  File "C:\Program Files\WindowsApps\PythonSoftwareFoundation.Python.3.10_3.10.3056.0_x64__qbz5n2kfra8p0\lib\concurrent\futures\thread.py", line 58, in run
    result = self.fn(*self.args, **self.kwargs)
  File "D:\Jafar\AAD\.env\lib\site-packages\asgiref\sync.py", line 538, in thread_handler
    return func(*args, **kwargs)
  File "D:\Jafar\AAD\.env\lib\site-packages\django\views\decorators\csrf.py", line 56, in wrapper_view
    return view_func(*args, **kwargs)
  File "D:\Jafar\AAD\.env\lib\site-packages\django\views\generic\base.py", line 104, in view
    return self.dispatch(request, *args, **kwargs)
  File "D:\Jafar\AAD\.env\lib\site-packages\rest_framework\views.py", line 511, in dispatch
    self.response = self.finalize_response(request, response, *args, **kwargs)
  File "D:\Jafar\AAD\.env\lib\site-packages\rest_framework\views.py", line 423, in finalize_response
    assert isinstance(response, HttpResponseBase), (
AssertionError: Expected a `Response`, `HttpResponse` or `HttpStreamingResponse` to be returned from the view, but received a `<class 'NoneType'>`
[35;1mHTTP POST /allauth/api/login 500 [0.66, 127.0.0.1:61515][0m
Internal Server Error: /adminportal/api/MOHDashboardView
Traceback (most recent call last):
  File "D:\Jafar\AAD\.env\lib\site-packages\django\db\models\fields\__init__.py", line 2053, in get_prep_value
    return int(value)
TypeError: int() argument must be a string, a bytes-like object or a real number, not 'CustomUser'

The above exception was the direct cause of the following exception:

Traceback (most recent call last):
  File "D:\Jafar\AAD\.env\lib\site-packages\asgiref\sync.py", line 534, in thread_handler
    raise exc_info[1]
  File "D:\Jafar\AAD\.env\lib\site-packages\django\core\handlers\exception.py", line 42, in inner
    response = await get_response(request)
  File "D:\Jafar\AAD\.env\lib\site-packages\django\core\handlers\base.py", line 253, in _get_response_async
    response = await wrapped_callback(
  File "D:\Jafar\AAD\.env\lib\site-packages\asgiref\sync.py", line 479, in __call__
    ret: _R = await loop.run_in_executor(
  File "C:\Program Files\WindowsApps\PythonSoftwareFoundation.Python.3.10_3.10.3056.0_x64__qbz5n2kfra8p0\lib\concurrent\futures\thread.py", line 58, in run
    result = self.fn(*self.args, **self.kwargs)
  File "D:\Jafar\AAD\.env\lib\site-packages\asgiref\sync.py", line 538, in thread_handler
    return func(*args, **kwargs)
  File "D:\Jafar\AAD\.env\lib\site-packages\django\views\decorators\csrf.py", line 56, in wrapper_view
    return view_func(*args, **kwargs)
  File "D:\Jafar\AAD\.env\lib\site-packages\django\views\generic\base.py", line 104, in view
    return self.dispatch(request, *args, **kwargs)
  File "D:\Jafar\AAD\.env\lib\site-packages\rest_framework\views.py", line 509, in dispatch
    response = self.handle_exception(exc)
  File "D:\Jafar\AAD\.env\lib\site-packages\rest_framework\views.py", line 469, in handle_exception
    self.raise_uncaught_exception(exc)
  File "D:\Jafar\AAD\.env\lib\site-packages\rest_framework\views.py", line 480, in raise_uncaught_exception
    raise exc
  File "D:\Jafar\AAD\.env\lib\site-packages\rest_framework\views.py", line 506, in dispatch
    response = handler(request, *args, **kwargs)
  File "D:\Jafar\AAD\adminportal\views.py", line 205, in get
    partial_survey_count = self.FamilySurvey_count.filter(partialSubmit = True , user__section__healthPost__ward__id = request.user).count()
  File "D:\Jafar\AAD\.env\lib\site-packages\django\db\models\query.py", line 1436, in filter
    return self._filter_or_exclude(False, args, kwargs)
  File "D:\Jafar\AAD\.env\lib\site-packages\django\db\models\query.py", line 1454, in _filter_or_exclude
    clone._filter_or_exclude_inplace(negate, args, kwargs)
  File "D:\Jafar\AAD\.env\lib\site-packages\django\db\models\query.py", line 1461, in _filter_or_exclude_inplace
    self._query.add_q(Q(*args, **kwargs))
  File "D:\Jafar\AAD\.env\lib\site-packages\django\db\models\sql\query.py", line 1545, in add_q
    clause, _ = self._add_q(q_object, self.used_aliases)
  File "D:\Jafar\AAD\.env\lib\site-packages\django\db\models\sql\query.py", line 1576, in _add_q
    child_clause, needed_inner = self.build_filter(
  File "D:\Jafar\AAD\.env\lib\site-packages\django\db\models\sql\query.py", line 1491, in build_filter
    condition = self.build_lookup(lookups, col, value)
  File "D:\Jafar\AAD\.env\lib\site-packages\django\db\models\sql\query.py", line 1318, in build_lookup
    lookup = lookup_class(lhs, rhs)
  File "D:\Jafar\AAD\.env\lib\site-packages\django\db\models\lookups.py", line 27, in __init__
    self.rhs = self.get_prep_lookup()
  File "D:\Jafar\AAD\.env\lib\site-packages\django\db\models\lookups.py", line 341, in get_prep_lookup
    return super().get_prep_lookup()
  File "D:\Jafar\AAD\.env\lib\site-packages\django\db\models\lookups.py", line 85, in get_prep_lookup
    return self.lhs.output_field.get_prep_value(self.rhs)
  File "D:\Jafar\AAD\.env\lib\site-packages\django\db\models\fields\__init__.py", line 2055, in get_prep_value
    raise e.__class__(
TypeError: Field 'id' expected a number but got <CustomUser: MOH>.
[35;1mHTTP GET /adminportal/api/MOHDashboardView 500 [0.24, 127.0.0.1:62210][0m
Bad Request: /healthworker/api/PostSurveyForm
[31;1mHTTP POST /healthworker/api/PostSurveyForm 400 [0.19, 10.202.100.219:52275][0m
Bad Request: /healthworker/api/PostSurveyForm
[31;1mHTTP POST /healthworker/api/PostSurveyForm 400 [0.10, 10.202.100.219:52346][0m
Bad Request: /healthworker/api/PostSurveyForm
[31;1mHTTP POST /healthworker/api/PostSurveyForm 400 [0.13, 10.202.100.219:52452][0m
view's UpdateUserDetails raised exception during schema generation; use `getattr(self, 'swagger_fake_view', False)` to detect and short-circuit this
Traceback (most recent call last):
  File "D:\Jafar\AAD\.env\lib\site-packages\drf_yasg\inspectors\base.py", line 42, in call_view_method
    return view_method()
  File "D:\Jafar\AAD\.env\lib\site-packages\rest_framework\generics.py", line 63, in get_queryset
    assert self.queryset is not None, (
AssertionError: 'UpdateUserDetails' should either include a `queryset` attribute, or override the `get_queryset()` method.
view's DownloadDispensarywiseUserList raised exception during schema generation; use `getattr(self, 'swagger_fake_view', False)` to detect and short-circuit this
Traceback (most recent call last):
  File "D:\Jafar\AAD\.env\lib\site-packages\drf_yasg\inspectors\base.py", line 42, in call_view_method
    return view_method()
  File "D:\Jafar\AAD\.env\lib\site-packages\rest_framework\generics.py", line 108, in get_serializer
    serializer_class = self.get_serializer_class()
  File "D:\Jafar\AAD\.env\lib\site-packages\rest_framework\generics.py", line 122, in get_serializer_class
    assert self.serializer_class is not None, (
AssertionError: 'DownloadDispensarywiseUserList' should either include a `serializer_class` attribute, or override the `get_serializer_class()` method.
view's DownloadHealthpostwiseUserList raised exception during schema generation; use `getattr(self, 'swagger_fake_view', False)` to detect and short-circuit this
Traceback (most recent call last):
  File "D:\Jafar\AAD\.env\lib\site-packages\drf_yasg\inspectors\base.py", line 42, in call_view_method
    return view_method()
  File "D:\Jafar\AAD\.env\lib\site-packages\rest_framework\generics.py", line 108, in get_serializer
    serializer_class = self.get_serializer_class()
  File "D:\Jafar\AAD\.env\lib\site-packages\rest_framework\generics.py", line 122, in get_serializer_class
    assert self.serializer_class is not None, (
AssertionError: 'DownloadHealthpostwiseUserList' should either include a `serializer_class` attribute, or override the `get_serializer_class()` method.
view's DownloadWardwiseUserList raised exception during schema generation; use `getattr(self, 'swagger_fake_view', False)` to detect and short-circuit this
Traceback (most recent call last):
  File "D:\Jafar\AAD\.env\lib\site-packages\drf_yasg\inspectors\base.py", line 42, in call_view_method
    return view_method()
  File "D:\Jafar\AAD\.env\lib\site-packages\rest_framework\generics.py", line 108, in get_serializer
    serializer_class = self.get_serializer_class()
  File "D:\Jafar\AAD\.env\lib\site-packages\rest_framework\generics.py", line 122, in get_serializer_class
    assert self.serializer_class is not None, (
AssertionError: 'DownloadWardwiseUserList' should either include a `serializer_class` attribute, or override the `get_serializer_class()` method.
view's MOHDashboardView raised exception during schema generation; use `getattr(self, 'swagger_fake_view', False)` to detect and short-circuit this
Traceback (most recent call last):
  File "D:\Jafar\AAD\.env\lib\site-packages\drf_yasg\inspectors\base.py", line 42, in call_view_method
    return view_method()
  File "D:\Jafar\AAD\.env\lib\site-packages\rest_framework\generics.py", line 108, in get_serializer
    serializer_class = self.get_serializer_class()
  File "D:\Jafar\AAD\.env\lib\site-packages\rest_framework\generics.py", line 122, in get_serializer_class
    assert self.serializer_class is not None, (
AssertionError: 'MOHDashboardView' should either include a `serializer_class` attribute, or override the `get_serializer_class()` method.
Bad Request: /allauth/api/login
[31;1mHTTP POST /allauth/api/login 400 [0.66, 127.0.0.1:64188][0m
Internal Server Error: /allauth/api/login
Traceback (most recent call last):
  File "D:\Jafar\AAD\.env\lib\site-packages\asgiref\sync.py", line 534, in thread_handler
    raise exc_info[1]
  File "D:\Jafar\AAD\.env\lib\site-packages\django\core\handlers\exception.py", line 42, in inner
    response = await get_response(request)
  File "D:\Jafar\AAD\.env\lib\site-packages\django\core\handlers\base.py", line 253, in _get_response_async
    response = await wrapped_callback(
  File "D:\Jafar\AAD\.env\lib\site-packages\asgiref\sync.py", line 479, in __call__
    ret: _R = await loop.run_in_executor(
  File "C:\Program Files\WindowsApps\PythonSoftwareFoundation.Python.3.10_3.10.3056.0_x64__qbz5n2kfra8p0\lib\concurrent\futures\thread.py", line 58, in run
    result = self.fn(*self.args, **self.kwargs)
  File "D:\Jafar\AAD\.env\lib\site-packages\asgiref\sync.py", line 538, in thread_handler
    return func(*args, **kwargs)
  File "D:\Jafar\AAD\.env\lib\site-packages\django\views\decorators\csrf.py", line 56, in wrapper_view
    return view_func(*args, **kwargs)
  File "D:\Jafar\AAD\.env\lib\site-packages\django\views\generic\base.py", line 104, in view
    return self.dispatch(request, *args, **kwargs)
  File "D:\Jafar\AAD\.env\lib\site-packages\rest_framework\views.py", line 509, in dispatch
    response = self.handle_exception(exc)
  File "D:\Jafar\AAD\.env\lib\site-packages\rest_framework\views.py", line 469, in handle_exception
    self.raise_uncaught_exception(exc)
  File "D:\Jafar\AAD\.env\lib\site-packages\rest_framework\views.py", line 480, in raise_uncaught_exception
    raise exc
  File "D:\Jafar\AAD\.env\lib\site-packages\rest_framework\views.py", line 506, in dispatch
    response = handler(request, *args, **kwargs)
  File "D:\Jafar\AAD\Allauth\views.py", line 1040, in post
    if serializer.is_valid():
  File "D:\Jafar\AAD\.env\lib\site-packages\rest_framework\serializers.py", line 227, in is_valid
    self._validated_data = self.run_validation(self.initial_data)
  File "D:\Jafar\AAD\.env\lib\site-packages\rest_framework\serializers.py", line 430, in run_validation
    assert value is not None, '.validate() should return the validated data'
AssertionError: .validate() should return the validated data
[35;1mHTTP POST /allauth/api/login 500 [0.36, 127.0.0.1:64230][0m
Bad Request: /allauth/api/login
[31;1mHTTP POST /allauth/api/login 400 [0.25, 127.0.0.1:64344][0m
Bad Request: /allauth/api/login
[31;1mHTTP POST /allauth/api/login 400 [0.33, 127.0.0.1:64368][0m
Bad Request: /allauth/api/login
[31;1mHTTP POST /allauth/api/login 400 [0.31, 127.0.0.1:64368][0m
Bad Request: /adminportal/api/AdminChangePasswordView/1004
[31;1mHTTP PATCH /adminportal/api/AdminChangePasswordView/1004 400 [0.10, 10.202.100.219:52803][0m
Bad Request: /adminportal/api/UpdateUserDetailsAPI/1004
[31;1mHTTP PATCH /adminportal/api/UpdateUserDetailsAPI/1004 400 [0.15, 10.202.100.219:52801][0m
Bad Request: /adminportal/api/UpdateUserDetailsAPI/1004
[31;1mHTTP PATCH /adminportal/api/UpdateUserDetailsAPI/1004 400 [0.15, 10.202.100.219:52801][0m
Bad Request: /allauth/api/login
[31;1mHTTP POST /allauth/api/login 400 [0.27, 127.0.0.1:64511][0m
Bad Request: /allauth/api/login
[31;1mHTTP POST /allauth/api/login 400 [0.25, 127.0.0.1:64511][0m
Bad Request: /allauth/api/login
[31;1mHTTP POST /allauth/api/login 400 [0.29, 127.0.0.1:64511][0m
Bad Request: /allauth/api/login
[31;1mHTTP POST /allauth/api/login 400 [0.70, 127.0.0.1:64511][0m
Bad Request: /allauth/api/login
[31;1mHTTP POST /allauth/api/login 400 [0.73, 127.0.0.1:64937][0m
Bad Request: /allauth/api/login
[31;1mHTTP POST /allauth/api/login 400 [0.76, 127.0.0.1:64937][0m
Bad Request: /allauth/api/login
[31;1mHTTP POST /allauth/api/login 400 [0.68, 127.0.0.1:64937][0m
Bad Request: /allauth/api/login
[31;1mHTTP POST /allauth/api/login 400 [0.65, 127.0.0.1:64937][0m
Bad Request: /allauth/api/login
[31;1mHTTP POST /allauth/api/login 400 [0.27, 127.0.0.1:65070][0m
Bad Request: /allauth/api/login
[31;1mHTTP POST /allauth/api/login 400 [0.30, 127.0.0.1:65130][0m
Bad Request: /allauth/api/login
[31;1mHTTP POST /allauth/api/login 400 [0.33, 127.0.0.1:65130][0m
Bad Request: /allauth/api/login
[31;1mHTTP POST /allauth/api/login 400 [0.27, 127.0.0.1:65203][0m
Internal Server Error: /allauth/api/login
Traceback (most recent call last):
  File "D:\Jafar\AAD\.env\lib\site-packages\asgiref\sync.py", line 534, in thread_handler
    raise exc_info[1]
  File "D:\Jafar\AAD\.env\lib\site-packages\django\core\handlers\exception.py", line 42, in inner
    response = await get_response(request)
  File "D:\Jafar\AAD\.env\lib\site-packages\django\core\handlers\base.py", line 253, in _get_response_async
    response = await wrapped_callback(
  File "D:\Jafar\AAD\.env\lib\site-packages\asgiref\sync.py", line 479, in __call__
    ret: _R = await loop.run_in_executor(
  File "C:\Program Files\WindowsApps\PythonSoftwareFoundation.Python.3.10_3.10.3056.0_x64__qbz5n2kfra8p0\lib\concurrent\futures\thread.py", line 58, in run
    result = self.fn(*self.args, **self.kwargs)
  File "D:\Jafar\AAD\.env\lib\site-packages\asgiref\sync.py", line 538, in thread_handler
    return func(*args, **kwargs)
  File "D:\Jafar\AAD\.env\lib\site-packages\django\views\decorators\csrf.py", line 56, in wrapper_view
    return view_func(*args, **kwargs)
  File "D:\Jafar\AAD\.env\lib\site-packages\django\views\generic\base.py", line 104, in view
    return self.dispatch(request, *args, **kwargs)
  File "D:\Jafar\AAD\.env\lib\site-packages\rest_framework\views.py", line 509, in dispatch
    response = self.handle_exception(exc)
  File "D:\Jafar\AAD\.env\lib\site-packages\rest_framework\views.py", line 469, in handle_exception
    self.raise_uncaught_exception(exc)
  File "D:\Jafar\AAD\.env\lib\site-packages\rest_framework\views.py", line 480, in raise_uncaught_exception
    raise exc
  File "D:\Jafar\AAD\.env\lib\site-packages\rest_framework\views.py", line 506, in dispatch
    response = handler(request, *args, **kwargs)
  File "D:\Jafar\AAD\Allauth\views.py", line 1040, in post
    if serializer.is_valid():
  File "D:\Jafar\AAD\.env\lib\site-packages\rest_framework\serializers.py", line 227, in is_valid
    self._validated_data = self.run_validation(self.initial_data)
  File "D:\Jafar\AAD\.env\lib\site-packages\rest_framework\serializers.py", line 429, in run_validation
    value = self.validate(value)
  File "D:\Jafar\AAD\Allauth\serializers.py", line 369, in validate
    if customuser.is_active == False:
AttributeError: 'NoneType' object has no attribute 'is_active'
[35;1mHTTP POST /allauth/api/login 500 [0.58, 127.0.0.1:49680][0m
Bad Request: /allauth/api/login
[31;1mHTTP POST /allauth/api/login 400 [0.27, 127.0.0.1:49705][0m
Bad Request: /allauth/api/login
[31;1mHTTP POST /allauth/api/login 400 [0.32, 127.0.0.1:49705][0m
Internal Server Error: /allauth/api/login
Traceback (most recent call last):
  File "D:\Jafar\AAD\.env\lib\site-packages\asgiref\sync.py", line 534, in thread_handler
    raise exc_info[1]
  File "D:\Jafar\AAD\.env\lib\site-packages\django\core\handlers\exception.py", line 42, in inner
    response = await get_response(request)
  File "D:\Jafar\AAD\.env\lib\site-packages\django\core\handlers\base.py", line 253, in _get_response_async
    response = await wrapped_callback(
  File "D:\Jafar\AAD\.env\lib\site-packages\asgiref\sync.py", line 479, in __call__
    ret: _R = await loop.run_in_executor(
  File "C:\Program Files\WindowsApps\PythonSoftwareFoundation.Python.3.10_3.10.3056.0_x64__qbz5n2kfra8p0\lib\concurrent\futures\thread.py", line 58, in run
    result = self.fn(*self.args, **self.kwargs)
  File "D:\Jafar\AAD\.env\lib\site-packages\asgiref\sync.py", line 538, in thread_handler
    return func(*args, **kwargs)
  File "D:\Jafar\AAD\.env\lib\site-packages\django\views\decorators\csrf.py", line 56, in wrapper_view
    return view_func(*args, **kwargs)
  File "D:\Jafar\AAD\.env\lib\site-packages\django\views\generic\base.py", line 104, in view
    return self.dispatch(request, *args, **kwargs)
  File "D:\Jafar\AAD\.env\lib\site-packages\rest_framework\views.py", line 509, in dispatch
    response = self.handle_exception(exc)
  File "D:\Jafar\AAD\.env\lib\site-packages\rest_framework\views.py", line 469, in handle_exception
    self.raise_uncaught_exception(exc)
  File "D:\Jafar\AAD\.env\lib\site-packages\rest_framework\views.py", line 480, in raise_uncaught_exception
    raise exc
  File "D:\Jafar\AAD\.env\lib\site-packages\rest_framework\views.py", line 506, in dispatch
    response = handler(request, *args, **kwargs)
  File "D:\Jafar\AAD\Allauth\views.py", line 1040, in post
    if serializer.is_valid():
  File "D:\Jafar\AAD\.env\lib\site-packages\rest_framework\serializers.py", line 227, in is_valid
    self._validated_data = self.run_validation(self.initial_data)
  File "D:\Jafar\AAD\.env\lib\site-packages\rest_framework\serializers.py", line 429, in run_validation
    value = self.validate(value)
  File "D:\Jafar\AAD\Allauth\serializers.py", line 369, in validate
    if customuser.is_active is False:
AttributeError: 'NoneType' object has no attribute 'is_active'
[35;1mHTTP POST /allauth/api/login 500 [1.55, 127.0.0.1:49789][0m
Internal Server Error: /allauth/api/login
Traceback (most recent call last):
  File "D:\Jafar\AAD\.env\lib\site-packages\asgiref\sync.py", line 534, in thread_handler
    raise exc_info[1]
  File "D:\Jafar\AAD\.env\lib\site-packages\django\core\handlers\exception.py", line 42, in inner
    response = await get_response(request)
  File "D:\Jafar\AAD\.env\lib\site-packages\django\core\handlers\base.py", line 253, in _get_response_async
    response = await wrapped_callback(
  File "D:\Jafar\AAD\.env\lib\site-packages\asgiref\sync.py", line 479, in __call__
    ret: _R = await loop.run_in_executor(
  File "C:\Program Files\WindowsApps\PythonSoftwareFoundation.Python.3.10_3.10.3056.0_x64__qbz5n2kfra8p0\lib\concurrent\futures\thread.py", line 58, in run
    result = self.fn(*self.args, **self.kwargs)
  File "D:\Jafar\AAD\.env\lib\site-packages\asgiref\sync.py", line 538, in thread_handler
    return func(*args, **kwargs)
  File "D:\Jafar\AAD\.env\lib\site-packages\django\views\decorators\csrf.py", line 56, in wrapper_view
    return view_func(*args, **kwargs)
  File "D:\Jafar\AAD\.env\lib\site-packages\django\views\generic\base.py", line 104, in view
    return self.dispatch(request, *args, **kwargs)
  File "D:\Jafar\AAD\.env\lib\site-packages\rest_framework\views.py", line 509, in dispatch
    response = self.handle_exception(exc)
  File "D:\Jafar\AAD\.env\lib\site-packages\rest_framework\views.py", line 469, in handle_exception
    self.raise_uncaught_exception(exc)
  File "D:\Jafar\AAD\.env\lib\site-packages\rest_framework\views.py", line 480, in raise_uncaught_exception
    raise exc
  File "D:\Jafar\AAD\.env\lib\site-packages\rest_framework\views.py", line 506, in dispatch
    response = handler(request, *args, **kwargs)
  File "D:\Jafar\AAD\Allauth\views.py", line 1040, in post
    if serializer.is_valid():
  File "D:\Jafar\AAD\.env\lib\site-packages\rest_framework\serializers.py", line 227, in is_valid
    self._validated_data = self.run_validation(self.initial_data)
  File "D:\Jafar\AAD\.env\lib\site-packages\rest_framework\serializers.py", line 429, in run_validation
    value = self.validate(value)
  File "D:\Jafar\AAD\Allauth\serializers.py", line 370, in validate
    if customuser.is_active is False:
AttributeError: 'NoneType' object has no attribute 'is_active'
[35;1mHTTP POST /allauth/api/login 500 [0.29, 127.0.0.1:49877][0m
Bad Request: /allauth/api/login
[31;1mHTTP POST /allauth/api/login 400 [0.33, 127.0.0.1:49937][0m
Not Found: /healthworker/api/veirfyaadharCard/
[33mHTTP GET /healthworker/api/veirfyaadharCard/ 404 [0.03, 10.202.100.219:53005][0m
Internal Server Error: /allauth/api/login
Traceback (most recent call last):
  File "D:\Jafar\AAD\.env\lib\site-packages\asgiref\sync.py", line 534, in thread_handler
    raise exc_info[1]
  File "D:\Jafar\AAD\.env\lib\site-packages\django\core\handlers\exception.py", line 42, in inner
    response = await get_response(request)
  File "D:\Jafar\AAD\.env\lib\site-packages\django\core\handlers\base.py", line 253, in _get_response_async
    response = await wrapped_callback(
  File "D:\Jafar\AAD\.env\lib\site-packages\asgiref\sync.py", line 479, in __call__
    ret: _R = await loop.run_in_executor(
  File "C:\Program Files\WindowsApps\PythonSoftwareFoundation.Python.3.10_3.10.3056.0_x64__qbz5n2kfra8p0\lib\concurrent\futures\thread.py", line 58, in run
    result = self.fn(*self.args, **self.kwargs)
  File "D:\Jafar\AAD\.env\lib\site-packages\asgiref\sync.py", line 538, in thread_handler
    return func(*args, **kwargs)
  File "D:\Jafar\AAD\.env\lib\site-packages\django\views\decorators\csrf.py", line 56, in wrapper_view
    return view_func(*args, **kwargs)
  File "D:\Jafar\AAD\.env\lib\site-packages\django\views\generic\base.py", line 104, in view
    return self.dispatch(request, *args, **kwargs)
  File "D:\Jafar\AAD\.env\lib\site-packages\rest_framework\views.py", line 509, in dispatch
    response = self.handle_exception(exc)
  File "D:\Jafar\AAD\.env\lib\site-packages\rest_framework\views.py", line 469, in handle_exception
    self.raise_uncaught_exception(exc)
  File "D:\Jafar\AAD\.env\lib\site-packages\rest_framework\views.py", line 480, in raise_uncaught_exception
    raise exc
  File "D:\Jafar\AAD\.env\lib\site-packages\rest_framework\views.py", line 506, in dispatch
    response = handler(request, *args, **kwargs)
  File "D:\Jafar\AAD\Allauth\views.py", line 1040, in post
    if serializer.is_valid():
  File "D:\Jafar\AAD\.env\lib\site-packages\rest_framework\serializers.py", line 227, in is_valid
    self._validated_data = self.run_validation(self.initial_data)
  File "D:\Jafar\AAD\.env\lib\site-packages\rest_framework\serializers.py", line 430, in run_validation
    assert value is not None, '.validate() should return the validated data'
AssertionError: .validate() should return the validated data
[35;1mHTTP POST /allauth/api/login 500 [0.28, 127.0.0.1:50114][0m
Internal Server Error: /allauth/api/login
Traceback (most recent call last):
  File "D:\Jafar\AAD\.env\lib\site-packages\asgiref\sync.py", line 534, in thread_handler
    raise exc_info[1]
  File "D:\Jafar\AAD\.env\lib\site-packages\django\core\handlers\exception.py", line 42, in inner
    response = await get_response(request)
  File "D:\Jafar\AAD\.env\lib\site-packages\django\core\handlers\base.py", line 253, in _get_response_async
    response = await wrapped_callback(
  File "D:\Jafar\AAD\.env\lib\site-packages\asgiref\sync.py", line 479, in __call__
    ret: _R = await loop.run_in_executor(
  File "C:\Program Files\WindowsApps\PythonSoftwareFoundation.Python.3.10_3.10.3056.0_x64__qbz5n2kfra8p0\lib\concurrent\futures\thread.py", line 58, in run
    result = self.fn(*self.args, **self.kwargs)
  File "D:\Jafar\AAD\.env\lib\site-packages\asgiref\sync.py", line 538, in thread_handler
    return func(*args, **kwargs)
  File "D:\Jafar\AAD\.env\lib\site-packages\django\views\decorators\csrf.py", line 56, in wrapper_view
    return view_func(*args, **kwargs)
  File "D:\Jafar\AAD\.env\lib\site-packages\django\views\generic\base.py", line 104, in view
    return self.dispatch(request, *args, **kwargs)
  File "D:\Jafar\AAD\.env\lib\site-packages\rest_framework\views.py", line 509, in dispatch
    response = self.handle_exception(exc)
  File "D:\Jafar\AAD\.env\lib\site-packages\rest_framework\views.py", line 469, in handle_exception
    self.raise_uncaught_exception(exc)
  File "D:\Jafar\AAD\.env\lib\site-packages\rest_framework\views.py", line 480, in raise_uncaught_exception
    raise exc
  File "D:\Jafar\AAD\.env\lib\site-packages\rest_framework\views.py", line 506, in dispatch
    response = handler(request, *args, **kwargs)
  File "D:\Jafar\AAD\Allauth\views.py", line 1040, in post
    if serializer.is_valid():
  File "D:\Jafar\AAD\.env\lib\site-packages\rest_framework\serializers.py", line 227, in is_valid
    self._validated_data = self.run_validation(self.initial_data)
  File "D:\Jafar\AAD\.env\lib\site-packages\rest_framework\serializers.py", line 430, in run_validation
    assert value is not None, '.validate() should return the validated data'
AssertionError: .validate() should return the validated data
[35;1mHTTP POST /allauth/api/login 500 [0.27, 127.0.0.1:50135][0m
Internal Server Error: /allauth/api/login
Traceback (most recent call last):
  File "D:\Jafar\AAD\.env\lib\site-packages\asgiref\sync.py", line 534, in thread_handler
    raise exc_info[1]
  File "D:\Jafar\AAD\.env\lib\site-packages\django\core\handlers\exception.py", line 42, in inner
    response = await get_response(request)
  File "D:\Jafar\AAD\.env\lib\site-packages\django\core\handlers\base.py", line 253, in _get_response_async
    response = await wrapped_callback(
  File "D:\Jafar\AAD\.env\lib\site-packages\asgiref\sync.py", line 479, in __call__
    ret: _R = await loop.run_in_executor(
  File "C:\Program Files\WindowsApps\PythonSoftwareFoundation.Python.3.10_3.10.3056.0_x64__qbz5n2kfra8p0\lib\concurrent\futures\thread.py", line 58, in run
    result = self.fn(*self.args, **self.kwargs)
  File "D:\Jafar\AAD\.env\lib\site-packages\asgiref\sync.py", line 538, in thread_handler
    return func(*args, **kwargs)
  File "D:\Jafar\AAD\.env\lib\site-packages\django\views\decorators\csrf.py", line 56, in wrapper_view
    return view_func(*args, **kwargs)
  File "D:\Jafar\AAD\.env\lib\site-packages\django\views\generic\base.py", line 104, in view
    return self.dispatch(request, *args, **kwargs)
  File "D:\Jafar\AAD\.env\lib\site-packages\rest_framework\views.py", line 509, in dispatch
    response = self.handle_exception(exc)
  File "D:\Jafar\AAD\.env\lib\site-packages\rest_framework\views.py", line 469, in handle_exception
    self.raise_uncaught_exception(exc)
  File "D:\Jafar\AAD\.env\lib\site-packages\rest_framework\views.py", line 480, in raise_uncaught_exception
    raise exc
  File "D:\Jafar\AAD\.env\lib\site-packages\rest_framework\views.py", line 506, in dispatch
    response = handler(request, *args, **kwargs)
  File "D:\Jafar\AAD\Allauth\views.py", line 1040, in post
    if serializer.is_valid():
  File "D:\Jafar\AAD\.env\lib\site-packages\rest_framework\serializers.py", line 227, in is_valid
    self._validated_data = self.run_validation(self.initial_data)
  File "D:\Jafar\AAD\.env\lib\site-packages\rest_framework\serializers.py", line 430, in run_validation
    assert value is not None, '.validate() should return the validated data'
AssertionError: .validate() should return the validated data
[35;1mHTTP POST /allauth/api/login 500 [0.28, 127.0.0.1:50135][0m
Internal Server Error: /allauth/api/login
Traceback (most recent call last):
  File "D:\Jafar\AAD\.env\lib\site-packages\asgiref\sync.py", line 534, in thread_handler
    raise exc_info[1]
  File "D:\Jafar\AAD\.env\lib\site-packages\django\core\handlers\exception.py", line 42, in inner
    response = await get_response(request)
  File "D:\Jafar\AAD\.env\lib\site-packages\django\core\handlers\base.py", line 253, in _get_response_async
    response = await wrapped_callback(
  File "D:\Jafar\AAD\.env\lib\site-packages\asgiref\sync.py", line 479, in __call__
    ret: _R = await loop.run_in_executor(
  File "C:\Program Files\WindowsApps\PythonSoftwareFoundation.Python.3.10_3.10.3056.0_x64__qbz5n2kfra8p0\lib\concurrent\futures\thread.py", line 58, in run
    result = self.fn(*self.args, **self.kwargs)
  File "D:\Jafar\AAD\.env\lib\site-packages\asgiref\sync.py", line 538, in thread_handler
    return func(*args, **kwargs)
  File "D:\Jafar\AAD\.env\lib\site-packages\django\views\decorators\csrf.py", line 56, in wrapper_view
    return view_func(*args, **kwargs)
  File "D:\Jafar\AAD\.env\lib\site-packages\django\views\generic\base.py", line 104, in view
    return self.dispatch(request, *args, **kwargs)
  File "D:\Jafar\AAD\.env\lib\site-packages\rest_framework\views.py", line 509, in dispatch
    response = self.handle_exception(exc)
  File "D:\Jafar\AAD\.env\lib\site-packages\rest_framework\views.py", line 469, in handle_exception
    self.raise_uncaught_exception(exc)
  File "D:\Jafar\AAD\.env\lib\site-packages\rest_framework\views.py", line 480, in raise_uncaught_exception
    raise exc
  File "D:\Jafar\AAD\.env\lib\site-packages\rest_framework\views.py", line 506, in dispatch
    response = handler(request, *args, **kwargs)
  File "D:\Jafar\AAD\Allauth\views.py", line 1040, in post
    if serializer.is_valid():
  File "D:\Jafar\AAD\.env\lib\site-packages\rest_framework\serializers.py", line 227, in is_valid
    self._validated_data = self.run_validation(self.initial_data)
  File "D:\Jafar\AAD\.env\lib\site-packages\rest_framework\serializers.py", line 430, in run_validation
    assert value is not None, '.validate() should return the validated data'
AssertionError: .validate() should return the validated data
[35;1mHTTP POST /allauth/api/login 500 [0.28, 127.0.0.1:50135][0m
Bad Request: /healthworker/api/PostSurveyForm
[31;1mHTTP POST /healthworker/api/PostSurveyForm 400 [0.10, 10.202.100.219:53022][0m
Internal Server Error: /allauth/api/login
Traceback (most recent call last):
  File "D:\Jafar\AAD\.env\lib\site-packages\asgiref\sync.py", line 534, in thread_handler
    raise exc_info[1]
  File "D:\Jafar\AAD\.env\lib\site-packages\django\core\handlers\exception.py", line 42, in inner
    response = await get_response(request)
  File "D:\Jafar\AAD\.env\lib\site-packages\django\core\handlers\base.py", line 253, in _get_response_async
    response = await wrapped_callback(
  File "D:\Jafar\AAD\.env\lib\site-packages\asgiref\sync.py", line 479, in __call__
    ret: _R = await loop.run_in_executor(
  File "C:\Program Files\WindowsApps\PythonSoftwareFoundation.Python.3.10_3.10.3056.0_x64__qbz5n2kfra8p0\lib\concurrent\futures\thread.py", line 58, in run
    result = self.fn(*self.args, **self.kwargs)
  File "D:\Jafar\AAD\.env\lib\site-packages\asgiref\sync.py", line 538, in thread_handler
    return func(*args, **kwargs)
  File "D:\Jafar\AAD\.env\lib\site-packages\django\views\decorators\csrf.py", line 56, in wrapper_view
    return view_func(*args, **kwargs)
  File "D:\Jafar\AAD\.env\lib\site-packages\django\views\generic\base.py", line 104, in view
    return self.dispatch(request, *args, **kwargs)
  File "D:\Jafar\AAD\.env\lib\site-packages\rest_framework\views.py", line 509, in dispatch
    response = self.handle_exception(exc)
  File "D:\Jafar\AAD\.env\lib\site-packages\rest_framework\views.py", line 469, in handle_exception
    self.raise_uncaught_exception(exc)
  File "D:\Jafar\AAD\.env\lib\site-packages\rest_framework\views.py", line 480, in raise_uncaught_exception
    raise exc
  File "D:\Jafar\AAD\.env\lib\site-packages\rest_framework\views.py", line 506, in dispatch
    response = handler(request, *args, **kwargs)
  File "D:\Jafar\AAD\Allauth\views.py", line 1043, in post
    group = user_data.groups.values_list("name", flat=True)[0]
AttributeError: 'collections.OrderedDict' object has no attribute 'groups'
[35;1mHTTP POST /allauth/api/login 500 [0.30, 127.0.0.1:50164][0m
Internal Server Error: /allauth/api/login
Traceback (most recent call last):
  File "D:\Jafar\AAD\.env\lib\site-packages\asgiref\sync.py", line 534, in thread_handler
    raise exc_info[1]
  File "D:\Jafar\AAD\.env\lib\site-packages\django\core\handlers\exception.py", line 42, in inner
    response = await get_response(request)
  File "D:\Jafar\AAD\.env\lib\site-packages\django\core\handlers\base.py", line 253, in _get_response_async
    response = await wrapped_callback(
  File "D:\Jafar\AAD\.env\lib\site-packages\asgiref\sync.py", line 479, in __call__
    ret: _R = await loop.run_in_executor(
  File "C:\Program Files\WindowsApps\PythonSoftwareFoundation.Python.3.10_3.10.3056.0_x64__qbz5n2kfra8p0\lib\concurrent\futures\thread.py", line 58, in run
    result = self.fn(*self.args, **self.kwargs)
  File "D:\Jafar\AAD\.env\lib\site-packages\asgiref\sync.py", line 538, in thread_handler
    return func(*args, **kwargs)
  File "D:\Jafar\AAD\.env\lib\site-packages\django\views\decorators\csrf.py", line 56, in wrapper_view
    return view_func(*args, **kwargs)
  File "D:\Jafar\AAD\.env\lib\site-packages\django\views\generic\base.py", line 104, in view
    return self.dispatch(request, *args, **kwargs)
  File "D:\Jafar\AAD\.env\lib\site-packages\rest_framework\views.py", line 509, in dispatch
    response = self.handle_exception(exc)
  File "D:\Jafar\AAD\.env\lib\site-packages\rest_framework\views.py", line 469, in handle_exception
    self.raise_uncaught_exception(exc)
  File "D:\Jafar\AAD\.env\lib\site-packages\rest_framework\views.py", line 480, in raise_uncaught_exception
    raise exc
  File "D:\Jafar\AAD\.env\lib\site-packages\rest_framework\views.py", line 506, in dispatch
    response = handler(request, *args, **kwargs)
  File "D:\Jafar\AAD\Allauth\views.py", line 1043, in post
    group = user_data.groups.values_list("name", flat=True)[0]
AttributeError: 'collections.OrderedDict' object has no attribute 'groups'
[35;1mHTTP POST /allauth/api/login 500 [0.39, 127.0.0.1:50164][0m
Internal Server Error: /allauth/api/login
Traceback (most recent call last):
  File "D:\Jafar\AAD\.env\lib\site-packages\asgiref\sync.py", line 534, in thread_handler
    raise exc_info[1]
  File "D:\Jafar\AAD\.env\lib\site-packages\django\core\handlers\exception.py", line 42, in inner
    response = await get_response(request)
  File "D:\Jafar\AAD\.env\lib\site-packages\django\core\handlers\base.py", line 253, in _get_response_async
    response = await wrapped_callback(
  File "D:\Jafar\AAD\.env\lib\site-packages\asgiref\sync.py", line 479, in __call__
    ret: _R = await loop.run_in_executor(
  File "C:\Program Files\WindowsApps\PythonSoftwareFoundation.Python.3.10_3.10.3056.0_x64__qbz5n2kfra8p0\lib\concurrent\futures\thread.py", line 58, in run
    result = self.fn(*self.args, **self.kwargs)
  File "D:\Jafar\AAD\.env\lib\site-packages\asgiref\sync.py", line 538, in thread_handler
    return func(*args, **kwargs)
  File "D:\Jafar\AAD\.env\lib\site-packages\django\views\decorators\csrf.py", line 56, in wrapper_view
    return view_func(*args, **kwargs)
  File "D:\Jafar\AAD\.env\lib\site-packages\django\views\generic\base.py", line 104, in view
    return self.dispatch(request, *args, **kwargs)
  File "D:\Jafar\AAD\.env\lib\site-packages\rest_framework\views.py", line 509, in dispatch
    response = self.handle_exception(exc)
  File "D:\Jafar\AAD\.env\lib\site-packages\rest_framework\views.py", line 469, in handle_exception
    self.raise_uncaught_exception(exc)
  File "D:\Jafar\AAD\.env\lib\site-packages\rest_framework\views.py", line 480, in raise_uncaught_exception
    raise exc
  File "D:\Jafar\AAD\.env\lib\site-packages\rest_framework\views.py", line 506, in dispatch
    response = handler(request, *args, **kwargs)
  File "D:\Jafar\AAD\Allauth\views.py", line 1040, in post
    if serializer.is_valid():
  File "D:\Jafar\AAD\.env\lib\site-packages\rest_framework\serializers.py", line 227, in is_valid
    self._validated_data = self.run_validation(self.initial_data)
  File "D:\Jafar\AAD\.env\lib\site-packages\rest_framework\serializers.py", line 429, in run_validation
    value = self.validate(value)
  File "D:\Jafar\AAD\Allauth\serializers.py", line 364, in validate
    print(settings.AUTHENTICATION_BACKENDS)
AttributeError: module 'ArogyaAplyaDari.settings' has no attribute 'AUTHENTICATION_BACKENDS'
[35;1mHTTP POST /allauth/api/login 500 [0.33, 127.0.0.1:50378][0m
Bad Request: /allauth/api/login
[31;1mHTTP POST /allauth/api/login 400 [0.40, 127.0.0.1:50711][0m
Internal Server Error: /allauth/api/login
Traceback (most recent call last):
  File "D:\Jafar\AAD\.env\lib\site-packages\asgiref\sync.py", line 534, in thread_handler
    raise exc_info[1]
  File "D:\Jafar\AAD\.env\lib\site-packages\django\core\handlers\exception.py", line 42, in inner
    response = await get_response(request)
  File "D:\Jafar\AAD\.env\lib\site-packages\django\core\handlers\base.py", line 253, in _get_response_async
    response = await wrapped_callback(
  File "D:\Jafar\AAD\.env\lib\site-packages\asgiref\sync.py", line 479, in __call__
    ret: _R = await loop.run_in_executor(
  File "C:\Program Files\WindowsApps\PythonSoftwareFoundation.Python.3.10_3.10.3056.0_x64__qbz5n2kfra8p0\lib\concurrent\futures\thread.py", line 58, in run
    result = self.fn(*self.args, **self.kwargs)
  File "D:\Jafar\AAD\.env\lib\site-packages\asgiref\sync.py", line 538, in thread_handler
    return func(*args, **kwargs)
  File "D:\Jafar\AAD\.env\lib\site-packages\django\views\decorators\csrf.py", line 56, in wrapper_view
    return view_func(*args, **kwargs)
  File "D:\Jafar\AAD\.env\lib\site-packages\django\views\generic\base.py", line 104, in view
    return self.dispatch(request, *args, **kwargs)
  File "D:\Jafar\AAD\.env\lib\site-packages\rest_framework\views.py", line 509, in dispatch
    response = self.handle_exception(exc)
  File "D:\Jafar\AAD\.env\lib\site-packages\rest_framework\views.py", line 469, in handle_exception
    self.raise_uncaught_exception(exc)
  File "D:\Jafar\AAD\.env\lib\site-packages\rest_framework\views.py", line 480, in raise_uncaught_exception
    raise exc
  File "D:\Jafar\AAD\.env\lib\site-packages\rest_framework\views.py", line 506, in dispatch
    response = handler(request, *args, **kwargs)
  File "D:\Jafar\AAD\Allauth\views.py", line 1040, in post
    if serializer.is_valid():
  File "D:\Jafar\AAD\.env\lib\site-packages\rest_framework\serializers.py", line 227, in is_valid
    self._validated_data = self.run_validation(self.initial_data)
  File "D:\Jafar\AAD\.env\lib\site-packages\rest_framework\serializers.py", line 429, in run_validation
    value = self.validate(value)
  File "D:\Jafar\AAD\Allauth\serializers.py", line 372, in validate
    if  customuser.is_active is False:
AttributeError: 'NoneType' object has no attribute 'is_active'
[35;1mHTTP POST /allauth/api/login 500 [0.46, 127.0.0.1:50711][0m
Bad Request: /allauth/api/login
[31;1mHTTP POST /allauth/api/login 400 [0.27, 127.0.0.1:50799][0m
Bad Request: /allauth/api/login
[31;1mHTTP POST /allauth/api/login 400 [0.31, 127.0.0.1:50799][0m
Not Found: /allauth/api/GethealthPostNameList
[33mHTTP GET /allauth/api/GethealthPostNameList?search=4 404 [0.00, 10.202.100.219:53497][0m
Not Found: /allauth/api/GethealthPostNameList
[33mHTTP GET /allauth/api/GethealthPostNameList?search=4 404 [0.02, 10.202.100.219:53508][0m
Bad Request: /allauth/api/login
[31;1mHTTP POST /allauth/api/login 400 [0.36, 127.0.0.1:51289][0m
Bad Request: /allauth/api/login
[31;1mHTTP POST /allauth/api/login 400 [0.25, 127.0.0.1:51312][0m
Bad Request: /allauth/api/login
[31;1mHTTP POST /allauth/api/login 400 [0.23, 127.0.0.1:51544][0m
Bad Request: /allauth/api/login
[31;1mHTTP POST /allauth/api/login 400 [0.27, 127.0.0.1:51738][0m
view's UpdateUserDetails raised exception during schema generation; use `getattr(self, 'swagger_fake_view', False)` to detect and short-circuit this
Traceback (most recent call last):
  File "D:\Jafar\AAD\.env\lib\site-packages\drf_yasg\inspectors\base.py", line 42, in call_view_method
    return view_method()
  File "D:\Jafar\AAD\.env\lib\site-packages\rest_framework\generics.py", line 63, in get_queryset
    assert self.queryset is not None, (
AssertionError: 'UpdateUserDetails' should either include a `queryset` attribute, or override the `get_queryset()` method.
view's DownloadDispensarywiseUserList raised exception during schema generation; use `getattr(self, 'swagger_fake_view', False)` to detect and short-circuit this
Traceback (most recent call last):
  File "D:\Jafar\AAD\.env\lib\site-packages\drf_yasg\inspectors\base.py", line 42, in call_view_method
    return view_method()
  File "D:\Jafar\AAD\.env\lib\site-packages\rest_framework\generics.py", line 108, in get_serializer
    serializer_class = self.get_serializer_class()
  File "D:\Jafar\AAD\.env\lib\site-packages\rest_framework\generics.py", line 122, in get_serializer_class
    assert self.serializer_class is not None, (
AssertionError: 'DownloadDispensarywiseUserList' should either include a `serializer_class` attribute, or override the `get_serializer_class()` method.
view's DownloadHealthpostwiseUserList raised exception during schema generation; use `getattr(self, 'swagger_fake_view', False)` to detect and short-circuit this
Traceback (most recent call last):
  File "D:\Jafar\AAD\.env\lib\site-packages\drf_yasg\inspectors\base.py", line 42, in call_view_method
    return view_method()
  File "D:\Jafar\AAD\.env\lib\site-packages\rest_framework\generics.py", line 108, in get_serializer
    serializer_class = self.get_serializer_class()
  File "D:\Jafar\AAD\.env\lib\site-packages\rest_framework\generics.py", line 122, in get_serializer_class
    assert self.serializer_class is not None, (
AssertionError: 'DownloadHealthpostwiseUserList' should either include a `serializer_class` attribute, or override the `get_serializer_class()` method.
view's DownloadWardwiseUserList raised exception during schema generation; use `getattr(self, 'swagger_fake_view', False)` to detect and short-circuit this
Traceback (most recent call last):
  File "D:\Jafar\AAD\.env\lib\site-packages\drf_yasg\inspectors\base.py", line 42, in call_view_method
    return view_method()
  File "D:\Jafar\AAD\.env\lib\site-packages\rest_framework\generics.py", line 108, in get_serializer
    serializer_class = self.get_serializer_class()
  File "D:\Jafar\AAD\.env\lib\site-packages\rest_framework\generics.py", line 122, in get_serializer_class
    assert self.serializer_class is not None, (
AssertionError: 'DownloadWardwiseUserList' should either include a `serializer_class` attribute, or override the `get_serializer_class()` method.
view's MOHDashboardView raised exception during schema generation; use `getattr(self, 'swagger_fake_view', False)` to detect and short-circuit this
Traceback (most recent call last):
  File "D:\Jafar\AAD\.env\lib\site-packages\drf_yasg\inspectors\base.py", line 42, in call_view_method
    return view_method()
  File "D:\Jafar\AAD\.env\lib\site-packages\rest_framework\generics.py", line 108, in get_serializer
    serializer_class = self.get_serializer_class()
  File "D:\Jafar\AAD\.env\lib\site-packages\rest_framework\generics.py", line 122, in get_serializer_class
    assert self.serializer_class is not None, (
AssertionError: 'MOHDashboardView' should either include a `serializer_class` attribute, or override the `get_serializer_class()` method.
Not Found: /allauth/api/GethealthPostNameList18
[33mHTTP GET /allauth/api/GethealthPostNameList18 404 [0.01, 10.202.100.219:53730][0m
Not Found: /allauth/api/GethealthPostNameList18
[33mHTTP GET /allauth/api/GethealthPostNameList18 404 [0.01, 10.202.100.219:53730][0m
view's UpdateUserDetails raised exception during schema generation; use `getattr(self, 'swagger_fake_view', False)` to detect and short-circuit this
Traceback (most recent call last):
  File "D:\Jafar\AAD\.env\lib\site-packages\drf_yasg\inspectors\base.py", line 42, in call_view_method
    return view_method()
  File "D:\Jafar\AAD\.env\lib\site-packages\rest_framework\generics.py", line 63, in get_queryset
    assert self.queryset is not None, (
AssertionError: 'UpdateUserDetails' should either include a `queryset` attribute, or override the `get_queryset()` method.
view's DownloadDispensarywiseUserList raised exception during schema generation; use `getattr(self, 'swagger_fake_view', False)` to detect and short-circuit this
Traceback (most recent call last):
  File "D:\Jafar\AAD\.env\lib\site-packages\drf_yasg\inspectors\base.py", line 42, in call_view_method
    return view_method()
  File "D:\Jafar\AAD\.env\lib\site-packages\rest_framework\generics.py", line 108, in get_serializer
    serializer_class = self.get_serializer_class()
  File "D:\Jafar\AAD\.env\lib\site-packages\rest_framework\generics.py", line 122, in get_serializer_class
    assert self.serializer_class is not None, (
AssertionError: 'DownloadDispensarywiseUserList' should either include a `serializer_class` attribute, or override the `get_serializer_class()` method.
view's DownloadHealthpostwiseUserList raised exception during schema generation; use `getattr(self, 'swagger_fake_view', False)` to detect and short-circuit this
Traceback (most recent call last):
  File "D:\Jafar\AAD\.env\lib\site-packages\drf_yasg\inspectors\base.py", line 42, in call_view_method
    return view_method()
  File "D:\Jafar\AAD\.env\lib\site-packages\rest_framework\generics.py", line 108, in get_serializer
    serializer_class = self.get_serializer_class()
  File "D:\Jafar\AAD\.env\lib\site-packages\rest_framework\generics.py", line 122, in get_serializer_class
    assert self.serializer_class is not None, (
AssertionError: 'DownloadHealthpostwiseUserList' should either include a `serializer_class` attribute, or override the `get_serializer_class()` method.
view's DownloadWardwiseUserList raised exception during schema generation; use `getattr(self, 'swagger_fake_view', False)` to detect and short-circuit this
Traceback (most recent call last):
  File "D:\Jafar\AAD\.env\lib\site-packages\drf_yasg\inspectors\base.py", line 42, in call_view_method
    return view_method()
  File "D:\Jafar\AAD\.env\lib\site-packages\rest_framework\generics.py", line 108, in get_serializer
    serializer_class = self.get_serializer_class()
  File "D:\Jafar\AAD\.env\lib\site-packages\rest_framework\generics.py", line 122, in get_serializer_class
    assert self.serializer_class is not None, (
AssertionError: 'DownloadWardwiseUserList' should either include a `serializer_class` attribute, or override the `get_serializer_class()` method.
view's MOHDashboardView raised exception during schema generation; use `getattr(self, 'swagger_fake_view', False)` to detect and short-circuit this
Traceback (most recent call last):
  File "D:\Jafar\AAD\.env\lib\site-packages\drf_yasg\inspectors\base.py", line 42, in call_view_method
    return view_method()
  File "D:\Jafar\AAD\.env\lib\site-packages\rest_framework\generics.py", line 108, in get_serializer
    serializer_class = self.get_serializer_class()
  File "D:\Jafar\AAD\.env\lib\site-packages\rest_framework\generics.py", line 122, in get_serializer_class
    assert self.serializer_class is not None, (
AssertionError: 'MOHDashboardView' should either include a `serializer_class` attribute, or override the `get_serializer_class()` method.
Not Found: /allauth/api/GethealthPostNameList/18
[33mHTTP GET /allauth/api/GethealthPostNameList/18 404 [0.01, 10.202.100.219:53795][0m
view's UpdateUserDetails raised exception during schema generation; use `getattr(self, 'swagger_fake_view', False)` to detect and short-circuit this
Traceback (most recent call last):
  File "D:\Jafar\AAD\.env\lib\site-packages\drf_yasg\inspectors\base.py", line 42, in call_view_method
    return view_method()
  File "D:\Jafar\AAD\.env\lib\site-packages\rest_framework\generics.py", line 63, in get_queryset
    assert self.queryset is not None, (
AssertionError: 'UpdateUserDetails' should either include a `queryset` attribute, or override the `get_queryset()` method.
view's DownloadDispensarywiseUserList raised exception during schema generation; use `getattr(self, 'swagger_fake_view', False)` to detect and short-circuit this
Traceback (most recent call last):
  File "D:\Jafar\AAD\.env\lib\site-packages\drf_yasg\inspectors\base.py", line 42, in call_view_method
    return view_method()
  File "D:\Jafar\AAD\.env\lib\site-packages\rest_framework\generics.py", line 108, in get_serializer
    serializer_class = self.get_serializer_class()
  File "D:\Jafar\AAD\.env\lib\site-packages\rest_framework\generics.py", line 122, in get_serializer_class
    assert self.serializer_class is not None, (
AssertionError: 'DownloadDispensarywiseUserList' should either include a `serializer_class` attribute, or override the `get_serializer_class()` method.
view's DownloadHealthpostwiseUserList raised exception during schema generation; use `getattr(self, 'swagger_fake_view', False)` to detect and short-circuit this
Traceback (most recent call last):
  File "D:\Jafar\AAD\.env\lib\site-packages\drf_yasg\inspectors\base.py", line 42, in call_view_method
    return view_method()
  File "D:\Jafar\AAD\.env\lib\site-packages\rest_framework\generics.py", line 108, in get_serializer
    serializer_class = self.get_serializer_class()
  File "D:\Jafar\AAD\.env\lib\site-packages\rest_framework\generics.py", line 122, in get_serializer_class
    assert self.serializer_class is not None, (
AssertionError: 'DownloadHealthpostwiseUserList' should either include a `serializer_class` attribute, or override the `get_serializer_class()` method.
view's DownloadWardwiseUserList raised exception during schema generation; use `getattr(self, 'swagger_fake_view', False)` to detect and short-circuit this
Traceback (most recent call last):
  File "D:\Jafar\AAD\.env\lib\site-packages\drf_yasg\inspectors\base.py", line 42, in call_view_method
    return view_method()
  File "D:\Jafar\AAD\.env\lib\site-packages\rest_framework\generics.py", line 108, in get_serializer
    serializer_class = self.get_serializer_class()
  File "D:\Jafar\AAD\.env\lib\site-packages\rest_framework\generics.py", line 122, in get_serializer_class
    assert self.serializer_class is not None, (
AssertionError: 'DownloadWardwiseUserList' should either include a `serializer_class` attribute, or override the `get_serializer_class()` method.
view's MOHDashboardView raised exception during schema generation; use `getattr(self, 'swagger_fake_view', False)` to detect and short-circuit this
Traceback (most recent call last):
  File "D:\Jafar\AAD\.env\lib\site-packages\drf_yasg\inspectors\base.py", line 42, in call_view_method
    return view_method()
  File "D:\Jafar\AAD\.env\lib\site-packages\rest_framework\generics.py", line 108, in get_serializer
    serializer_class = self.get_serializer_class()
  File "D:\Jafar\AAD\.env\lib\site-packages\rest_framework\generics.py", line 122, in get_serializer_class
    assert self.serializer_class is not None, (
AssertionError: 'MOHDashboardView' should either include a `serializer_class` attribute, or override the `get_serializer_class()` method.
Bad Request: /allauth/api/login
[31;1mHTTP POST /allauth/api/login 400 [0.26, 127.0.0.1:52006][0m
Exception inside application: cannot schedule new futures after interpreter shutdown
Traceback (most recent call last):
  File "D:\Jafar\AAD\.env\lib\site-packages\django\contrib\staticfiles\handlers.py", line 101, in __call__
    return await self.application(scope, receive, send)
  File "D:\Jafar\AAD\.env\lib\site-packages\channels\routing.py", line 62, in __call__
    return await application(scope, receive, send)
  File "D:\Jafar\AAD\.env\lib\site-packages\django\core\handlers\asgi.py", line 160, in __call__
    await self.handle(scope, receive, send)
  File "D:\Jafar\AAD\.env\lib\site-packages\django\core\handlers\asgi.py", line 173, in handle
    await sync_to_async(signals.request_started.send, thread_sensitive=True)(
  File "D:\Jafar\AAD\.env\lib\site-packages\asgiref\sync.py", line 479, in __call__
    ret: _R = await loop.run_in_executor(
  File "C:\Program Files\WindowsApps\PythonSoftwareFoundation.Python.3.10_3.10.3056.0_x64__qbz5n2kfra8p0\lib\asyncio\base_events.py", line 821, in run_in_executor
    executor.submit(func, *args), loop=self)
  File "C:\Program Files\WindowsApps\PythonSoftwareFoundation.Python.3.10_3.10.3056.0_x64__qbz5n2kfra8p0\lib\concurrent\futures\thread.py", line 169, in submit
    raise RuntimeError('cannot schedule new futures after '
RuntimeError: cannot schedule new futures after interpreter shutdown
[35;1mHTTP GET /swagger/ 500 [0.45, 127.0.0.1:52091][0m
Exception inside application: cannot schedule new futures after interpreter shutdown
Traceback (most recent call last):
  File "D:\Jafar\AAD\.env\lib\site-packages\django\contrib\staticfiles\handlers.py", line 101, in __call__
    return await self.application(scope, receive, send)
  File "D:\Jafar\AAD\.env\lib\site-packages\channels\routing.py", line 62, in __call__
    return await application(scope, receive, send)
  File "D:\Jafar\AAD\.env\lib\site-packages\django\core\handlers\asgi.py", line 160, in __call__
    await self.handle(scope, receive, send)
  File "D:\Jafar\AAD\.env\lib\site-packages\django\core\handlers\asgi.py", line 173, in handle
    await sync_to_async(signals.request_started.send, thread_sensitive=True)(
  File "D:\Jafar\AAD\.env\lib\site-packages\asgiref\sync.py", line 479, in __call__
    ret: _R = await loop.run_in_executor(
  File "C:\Program Files\WindowsApps\PythonSoftwareFoundation.Python.3.10_3.10.3056.0_x64__qbz5n2kfra8p0\lib\asyncio\base_events.py", line 821, in run_in_executor
    executor.submit(func, *args), loop=self)
  File "C:\Program Files\WindowsApps\PythonSoftwareFoundation.Python.3.10_3.10.3056.0_x64__qbz5n2kfra8p0\lib\concurrent\futures\thread.py", line 169, in submit
    raise RuntimeError('cannot schedule new futures after '
RuntimeError: cannot schedule new futures after interpreter shutdown
[35;1mHTTP GET /swagger/ 500 [0.62, 127.0.0.1:52091][0m
Exception inside application: cannot schedule new futures after interpreter shutdown
Traceback (most recent call last):
  File "D:\Jafar\AAD\.env\lib\site-packages\django\contrib\staticfiles\handlers.py", line 101, in __call__
    return await self.application(scope, receive, send)
  File "D:\Jafar\AAD\.env\lib\site-packages\channels\routing.py", line 62, in __call__
    return await application(scope, receive, send)
  File "D:\Jafar\AAD\.env\lib\site-packages\django\core\handlers\asgi.py", line 160, in __call__
    await self.handle(scope, receive, send)
  File "D:\Jafar\AAD\.env\lib\site-packages\django\core\handlers\asgi.py", line 173, in handle
    await sync_to_async(signals.request_started.send, thread_sensitive=True)(
  File "D:\Jafar\AAD\.env\lib\site-packages\asgiref\sync.py", line 479, in __call__
    ret: _R = await loop.run_in_executor(
  File "C:\Program Files\WindowsApps\PythonSoftwareFoundation.Python.3.10_3.10.3056.0_x64__qbz5n2kfra8p0\lib\asyncio\base_events.py", line 821, in run_in_executor
    executor.submit(func, *args), loop=self)
  File "C:\Program Files\WindowsApps\PythonSoftwareFoundation.Python.3.10_3.10.3056.0_x64__qbz5n2kfra8p0\lib\concurrent\futures\thread.py", line 169, in submit
    raise RuntimeError('cannot schedule new futures after '
RuntimeError: cannot schedule new futures after interpreter shutdown
[35;1mHTTP GET /swagger/ 500 [0.43, 127.0.0.1:52091][0m
Exception inside application: cannot schedule new futures after shutdown
Traceback (most recent call last):
  File "D:\Jafar\AAD\.env\lib\site-packages\django\core\handlers\base.py", line 284, in _get_response_async
    response = await sync_to_async(
  File "D:\Jafar\AAD\.env\lib\site-packages\asgiref\sync.py", line 479, in __call__
    ret: _R = await loop.run_in_executor(
  File "C:\Program Files\WindowsApps\PythonSoftwareFoundation.Python.3.10_3.10.3056.0_x64__qbz5n2kfra8p0\lib\asyncio\base_events.py", line 821, in run_in_executor
    executor.submit(func, *args), loop=self)
  File "C:\Program Files\WindowsApps\PythonSoftwareFoundation.Python.3.10_3.10.3056.0_x64__qbz5n2kfra8p0\lib\concurrent\futures\thread.py", line 167, in submit
    raise RuntimeError('cannot schedule new futures after shutdown')
RuntimeError: cannot schedule new futures after shutdown

During handling of the above exception, another exception occurred:

Traceback (most recent call last):
  File "D:\Jafar\AAD\.env\lib\site-packages\django\core\handlers\exception.py", line 42, in inner
    response = await get_response(request)
  File "D:\Jafar\AAD\.env\lib\site-packages\django\core\handlers\base.py", line 288, in _get_response_async
    response = await sync_to_async(
  File "D:\Jafar\AAD\.env\lib\site-packages\asgiref\sync.py", line 479, in __call__
    ret: _R = await loop.run_in_executor(
  File "C:\Program Files\WindowsApps\PythonSoftwareFoundation.Python.3.10_3.10.3056.0_x64__qbz5n2kfra8p0\lib\asyncio\base_events.py", line 821, in run_in_executor
    executor.submit(func, *args), loop=self)
  File "C:\Program Files\WindowsApps\PythonSoftwareFoundation.Python.3.10_3.10.3056.0_x64__qbz5n2kfra8p0\lib\concurrent\futures\thread.py", line 167, in submit
    raise RuntimeError('cannot schedule new futures after shutdown')
RuntimeError: cannot schedule new futures after shutdown

During handling of the above exception, another exception occurred:

Traceback (most recent call last):
  File "D:\Jafar\AAD\.env\lib\site-packages\django\core\handlers\exception.py", line 42, in inner
    response = await get_response(request)
  File "D:\Jafar\AAD\.env\lib\site-packages\django\utils\deprecation.py", line 150, in __acall__
    response = response or await self.get_response(request)
  File "D:\Jafar\AAD\.env\lib\site-packages\django\core\handlers\exception.py", line 44, in inner
    response = await sync_to_async(
  File "D:\Jafar\AAD\.env\lib\site-packages\asgiref\sync.py", line 479, in __call__
    ret: _R = await loop.run_in_executor(
  File "C:\Program Files\WindowsApps\PythonSoftwareFoundation.Python.3.10_3.10.3056.0_x64__qbz5n2kfra8p0\lib\asyncio\base_events.py", line 821, in run_in_executor
    executor.submit(func, *args), loop=self)
  File "C:\Program Files\WindowsApps\PythonSoftwareFoundation.Python.3.10_3.10.3056.0_x64__qbz5n2kfra8p0\lib\concurrent\futures\thread.py", line 167, in submit
    raise RuntimeError('cannot schedule new futures after shutdown')
RuntimeError: cannot schedule new futures after shutdown

During handling of the above exception, another exception occurred:

Traceback (most recent call last):
  File "D:\Jafar\AAD\.env\lib\site-packages\django\core\handlers\exception.py", line 42, in inner
    response = await get_response(request)
  File "D:\Jafar\AAD\.env\lib\site-packages\django\utils\deprecation.py", line 150, in __acall__
    response = response or await self.get_response(request)
  File "D:\Jafar\AAD\.env\lib\site-packages\django\core\handlers\exception.py", line 44, in inner
    response = await sync_to_async(
  File "D:\Jafar\AAD\.env\lib\site-packages\asgiref\sync.py", line 479, in __call__
    ret: _R = await loop.run_in_executor(
  File "C:\Program Files\WindowsApps\PythonSoftwareFoundation.Python.3.10_3.10.3056.0_x64__qbz5n2kfra8p0\lib\asyncio\base_events.py", line 821, in run_in_executor
    executor.submit(func, *args), loop=self)
  File "C:\Program Files\WindowsApps\PythonSoftwareFoundation.Python.3.10_3.10.3056.0_x64__qbz5n2kfra8p0\lib\concurrent\futures\thread.py", line 167, in submit
    raise RuntimeError('cannot schedule new futures after shutdown')
RuntimeError: cannot schedule new futures after shutdown

During handling of the above exception, another exception occurred:

Traceback (most recent call last):
  File "D:\Jafar\AAD\.env\lib\site-packages\django\core\handlers\exception.py", line 42, in inner
    response = await get_response(request)
  File "D:\Jafar\AAD\.env\lib\site-packages\django\utils\deprecation.py", line 150, in __acall__
    response = response or await self.get_response(request)
  File "D:\Jafar\AAD\.env\lib\site-packages\django\core\handlers\exception.py", line 44, in inner
    response = await sync_to_async(
  File "D:\Jafar\AAD\.env\lib\site-packages\asgiref\sync.py", line 479, in __call__
    ret: _R = await loop.run_in_executor(
  File "C:\Program Files\WindowsApps\PythonSoftwareFoundation.Python.3.10_3.10.3056.0_x64__qbz5n2kfra8p0\lib\asyncio\base_events.py", line 821, in run_in_executor
    executor.submit(func, *args), loop=self)
  File "C:\Program Files\WindowsApps\PythonSoftwareFoundation.Python.3.10_3.10.3056.0_x64__qbz5n2kfra8p0\lib\concurrent\futures\thread.py", line 167, in submit
    raise RuntimeError('cannot schedule new futures after shutdown')
RuntimeError: cannot schedule new futures after shutdown

During handling of the above exception, another exception occurred:

Traceback (most recent call last):
  File "D:\Jafar\AAD\.env\lib\site-packages\django\core\handlers\exception.py", line 42, in inner
    response = await get_response(request)
  File "D:\Jafar\AAD\.env\lib\site-packages\django\utils\deprecation.py", line 150, in __acall__
    response = response or await self.get_response(request)
  File "D:\Jafar\AAD\.env\lib\site-packages\django\core\handlers\exception.py", line 44, in inner
    response = await sync_to_async(
  File "D:\Jafar\AAD\.env\lib\site-packages\asgiref\sync.py", line 479, in __call__
    ret: _R = await loop.run_in_executor(
  File "C:\Program Files\WindowsApps\PythonSoftwareFoundation.Python.3.10_3.10.3056.0_x64__qbz5n2kfra8p0\lib\asyncio\base_events.py", line 821, in run_in_executor
    executor.submit(func, *args), loop=self)
  File "C:\Program Files\WindowsApps\PythonSoftwareFoundation.Python.3.10_3.10.3056.0_x64__qbz5n2kfra8p0\lib\concurrent\futures\thread.py", line 167, in submit
    raise RuntimeError('cannot schedule new futures after shutdown')
RuntimeError: cannot schedule new futures after shutdown

During handling of the above exception, another exception occurred:

Traceback (most recent call last):
  File "D:\Jafar\AAD\.env\lib\site-packages\django\core\handlers\exception.py", line 42, in inner
    response = await get_response(request)
  File "D:\Jafar\AAD\.env\lib\site-packages\django\utils\deprecation.py", line 150, in __acall__
    response = response or await self.get_response(request)
  File "D:\Jafar\AAD\.env\lib\site-packages\django\core\handlers\exception.py", line 44, in inner
    response = await sync_to_async(
  File "D:\Jafar\AAD\.env\lib\site-packages\asgiref\sync.py", line 479, in __call__
    ret: _R = await loop.run_in_executor(
  File "C:\Program Files\WindowsApps\PythonSoftwareFoundation.Python.3.10_3.10.3056.0_x64__qbz5n2kfra8p0\lib\asyncio\base_events.py", line 821, in run_in_executor
    executor.submit(func, *args), loop=self)
  File "C:\Program Files\WindowsApps\PythonSoftwareFoundation.Python.3.10_3.10.3056.0_x64__qbz5n2kfra8p0\lib\concurrent\futures\thread.py", line 167, in submit
    raise RuntimeError('cannot schedule new futures after shutdown')
RuntimeError: cannot schedule new futures after shutdown

During handling of the above exception, another exception occurred:

Traceback (most recent call last):
  File "D:\Jafar\AAD\.env\lib\site-packages\django\core\handlers\exception.py", line 42, in inner
    response = await get_response(request)
  File "D:\Jafar\AAD\.env\lib\site-packages\corsheaders\middleware.py", line 67, in __acall__
    response = await result
  File "D:\Jafar\AAD\.env\lib\site-packages\django\core\handlers\exception.py", line 44, in inner
    response = await sync_to_async(
  File "D:\Jafar\AAD\.env\lib\site-packages\asgiref\sync.py", line 479, in __call__
    ret: _R = await loop.run_in_executor(
  File "C:\Program Files\WindowsApps\PythonSoftwareFoundation.Python.3.10_3.10.3056.0_x64__qbz5n2kfra8p0\lib\asyncio\base_events.py", line 821, in run_in_executor
    executor.submit(func, *args), loop=self)
  File "C:\Program Files\WindowsApps\PythonSoftwareFoundation.Python.3.10_3.10.3056.0_x64__qbz5n2kfra8p0\lib\concurrent\futures\thread.py", line 167, in submit
    raise RuntimeError('cannot schedule new futures after shutdown')
RuntimeError: cannot schedule new futures after shutdown

During handling of the above exception, another exception occurred:

Traceback (most recent call last):
  File "D:\Jafar\AAD\.env\lib\site-packages\django\core\handlers\exception.py", line 42, in inner
    response = await get_response(request)
  File "D:\Jafar\AAD\.env\lib\site-packages\django\utils\deprecation.py", line 150, in __acall__
    response = response or await self.get_response(request)
  File "D:\Jafar\AAD\.env\lib\site-packages\django\core\handlers\exception.py", line 44, in inner
    response = await sync_to_async(
  File "D:\Jafar\AAD\.env\lib\site-packages\asgiref\sync.py", line 479, in __call__
    ret: _R = await loop.run_in_executor(
  File "C:\Program Files\WindowsApps\PythonSoftwareFoundation.Python.3.10_3.10.3056.0_x64__qbz5n2kfra8p0\lib\asyncio\base_events.py", line 821, in run_in_executor
    executor.submit(func, *args), loop=self)
  File "C:\Program Files\WindowsApps\PythonSoftwareFoundation.Python.3.10_3.10.3056.0_x64__qbz5n2kfra8p0\lib\concurrent\futures\thread.py", line 167, in submit
    raise RuntimeError('cannot schedule new futures after shutdown')
RuntimeError: cannot schedule new futures after shutdown

During handling of the above exception, another exception occurred:

Traceback (most recent call last):
  File "D:\Jafar\AAD\.env\lib\site-packages\django\core\handlers\exception.py", line 42, in inner
    response = await get_response(request)
  File "D:\Jafar\AAD\.env\lib\site-packages\django\utils\deprecation.py", line 150, in __acall__
    response = response or await self.get_response(request)
  File "D:\Jafar\AAD\.env\lib\site-packages\django\core\handlers\exception.py", line 44, in inner
    response = await sync_to_async(
  File "D:\Jafar\AAD\.env\lib\site-packages\asgiref\sync.py", line 479, in __call__
    ret: _R = await loop.run_in_executor(
  File "C:\Program Files\WindowsApps\PythonSoftwareFoundation.Python.3.10_3.10.3056.0_x64__qbz5n2kfra8p0\lib\asyncio\base_events.py", line 821, in run_in_executor
    executor.submit(func, *args), loop=self)
  File "C:\Program Files\WindowsApps\PythonSoftwareFoundation.Python.3.10_3.10.3056.0_x64__qbz5n2kfra8p0\lib\concurrent\futures\thread.py", line 167, in submit
    raise RuntimeError('cannot schedule new futures after shutdown')
RuntimeError: cannot schedule new futures after shutdown

During handling of the above exception, another exception occurred:

Traceback (most recent call last):
  File "D:\Jafar\AAD\.env\lib\site-packages\django\contrib\staticfiles\handlers.py", line 101, in __call__
    return await self.application(scope, receive, send)
  File "D:\Jafar\AAD\.env\lib\site-packages\channels\routing.py", line 62, in __call__
    return await application(scope, receive, send)
  File "D:\Jafar\AAD\.env\lib\site-packages\django\core\handlers\asgi.py", line 160, in __call__
    await self.handle(scope, receive, send)
  File "D:\Jafar\AAD\.env\lib\site-packages\django\core\handlers\asgi.py", line 183, in handle
    response = await self.get_response_async(request)
  File "D:\Jafar\AAD\.env\lib\site-packages\django\core\handlers\base.py", line 162, in get_response_async
    response = await self._middleware_chain(request)
  File "D:\Jafar\AAD\.env\lib\site-packages\django\core\handlers\exception.py", line 44, in inner
    response = await sync_to_async(
  File "D:\Jafar\AAD\.env\lib\site-packages\asgiref\sync.py", line 479, in __call__
    ret: _R = await loop.run_in_executor(
  File "C:\Program Files\WindowsApps\PythonSoftwareFoundation.Python.3.10_3.10.3056.0_x64__qbz5n2kfra8p0\lib\asyncio\base_events.py", line 821, in run_in_executor
    executor.submit(func, *args), loop=self)
  File "C:\Program Files\WindowsApps\PythonSoftwareFoundation.Python.3.10_3.10.3056.0_x64__qbz5n2kfra8p0\lib\concurrent\futures\thread.py", line 167, in submit
    raise RuntimeError('cannot schedule new futures after shutdown')
RuntimeError: cannot schedule new futures after shutdown
[35;1mHTTP GET /adminportal/api/GetuserListAPI/CHV/ASHA 500 [39.49, 10.202.100.219:53872][0m
view's UpdateUserDetails raised exception during schema generation; use `getattr(self, 'swagger_fake_view', False)` to detect and short-circuit this
Traceback (most recent call last):
  File "D:\Jafar\AAD\.env\lib\site-packages\drf_yasg\inspectors\base.py", line 42, in call_view_method
    return view_method()
  File "D:\Jafar\AAD\.env\lib\site-packages\rest_framework\generics.py", line 63, in get_queryset
    assert self.queryset is not None, (
AssertionError: 'UpdateUserDetails' should either include a `queryset` attribute, or override the `get_queryset()` method.
view's DownloadDispensarywiseUserList raised exception during schema generation; use `getattr(self, 'swagger_fake_view', False)` to detect and short-circuit this
Traceback (most recent call last):
  File "D:\Jafar\AAD\.env\lib\site-packages\drf_yasg\inspectors\base.py", line 42, in call_view_method
    return view_method()
  File "D:\Jafar\AAD\.env\lib\site-packages\rest_framework\generics.py", line 108, in get_serializer
    serializer_class = self.get_serializer_class()
  File "D:\Jafar\AAD\.env\lib\site-packages\rest_framework\generics.py", line 122, in get_serializer_class
    assert self.serializer_class is not None, (
AssertionError: 'DownloadDispensarywiseUserList' should either include a `serializer_class` attribute, or override the `get_serializer_class()` method.
view's DownloadHealthpostwiseUserList raised exception during schema generation; use `getattr(self, 'swagger_fake_view', False)` to detect and short-circuit this
Traceback (most recent call last):
  File "D:\Jafar\AAD\.env\lib\site-packages\drf_yasg\inspectors\base.py", line 42, in call_view_method
    return view_method()
  File "D:\Jafar\AAD\.env\lib\site-packages\rest_framework\generics.py", line 108, in get_serializer
    serializer_class = self.get_serializer_class()
  File "D:\Jafar\AAD\.env\lib\site-packages\rest_framework\generics.py", line 122, in get_serializer_class
    assert self.serializer_class is not None, (
AssertionError: 'DownloadHealthpostwiseUserList' should either include a `serializer_class` attribute, or override the `get_serializer_class()` method.
view's DownloadWardwiseUserList raised exception during schema generation; use `getattr(self, 'swagger_fake_view', False)` to detect and short-circuit this
Traceback (most recent call last):
  File "D:\Jafar\AAD\.env\lib\site-packages\drf_yasg\inspectors\base.py", line 42, in call_view_method
    return view_method()
  File "D:\Jafar\AAD\.env\lib\site-packages\rest_framework\generics.py", line 108, in get_serializer
    serializer_class = self.get_serializer_class()
  File "D:\Jafar\AAD\.env\lib\site-packages\rest_framework\generics.py", line 122, in get_serializer_class
    assert self.serializer_class is not None, (
AssertionError: 'DownloadWardwiseUserList' should either include a `serializer_class` attribute, or override the `get_serializer_class()` method.
view's MOHDashboardView raised exception during schema generation; use `getattr(self, 'swagger_fake_view', False)` to detect and short-circuit this
Traceback (most recent call last):
  File "D:\Jafar\AAD\.env\lib\site-packages\drf_yasg\inspectors\base.py", line 42, in call_view_method
    return view_method()
  File "D:\Jafar\AAD\.env\lib\site-packages\rest_framework\generics.py", line 108, in get_serializer
    serializer_class = self.get_serializer_class()
  File "D:\Jafar\AAD\.env\lib\site-packages\rest_framework\generics.py", line 122, in get_serializer_class
    assert self.serializer_class is not None, (
AssertionError: 'MOHDashboardView' should either include a `serializer_class` attribute, or override the `get_serializer_class()` method.
view's UpdateUserDetails raised exception during schema generation; use `getattr(self, 'swagger_fake_view', False)` to detect and short-circuit this
Traceback (most recent call last):
  File "D:\Jafar\AAD\.env\lib\site-packages\drf_yasg\inspectors\base.py", line 42, in call_view_method
    return view_method()
  File "D:\Jafar\AAD\.env\lib\site-packages\rest_framework\generics.py", line 63, in get_queryset
    assert self.queryset is not None, (
AssertionError: 'UpdateUserDetails' should either include a `queryset` attribute, or override the `get_queryset()` method.
view's DownloadDispensarywiseUserList raised exception during schema generation; use `getattr(self, 'swagger_fake_view', False)` to detect and short-circuit this
Traceback (most recent call last):
  File "D:\Jafar\AAD\.env\lib\site-packages\drf_yasg\inspectors\base.py", line 42, in call_view_method
    return view_method()
  File "D:\Jafar\AAD\.env\lib\site-packages\rest_framework\generics.py", line 108, in get_serializer
    serializer_class = self.get_serializer_class()
  File "D:\Jafar\AAD\.env\lib\site-packages\rest_framework\generics.py", line 122, in get_serializer_class
    assert self.serializer_class is not None, (
AssertionError: 'DownloadDispensarywiseUserList' should either include a `serializer_class` attribute, or override the `get_serializer_class()` method.
view's DownloadHealthpostwiseUserList raised exception during schema generation; use `getattr(self, 'swagger_fake_view', False)` to detect and short-circuit this
Traceback (most recent call last):
  File "D:\Jafar\AAD\.env\lib\site-packages\drf_yasg\inspectors\base.py", line 42, in call_view_method
    return view_method()
  File "D:\Jafar\AAD\.env\lib\site-packages\rest_framework\generics.py", line 108, in get_serializer
    serializer_class = self.get_serializer_class()
  File "D:\Jafar\AAD\.env\lib\site-packages\rest_framework\generics.py", line 122, in get_serializer_class
    assert self.serializer_class is not None, (
AssertionError: 'DownloadHealthpostwiseUserList' should either include a `serializer_class` attribute, or override the `get_serializer_class()` method.
view's DownloadWardwiseUserList raised exception during schema generation; use `getattr(self, 'swagger_fake_view', False)` to detect and short-circuit this
Traceback (most recent call last):
  File "D:\Jafar\AAD\.env\lib\site-packages\drf_yasg\inspectors\base.py", line 42, in call_view_method
    return view_method()
  File "D:\Jafar\AAD\.env\lib\site-packages\rest_framework\generics.py", line 108, in get_serializer
    serializer_class = self.get_serializer_class()
  File "D:\Jafar\AAD\.env\lib\site-packages\rest_framework\generics.py", line 122, in get_serializer_class
    assert self.serializer_class is not None, (
AssertionError: 'DownloadWardwiseUserList' should either include a `serializer_class` attribute, or override the `get_serializer_class()` method.
view's MOHDashboardView raised exception during schema generation; use `getattr(self, 'swagger_fake_view', False)` to detect and short-circuit this
Traceback (most recent call last):
  File "D:\Jafar\AAD\.env\lib\site-packages\drf_yasg\inspectors\base.py", line 42, in call_view_method
    return view_method()
  File "D:\Jafar\AAD\.env\lib\site-packages\rest_framework\generics.py", line 108, in get_serializer
    serializer_class = self.get_serializer_class()
  File "D:\Jafar\AAD\.env\lib\site-packages\rest_framework\generics.py", line 122, in get_serializer_class
    assert self.serializer_class is not None, (
AssertionError: 'MOHDashboardView' should either include a `serializer_class` attribute, or override the `get_serializer_class()` method.
view's UpdateUserDetails raised exception during schema generation; use `getattr(self, 'swagger_fake_view', False)` to detect and short-circuit this
Traceback (most recent call last):
  File "D:\Jafar\AAD\.env\lib\site-packages\drf_yasg\inspectors\base.py", line 42, in call_view_method
    return view_method()
  File "D:\Jafar\AAD\.env\lib\site-packages\rest_framework\generics.py", line 63, in get_queryset
    assert self.queryset is not None, (
AssertionError: 'UpdateUserDetails' should either include a `queryset` attribute, or override the `get_queryset()` method.
view's DownloadDispensarywiseUserList raised exception during schema generation; use `getattr(self, 'swagger_fake_view', False)` to detect and short-circuit this
Traceback (most recent call last):
  File "D:\Jafar\AAD\.env\lib\site-packages\drf_yasg\inspectors\base.py", line 42, in call_view_method
    return view_method()
  File "D:\Jafar\AAD\.env\lib\site-packages\rest_framework\generics.py", line 108, in get_serializer
    serializer_class = self.get_serializer_class()
  File "D:\Jafar\AAD\.env\lib\site-packages\rest_framework\generics.py", line 122, in get_serializer_class
    assert self.serializer_class is not None, (
AssertionError: 'DownloadDispensarywiseUserList' should either include a `serializer_class` attribute, or override the `get_serializer_class()` method.
view's DownloadHealthpostwiseUserList raised exception during schema generation; use `getattr(self, 'swagger_fake_view', False)` to detect and short-circuit this
Traceback (most recent call last):
  File "D:\Jafar\AAD\.env\lib\site-packages\drf_yasg\inspectors\base.py", line 42, in call_view_method
    return view_method()
  File "D:\Jafar\AAD\.env\lib\site-packages\rest_framework\generics.py", line 108, in get_serializer
    serializer_class = self.get_serializer_class()
  File "D:\Jafar\AAD\.env\lib\site-packages\rest_framework\generics.py", line 122, in get_serializer_class
    assert self.serializer_class is not None, (
AssertionError: 'DownloadHealthpostwiseUserList' should either include a `serializer_class` attribute, or override the `get_serializer_class()` method.
view's DownloadWardwiseUserList raised exception during schema generation; use `getattr(self, 'swagger_fake_view', False)` to detect and short-circuit this
Traceback (most recent call last):
  File "D:\Jafar\AAD\.env\lib\site-packages\drf_yasg\inspectors\base.py", line 42, in call_view_method
    return view_method()
  File "D:\Jafar\AAD\.env\lib\site-packages\rest_framework\generics.py", line 108, in get_serializer
    serializer_class = self.get_serializer_class()
  File "D:\Jafar\AAD\.env\lib\site-packages\rest_framework\generics.py", line 122, in get_serializer_class
    assert self.serializer_class is not None, (
AssertionError: 'DownloadWardwiseUserList' should either include a `serializer_class` attribute, or override the `get_serializer_class()` method.
view's MOHDashboardView raised exception during schema generation; use `getattr(self, 'swagger_fake_view', False)` to detect and short-circuit this
Traceback (most recent call last):
  File "D:\Jafar\AAD\.env\lib\site-packages\drf_yasg\inspectors\base.py", line 42, in call_view_method
    return view_method()
  File "D:\Jafar\AAD\.env\lib\site-packages\rest_framework\generics.py", line 108, in get_serializer
    serializer_class = self.get_serializer_class()
  File "D:\Jafar\AAD\.env\lib\site-packages\rest_framework\generics.py", line 122, in get_serializer_class
    assert self.serializer_class is not None, (
AssertionError: 'MOHDashboardView' should either include a `serializer_class` attribute, or override the `get_serializer_class()` method.
Exception inside application: cannot schedule new futures after interpreter shutdown
Traceback (most recent call last):
  File "D:\Jafar\AAD\.env\lib\site-packages\django\contrib\staticfiles\handlers.py", line 101, in __call__
    return await self.application(scope, receive, send)
  File "D:\Jafar\AAD\.env\lib\site-packages\channels\routing.py", line 62, in __call__
    return await application(scope, receive, send)
  File "D:\Jafar\AAD\.env\lib\site-packages\django\core\handlers\asgi.py", line 160, in __call__
    await self.handle(scope, receive, send)
  File "D:\Jafar\AAD\.env\lib\site-packages\django\core\handlers\asgi.py", line 173, in handle
    await sync_to_async(signals.request_started.send, thread_sensitive=True)(
  File "D:\Jafar\AAD\.env\lib\site-packages\asgiref\sync.py", line 479, in __call__
    ret: _R = await loop.run_in_executor(
  File "C:\Program Files\WindowsApps\PythonSoftwareFoundation.Python.3.10_3.10.3056.0_x64__qbz5n2kfra8p0\lib\asyncio\base_events.py", line 821, in run_in_executor
    executor.submit(func, *args), loop=self)
  File "C:\Program Files\WindowsApps\PythonSoftwareFoundation.Python.3.10_3.10.3056.0_x64__qbz5n2kfra8p0\lib\concurrent\futures\thread.py", line 169, in submit
    raise RuntimeError('cannot schedule new futures after '
RuntimeError: cannot schedule new futures after interpreter shutdown
[35;1mHTTP GET /adminportal/api/GetWardWiseSUerList/healthworker/F%2FS 500 [0.21, 127.0.0.1:53140][0m
Exception inside application: cannot schedule new futures after interpreter shutdown
Traceback (most recent call last):
  File "D:\Jafar\AAD\.env\lib\site-packages\django\contrib\staticfiles\handlers.py", line 101, in __call__
    return await self.application(scope, receive, send)
  File "D:\Jafar\AAD\.env\lib\site-packages\channels\routing.py", line 62, in __call__
    return await application(scope, receive, send)
  File "D:\Jafar\AAD\.env\lib\site-packages\django\core\handlers\asgi.py", line 160, in __call__
    await self.handle(scope, receive, send)
  File "D:\Jafar\AAD\.env\lib\site-packages\django\core\handlers\asgi.py", line 173, in handle
    await sync_to_async(signals.request_started.send, thread_sensitive=True)(
  File "D:\Jafar\AAD\.env\lib\site-packages\asgiref\sync.py", line 479, in __call__
    ret: _R = await loop.run_in_executor(
  File "C:\Program Files\WindowsApps\PythonSoftwareFoundation.Python.3.10_3.10.3056.0_x64__qbz5n2kfra8p0\lib\asyncio\base_events.py", line 821, in run_in_executor
    executor.submit(func, *args), loop=self)
  File "C:\Program Files\WindowsApps\PythonSoftwareFoundation.Python.3.10_3.10.3056.0_x64__qbz5n2kfra8p0\lib\concurrent\futures\thread.py", line 169, in submit
    raise RuntimeError('cannot schedule new futures after '
RuntimeError: cannot schedule new futures after interpreter shutdown
[35;1mHTTP GET /adminportal/api/GetWardWiseSUerList/healthworker/F%2FS 500 [0.20, 127.0.0.1:53140][0m
